Workbook

Sheet SAISIE
A1: 1 | B1: Flux caractérisé | C1: Date | D1: Equipe | E1: Provenance | F1: JRM | G1: EMR | H1: CARTON | I1: GM | J1: PETQ9 | K1: FLUX DEV | L1: PET B | M1: PEPP | N1: ELA | O1: FILM | P1: ACIER | Q1: ALU | R1: PETIT ALU | S1: REFUS | T1: Total (kg) | U1: Taux de pureté | V1: Remarques | W1: Année | X1: Mois | Y1: Semaine | Z1: JRM* | AA1: EMR* | AB1: CARTON* | AC1: GM* | AD1: PET Q9* | AE1: FLUX DEV* | AF1: PET B* | AG1: PEPP* | AH1: ELA* | AI1: FILM* | AJ1: ACIER* | AK1: ALU* | AL1: PETIT ALU* | AM1: REFUS* | AN1: Fibreux | AO1: CC | AP1: Contaminant A | AQ1: Contaminant B | AR1: Global indésirable | AS1: CC + REFUS | AT1: Fibreux + ELA | AU1: Fibreux + CC | AV1: Fibreux + CC - FILM | AW1: CC - ELA
A2: =A1+1 | B2: EMR | C2: 24/02/26 | D2: MATIN | E2: COLLECTE | F2: 1.6 | G2: 15.6 | H2: 0.6 | I2: 1.3 | J2: 0.2 | K2: 0.1 | L2: 0.3 | M2: 0.1 | N2: 0.1 | O2: 0.1 | P2: 0 | Q2: 0 | R2: 0 | S2: 1.2 | T2: =SUM(F2:S2) | U2: =(HLOOKUP(B2,F:T,A2,FALSE)/T2) | W2: 2026 | X2: 2 | Y2: 8 | Z2: =IFERROR(F2/$T2,0) | AA2: =IFERROR(G2/$T2,0) | AB2: =IFERROR(H2/$T2,0) | AC2: =IFERROR(I2/$T2,0) | AD2: =IFERROR(J2/$T2,0) | AE2: =IFERROR(K2/$T2,0) | AF2: =IFERROR(L2/$T2,0) | AG2: =IFERROR(M2/$T2,0) | ... AM2: =IFERROR(S2/$T2,0) | AN2: =SUM(Z2:AC2) | AO2: =SUM(AD2:AL2) | AP2: =SUM(AM2,AB2) | AQ2: =SUM(AA2) | AR2: =(AP2+AQ2)-3% | AS2: =SUM(AO2+AM2) | AT2: =SUM(AH2+AN2) | AU2: =SUM(AN2+AO2) | AV2: =SUM(AN2+AD2+AE2+AF2+AG2+AH2+AJ2+AK2+AL2) | AW2: =SUM(AD2+AE2+AF2+AG2+AI2+AJ2+AK2+AL2)
A3: =A2+1 | B3: JRM | C3: 24/02/26 | D3: MATIN | E3: SILO | F3: 1.2 | G3: 0.1 | H3: 0.1 | I3: 0.1 | J3: 0 | K3: 0 | L3: 0 | M3: 0 | N3: 0 | O3: 0 | P3: 0 | Q3: 0 | R3: 0 | S3: 0.5 | T3: =SUM(F3:S3) | U3: =(HLOOKUP(B3,F:T,A3,FALSE)/T3) | W3: 2026 | X3: 2 | Y3: 8 | Z3: =IFERROR(F3/$T3,0) | AA3: =IFERROR(G3/$T3,0) | AB3: =IFERROR(H3/$T3,0) | AC3: =IFERROR(I3/$T3,0) | AD3: =IFERROR(J3/$T3,0) | AE3: =IFERROR(K3/$T3,0) | AF3: =IFERROR(L3/$T3,0) | AG3: =IFERROR(M3/$T3,0) | ... AM3: =IFERROR(S3/$T3,0) | AN3: =SUM(Z3:AC3) | AO3: =SUM(AD3:AL3) | AP3: =SUM(AM3,AB3) | AQ3: =SUM(AA3) | AR3: =(AP3+AQ3)-3% | AS3: =SUM(AO3+AM3) | AT3: =SUM(AH3+AN3) | AU3: =SUM(AN3+AO3) | AV3: =SUM(AN3+AD3+AE3+AF3+AG3+AH3+AJ3+AK3+AL3) | AW3: =SUM(AD3+AE3+AF3+AG3+AI3+AJ3+AK3+AL3)
A4: =A3+1 | B4: EMR | C4: 24/02/26 | D4: MATIN | E4: SILO | F4: 1.2 | G4: 3 | H4: 0.1 | I4: 0.1 | J4: 0 | K4: 0 | L4: 0 | M4: 0 | N4: 0 | O4: 0 | P4: 0 | Q4: 0 | R4: 0 | S4: 0.5 | T4: =SUM(F4:S4) | U4: =(HLOOKUP(B4,F:T,A4,FALSE)/T4) | W4: 2026 | X4: 2 | Y4: 8 | Z4: =IFERROR(F4/$T4,0) | AA4: =IFERROR(G4/$T4,0) | AB4: =IFERROR(H4/$T4,0) | AC4: =IFERROR(I4/$T4,0) | AD4: =IFERROR(J4/$T4,0) | AE4: =IFERROR(K4/$T4,0) | AF4: =IFERROR(L4/$T4,0) | AG4: =IFERROR(M4/$T4,0) | ... AM4: =IFERROR(S4/$T4,0) | AN4: =SUM(Z4:AC4) | AO4: =SUM(AD4:AL4) | AP4: =SUM(AM4,AB4) | AQ4: =SUM(AA4) | AR4: =(AP4+AQ4)-3% | AS4: =SUM(AO4+AM4) | AT4: =SUM(AH4+AN4) | AU4: =SUM(AN4+AO4) | AV4: =SUM(AN4+AD4+AE4+AF4+AG4+AH4+AJ4+AK4+AL4) | AW4: =SUM(AD4+AE4+AF4+AG4+AI4+AJ4+AK4+AL4)
A5: =A4+1 | B5: JRM | C5: 24-02-2026 | D5: MATIN | E5: SILO | F5: 4.8 | G5: 0.2 | H5: 0.2 | I5: 0.1 | J5: 0 | K5: 0 | L5: 0 | M5: 0 | N5: 0 | O5: 0 | P5: 0.1 | Q5: 0.1 | R5: 0.1 | S5: 0.1 | T5: =SUM(F5:S5) | U5: =(HLOOKUP(B5,F:T,A5,FALSE)/T5) | W5: 2026 | X5: 2 | Y5: 8 | Z5: =IFERROR(F5/$T5,0) | AA5: =IFERROR(G5/$T5,0) | AB5: =IFERROR(H5/$T5,0) | AC5: =IFERROR(I5/$T5,0) | AD5: =IFERROR(J5/$T5,0) | AE5: =IFERROR(K5/$T5,0) | AF5: =IFERROR(L5/$T5,0) | AG5: =IFERROR(M5/$T5,0) | ... AM5: =IFERROR(S5/$T5,0) | AN5: =SUM(Z5:AC5) | AO5: =SUM(AD5:AL5) | AP5: =SUM(AM5,AB5) | AQ5: =SUM(AA5) | AR5: =(AP5+AQ5)-3% | AS5: =SUM(AO5+AM5) | AT5: =SUM(AH5+AN5) | AU5: =SUM(AN5+AO5) | AV5: =SUM(AN5+AD5+AE5+AF5+AG5+AH5+AJ5+AK5+AL5) | AW5: =SUM(AD5+AE5+AF5+AG5+AI5+AJ5+AK5+AL5)
A6: =A5+1 | T6: =SUM(F6:S6) | U6: =(HLOOKUP(B6,F:T,A6,FALSE)/T6) | W6: =YEAR(C6) | X6: =MONTH(C6) | Y6: =WEEKNUM(C6,21) | Z6: =IFERROR(F6/$T6,0) | AA6: =IFERROR(G6/$T6,0) | AB6: =IFERROR(H6/$T6,0) | AC6: =IFERROR(I6/$T6,0) | AD6: =IFERROR(J6/$T6,0) | AE6: =IFERROR(K6/$T6,0) | AF6: =IFERROR(L6/$T6,0) | AG6: =IFERROR(M6/$T6,0) | ... AM6: =IFERROR(S6/$T6,0) | AN6: =SUM(Z6:AC6) | AO6: =SUM(AD6:AL6) | AP6: =SUM(AM6,AB6) | AQ6: =SUM(AA6) | AR6: =(AP6+AQ6)-3% | AS6: =SUM(AO6+AM6) | AT6: =SUM(AH6+AN6) | AU6: =SUM(AN6+AO6) | AV6: =SUM(AN6+AD6+AE6+AF6+AG6+AH6+AJ6+AK6+AL6) | AW6: =SUM(AD6+AE6+AF6+AG6+AI6+AJ6+AK6+AL6)
A7: =A6+1 | T7: =SUM(F7:S7) | U7: =(HLOOKUP(B7,F:T,A7,FALSE)/T7) | W7: =YEAR(C7) | X7: =MONTH(C7) | Y7: =WEEKNUM(C7,21) | Z7: =IFERROR(F7/$T7,0) | AA7: =IFERROR(G7/$T7,0) | AB7: =IFERROR(H7/$T7,0) | AC7: =IFERROR(I7/$T7,0) | AD7: =IFERROR(J7/$T7,0) | AE7: =IFERROR(K7/$T7,0) | AF7: =IFERROR(L7/$T7,0) | AG7: =IFERROR(M7/$T7,0) | ... AM7: =IFERROR(S7/$T7,0) | AN7: =SUM(Z7:AC7) | AO7: =SUM(AD7:AL7) | AP7: =SUM(AM7,AB7) | AQ7: =SUM(AA7) | AR7: =(AP7+AQ7)-3% | AS7: =SUM(AO7+AM7) | AT7: =SUM(AH7+AN7) | AU7: =SUM(AN7+AO7) | AV7: =SUM(AN7+AD7+AE7+AF7+AG7+AH7+AJ7+AK7+AL7) | AW7: =SUM(AD7+AE7+AF7+AG7+AI7+AJ7+AK7+AL7)
A8: =A7+1 | T8: =SUM(F8:S8) | U8: =(HLOOKUP(B8,F:T,A8,FALSE)/T8) | W8: =YEAR(C8) | X8: =MONTH(C8) | Y8: =WEEKNUM(C8,21) | Z8: =IFERROR(F8/$T8,0) | AA8: =IFERROR(G8/$T8,0) | AB8: =IFERROR(H8/$T8,0) | AC8: =IFERROR(I8/$T8,0) | AD8: =IFERROR(J8/$T8,0) | AE8: =IFERROR(K8/$T8,0) | AF8: =IFERROR(L8/$T8,0) | AG8: =IFERROR(M8/$T8,0) | ... AM8: =IFERROR(S8/$T8,0) | AN8: =SUM(Z8:AC8) | AO8: =SUM(AD8:AL8) | AP8: =SUM(AM8,AB8) | AQ8: =SUM(AA8) | AR8: =(AP8+AQ8)-3% | AS8: =SUM(AO8+AM8) | AT8: =SUM(AH8+AN8) | AU8: =SUM(AN8+AO8) | AV8: =SUM(AN8+AD8+AE8+AF8+AG8+AH8+AJ8+AK8+AL8) | AW8: =SUM(AD8+AE8+AF8+AG8+AI8+AJ8+AK8+AL8)
A9: =A8+1 | T9: =SUM(F9:S9) | U9: =(HLOOKUP(B9,F:T,A9,FALSE)/T9) | W9: =YEAR(C9) | X9: =MONTH(C9) | Y9: =WEEKNUM(C9,21) | Z9: =IFERROR(F9/$T9,0) | AA9: =IFERROR(G9/$T9,0) | AB9: =IFERROR(H9/$T9,0) | AC9: =IFERROR(I9/$T9,0) | AD9: =IFERROR(J9/$T9,0) | AE9: =IFERROR(K9/$T9,0) | AF9: =IFERROR(L9/$T9,0) | AG9: =IFERROR(M9/$T9,0) | ... AM9: =IFERROR(S9/$T9,0) | AN9: =SUM(Z9:AC9) | AO9: =SUM(AD9:AL9) | AP9: =SUM(AM9,AB9) | AQ9: =SUM(AA9) | AR9: =(AP9+AQ9)-3% | AS9: =SUM(AO9+AM9) | AT9: =SUM(AH9+AN9) | AU9: =SUM(AN9+AO9) | AV9: =SUM(AN9+AD9+AE9+AF9+AG9+AH9+AJ9+AK9+AL9) | AW9: =SUM(AD9+AE9+AF9+AG9+AI9+AJ9+AK9+AL9)
A10: =A9+1 | T10: =SUM(F10:S10) | U10: =(HLOOKUP(B10,F:T,A10,FALSE)/T10) | W10: =YEAR(C10) | X10: =MONTH(C10) | Y10: =WEEKNUM(C10,21) | Z10: =IFERROR(F10/$T10,0) | AA10: =IFERROR(G10/$T10,0) | AB10: =IFERROR(H10/$T10,0) | AC10: =IFERROR(I10/$T10,0) | AD10: =IFERROR(J10/$T10,0) | AE10: =IFERROR(K10/$T10,0) | AF10: =IFERROR(L10/$T10,0) | AG10: =IFERROR(M10/$T10,0) | ... AM10: =IFERROR(S10/$T10,0) | AN10: =SUM(Z10:AC10) | AO10: =SUM(AD10:AL10) | AP10: =SUM(AM10,AB10) | AQ10: =SUM(AA10) | AR10: =(AP10+AQ10)-3% | AS10: =SUM(AO10+AM10) | AT10: =SUM(AH10+AN10) | AU10: =SUM(AN10+AO10) | AV10: =SUM(AN10+AD10+AE10+AF10+AG10+AH10+AJ10+AK10+AL10) | AW10: =SUM(AD10+AE10+AF10+AG10+AI10+AJ10+AK10+AL10)
A11: =A10+1 | T11: =SUM(F11:S11) | U11: =(HLOOKUP(B11,F:T,A11,FALSE)/T11) | W11: =YEAR(C11) | X11: =MONTH(C11) | Y11: =WEEKNUM(C11,21) | Z11: =IFERROR(F11/$T11,0) | AA11: =IFERROR(G11/$T11,0) | AB11: =IFERROR(H11/$T11,0) | AC11: =IFERROR(I11/$T11,0) | AD11: =IFERROR(J11/$T11,0) | AE11: =IFERROR(K11/$T11,0) | AF11: =IFERROR(L11/$T11,0) | AG11: =IFERROR(M11/$T11,0) | ... AM11: =IFERROR(S11/$T11,0) | AN11: =SUM(Z11:AC11) | AO11: =SUM(AD11:AL11) | AP11: =SUM(AM11,AB11) | AQ11: =SUM(AA11) | AR11: =(AP11+AQ11)-3% | AS11: =SUM(AO11+AM11) | AT11: =SUM(AH11+AN11) | AU11: =SUM(AN11+AO11) | AV11: =SUM(AN11+AD11+AE11+AF11+AG11+AH11+AJ11+AK11+AL11) | AW11: =SUM(AD11+AE11+AF11+AG11+AI11+AJ11+AK11+AL11)
A12: =A11+1 | T12: =SUM(F12:S12) | U12: =(HLOOKUP(B12,F:T,A12,FALSE)/T12) | W12: =YEAR(C12) | X12: =MONTH(C12) | Y12: =WEEKNUM(C12,21) | Z12: =IFERROR(F12/$T12,0) | AA12: =IFERROR(G12/$T12,0) | AB12: =IFERROR(H12/$T12,0) | AC12: =IFERROR(I12/$T12,0) | AD12: =IFERROR(J12/$T12,0) | AE12: =IFERROR(K12/$T12,0) | AF12: =IFERROR(L12/$T12,0) | AG12: =IFERROR(M12/$T12,0) | ... AM12: =IFERROR(S12/$T12,0) | AN12: =SUM(Z12:AC12) | AO12: =SUM(AD12:AL12) | AP12: =SUM(AM12,AB12) | AQ12: =SUM(AA12) | AR12: =(AP12+AQ12)-3% | AS12: =SUM(AO12+AM12) | AT12: =SUM(AH12+AN12) | AU12: =SUM(AN12+AO12) | AV12: =SUM(AN12+AD12+AE12+AF12+AG12+AH12+AJ12+AK12+AL12) | AW12: =SUM(AD12+AE12+AF12+AG12+AI12+AJ12+AK12+AL12)
A13: =A12+1 | T13: =SUM(F13:S13) | U13: =(HLOOKUP(B13,F:T,A13,FALSE)/T13) | W13: =YEAR(C13) | X13: =MONTH(C13) | Y13: =WEEKNUM(C13,21) | Z13: =IFERROR(F13/$T13,0) | AA13: =IFERROR(G13/$T13,0) | AB13: =IFERROR(H13/$T13,0) | AC13: =IFERROR(I13/$T13,0) | AD13: =IFERROR(J13/$T13,0) | AE13: =IFERROR(K13/$T13,0) | AF13: =IFERROR(L13/$T13,0) | AG13: =IFERROR(M13/$T13,0) | ... AM13: =IFERROR(S13/$T13,0) | AN13: =SUM(Z13:AC13) | AO13: =SUM(AD13:AL13) | AP13: =SUM(AM13,AB13) | AQ13: =SUM(AA13) | AR13: =(AP13+AQ13)-3% | AS13: =SUM(AO13+AM13) | AT13: =SUM(AH13+AN13) | AU13: =SUM(AN13+AO13) | AV13: =SUM(AN13+AD13+AE13+AF13+AG13+AH13+AJ13+AK13+AL13) | AW13: =SUM(AD13+AE13+AF13+AG13+AI13+AJ13+AK13+AL13)
A14: =A13+1 | T14: =SUM(F14:S14) | U14: =(HLOOKUP(B14,F:T,A14,FALSE)/T14) | W14: =YEAR(C14) | X14: =MONTH(C14) | Y14: =WEEKNUM(C14,21) | Z14: =IFERROR(F14/$T14,0) | AA14: =IFERROR(G14/$T14,0) | AB14: =IFERROR(H14/$T14,0) | AC14: =IFERROR(I14/$T14,0) | AD14: =IFERROR(J14/$T14,0) | AE14: =IFERROR(K14/$T14,0) | AF14: =IFERROR(L14/$T14,0) | AG14: =IFERROR(M14/$T14,0) | ... AM14: =IFERROR(S14/$T14,0) | AN14: =SUM(Z14:AC14) | AO14: =SUM(AD14:AL14) | AP14: =SUM(AM14,AB14) | AQ14: =SUM(AA14) | AR14: =(AP14+AQ14)-3% | AS14: =SUM(AO14+AM14) | AT14: =SUM(AH14+AN14) | AU14: =SUM(AN14+AO14) | AV14: =SUM(AN14+AD14+AE14+AF14+AG14+AH14+AJ14+AK14+AL14) | AW14: =SUM(AD14+AE14+AF14+AG14+AI14+AJ14+AK14+AL14)
A15: =A14+1 | T15: =SUM(F15:S15) | U15: =(HLOOKUP(B15,F:T,A15,FALSE)/T15) | W15: =YEAR(C15) | X15: =MONTH(C15) | Y15: =WEEKNUM(C15,21) | Z15: =IFERROR(F15/$T15,0) | AA15: =IFERROR(G15/$T15,0) | AB15: =IFERROR(H15/$T15,0) | AC15: =IFERROR(I15/$T15,0) | AD15: =IFERROR(J15/$T15,0) | AE15: =IFERROR(K15/$T15,0) | AF15: =IFERROR(L15/$T15,0) | AG15: =IFERROR(M15/$T15,0) | ... AM15: =IFERROR(S15/$T15,0) | AN15: =SUM(Z15:AC15) | AO15: =SUM(AD15:AL15) | AP15: =SUM(AM15,AB15) | AQ15: =SUM(AA15) | AR15: =(AP15+AQ15)-3% | AS15: =SUM(AO15+AM15) | AT15: =SUM(AH15+AN15) | AU15: =SUM(AN15+AO15) | AV15: =SUM(AN15+AD15+AE15+AF15+AG15+AH15+AJ15+AK15+AL15) | AW15: =SUM(AD15+AE15+AF15+AG15+AI15+AJ15+AK15+AL15)
A16: =A15+1 | T16: =SUM(F16:S16) | U16: =(HLOOKUP(B16,F:T,A16,FALSE)/T16) | W16: =YEAR(C16) | X16: =MONTH(C16) | Y16: =WEEKNUM(C16,21) | Z16: =IFERROR(F16/$T16,0) | AA16: =IFERROR(G16/$T16,0) | AB16: =IFERROR(H16/$T16,0) | AC16: =IFERROR(I16/$T16,0) | AD16: =IFERROR(J16/$T16,0) | AE16: =IFERROR(K16/$T16,0) | AF16: =IFERROR(L16/$T16,0) | AG16: =IFERROR(M16/$T16,0) | ... AM16: =IFERROR(S16/$T16,0) | AN16: =SUM(Z16:AC16) | AO16: =SUM(AD16:AL16) | AP16: =SUM(AM16,AB16) | AQ16: =SUM(AA16) | AR16: =(AP16+AQ16)-3% | AS16: =SUM(AO16+AM16) | AT16: =SUM(AH16+AN16) | AU16: =SUM(AN16+AO16) | AV16: =SUM(AN16+AD16+AE16+AF16+AG16+AH16+AJ16+AK16+AL16) | AW16: =SUM(AD16+AE16+AF16+AG16+AI16+AJ16+AK16+AL16)
A17: =A16+1 | T17: =SUM(F17:S17) | U17: =(HLOOKUP(B17,F:T,A17,FALSE)/T17) | W17: =YEAR(C17) | X17: =MONTH(C17) | Y17: =WEEKNUM(C17,21) | Z17: =IFERROR(F17/$T17,0) | AA17: =IFERROR(G17/$T17,0) | AB17: =IFERROR(H17/$T17,0) | AC17: =IFERROR(I17/$T17,0) | AD17: =IFERROR(J17/$T17,0) | AE17: =IFERROR(K17/$T17,0) | AF17: =IFERROR(L17/$T17,0) | AG17: =IFERROR(M17/$T17,0) | ... AM17: =IFERROR(S17/$T17,0) | AN17: =SUM(Z17:AC17) | AO17: =SUM(AD17:AL17) | AP17: =SUM(AM17,AB17) | AQ17: =SUM(AA17) | AR17: =(AP17+AQ17)-3% | AS17: =SUM(AO17+AM17) | AT17: =SUM(AH17+AN17) | AU17: =SUM(AN17+AO17) | AV17: =SUM(AN17+AD17+AE17+AF17+AG17+AH17+AJ17+AK17+AL17) | AW17: =SUM(AD17+AE17+AF17+AG17+AI17+AJ17+AK17+AL17)
... A27: =A26+1 | T27: =SUM(F27:S27) | U27: =(HLOOKUP(B27,F:T,A27,FALSE)/T27) | W27: =YEAR(C27) | X27: =MONTH(C27) | Y27: =WEEKNUM(C27,21) | Z27: =IFERROR(F27/$T27,0) | AA27: =IFERROR(G27/$T27,0) | AB27: =IFERROR(H27/$T27,0) | AC27: =IFERROR(I27/$T27,0) | AD27: =IFERROR(J27/$T27,0) | AE27: =IFERROR(K27/$T27,0) | AF27: =IFERROR(L27/$T27,0) | AG27: =IFERROR(M27/$T27,0) | ... AM27: =IFERROR(S27/$T27,0) | AN27: =SUM(Z27:AC27) | AO27: =SUM(AD27:AL27) | AP27: =SUM(AM27,AB27) | AQ27: =SUM(AA27) | AR27: =(AP27+AQ27)-3% | AS27: =SUM(AO27+AM27) | AT27: =SUM(AH27+AN27) | AU27: =SUM(AN27+AO27) | AV27: =SUM(AN27+AD27+AE27+AF27+AG27+AH27+AJ27+AK27+AL27) | AW27: =SUM(AD27+AE27+AF27+AG27+AI27+AJ27+AK27+AL27)
A28: =A27+1 | T28: =SUM(F28:S28) | U28: =(HLOOKUP(B28,F:T,A28,FALSE)/T28) | W28: 2026 | X28: 2 | Y28: 8 | Z28: =IFERROR(F28/$T28,0) | AA28: =IFERROR(G28/$T28,0) | AB28: =IFERROR(H28/$T28,0) | AC28: =IFERROR(I28/$T28,0) | AD28: =IFERROR(J28/$T28,0) | AE28: =IFERROR(K28/$T28,0) | AF28: =IFERROR(L28/$T28,0) | AG28: =IFERROR(M28/$T28,0) | ... AM28: =IFERROR(S28/$T28,0) | AN28: =SUM(Z28:AC28) | AO28: =SUM(AD28:AL28) | AP28: =SUM(AM28,AB28) | AQ28: =SUM(AA28) | AR28: =(AP28+AQ28)-3% | AS28: =SUM(AO28+AM28) | AT28: =SUM(AH28+AN28) | AU28: =SUM(AN28+AO28) | AV28: =SUM(AN28+AD28+AE28+AF28+AG28+AH28+AJ28+AK28+AL28) | AW28: =SUM(AD28+AE28+AF28+AG28+AI28+AJ28+AK28+AL28)
A29: =A28+1 | T29: =SUM(F29:S29) | U29: =(HLOOKUP(B29,F:T,A29,FALSE)/T29) | W29: 2026 | X29: 2 | Y29: 8 | Z29: =IFERROR(F29/$T29,0) | AA29: =IFERROR(G29/$T29,0) | AB29: =IFERROR(H29/$T29,0) | AC29: =IFERROR(I29/$T29,0) | AD29: =IFERROR(J29/$T29,0) | AE29: =IFERROR(K29/$T29,0) | AF29: =IFERROR(L29/$T29,0) | AG29: =IFERROR(M29/$T29,0) | ... AM29: =IFERROR(S29/$T29,0) | AN29: =SUM(Z29:AC29) | AO29: =SUM(AD29:AL29) | AP29: =SUM(AM29,AB29) | AQ29: =SUM(AA29) | AR29: =(AP29+AQ29)-3% | AS29: =SUM(AO29+AM29) | AT29: =SUM(AH29+AN29) | AU29: =SUM(AN29+AO29) | AV29: =SUM(AN29+AD29+AE29+AF29+AG29+AH29+AJ29+AK29+AL29) | AW29: =SUM(AD29+AE29+AF29+AG29+AI29+AJ29+AK29+AL29)
A30: =A29+1 | T30: =SUM(F30:S30) | U30: =(HLOOKUP(B30,F:T,A30,FALSE)/T30) | W30: 2026 | X30: 2 | Y30: 8 | Z30: =IFERROR(F30/$T30,0) | AA30: =IFERROR(G30/$T30,0) | AB30: =IFERROR(H30/$T30,0) | AC30: =IFERROR(I30/$T30,0) | AD30: =IFERROR(J30/$T30,0) | AE30: =IFERROR(K30/$T30,0) | AF30: =IFERROR(L30/$T30,0) | AG30: =IFERROR(M30/$T30,0) | ... AM30: =IFERROR(S30/$T30,0) | AN30: =SUM(Z30:AC30) | AO30: =SUM(AD30:AL30) | AP30: =SUM(AM30,AB30) | AQ30: =SUM(AA30) | AR30: =(AP30+AQ30)-3% | AS30: =SUM(AO30+AM30) | AT30: =SUM(AH30+AN30) | AU30: =SUM(AN30+AO30) | AV30: =SUM(AN30+AD30+AE30+AF30+AG30+AH30+AJ30+AK30+AL30) | AW30: =SUM(AD30+AE30+AF30+AG30+AI30+AJ30+AK30+AL30)
A31: =A30+1 | T31: =SUM(F31:S31) | U31: =(HLOOKUP(B31,F:T,A31,FALSE)/T31) | W31: 2026 | X31: 2 | Y31: 8 | Z31: =IFERROR(F31/$T31,0) | AA31: =IFERROR(G31/$T31,0) | AB31: =IFERROR(H31/$T31,0) | AC31: =IFERROR(I31/$T31,0) | AD31: =IFERROR(J31/$T31,0) | AE31: =IFERROR(K31/$T31,0) | AF31: =IFERROR(L31/$T31,0) | AG31: =IFERROR(M31/$T31,0) | ... AM31: =IFERROR(S31/$T31,0) | AN31: =SUM(Z31:AC31) | AO31: =SUM(AD31:AL31) | AP31: =SUM(AM31,AB31) | AQ31: =SUM(AA31) | AR31: =(AP31+AQ31)-3% | AS31: =SUM(AO31+AM31) | AT31: =SUM(AH31+AN31) | AU31: =SUM(AN31+AO31) | AV31: =SUM(AN31+AD31+AE31+AF31+AG31+AH31+AJ31+AK31+AL31) | AW31: =SUM(AD31+AE31+AF31+AG31+AI31+AJ31+AK31+AL31)
A32: =A31+1 | T32: =SUM(F32:S32) | U32: =(HLOOKUP(B32,F:T,A32,FALSE)/T32) | W32: 2026 | X32: 2 | Y32: 8 | Z32: =IFERROR(F32/$T32,0) | AA32: =IFERROR(G32/$T32,0) | AB32: =IFERROR(H32/$T32,0) | AC32: =IFERROR(I32/$T32,0) | AD32: =IFERROR(J32/$T32,0) | AE32: =IFERROR(K32/$T32,0) | AF32: =IFERROR(L32/$T32,0) | AG32: =IFERROR(M32/$T32,0) | ... AM32: =IFERROR(S32/$T32,0) | AN32: =SUM(Z32:AC32) | AO32: =SUM(AD32:AL32) | AP32: =SUM(AM32,AB32) | AQ32: =SUM(AA32) | AR32: =(AP32+AQ32)-3% | AS32: =SUM(AO32+AM32) | AT32: =SUM(AH32+AN32) | AU32: =SUM(AN32+AO32) | AV32: =SUM(AN32+AD32+AE32+AF32+AG32+AH32+AJ32+AK32+AL32) | AW32: =SUM(AD32+AE32+AF32+AG32+AI32+AJ32+AK32+AL32)
A33: =A32+1 | T33: =SUM(F33:S33) | U33: =(HLOOKUP(B33,F:T,A33,FALSE)/T33) | W33: =YEAR(C33) | X33: =MONTH(C33) | Y33: =WEEKNUM(C33,21) | Z33: =IFERROR(F33/$T33,0) | AA33: =IFERROR(G33/$T33,0) | AB33: =IFERROR(H33/$T33,0) | AC33: =IFERROR(I33/$T33,0) | AD33: =IFERROR(J33/$T33,0) | AE33: =IFERROR(K33/$T33,0) | AF33: =IFERROR(L33/$T33,0) | AG33: =IFERROR(M33/$T33,0) | ... AM33: =IFERROR(S33/$T33,0) | AN33: =SUM(Z33:AC33) | AO33: =SUM(AD33:AL33) | AP33: =SUM(AM33,AB33) | AQ33: =SUM(AA33) | AR33: =(AP33+AQ33)-3% | AS33: =SUM(AO33+AM33) | AT33: =SUM(AH33+AN33) | AU33: =SUM(AN33+AO33) | AV33: =SUM(AN33+AD33+AE33+AF33+AG33+AH33+AJ33+AK33+AL33) | AW33: =SUM(AD33+AE33+AF33+AG33+AI33+AJ33+AK33+AL33)
A34: =A33+1 | T34: =SUM(F34:S34) | U34: =(HLOOKUP(B34,F:T,A34,FALSE)/T34) | W34: =YEAR(C34) | X34: =MONTH(C34) | Y34: =WEEKNUM(C34,21) | Z34: =IFERROR(F34/$T34,0) | AA34: =IFERROR(G34/$T34,0) | AB34: =IFERROR(H34/$T34,0) | AC34: =IFERROR(I34/$T34,0) | AD34: =IFERROR(J34/$T34,0) | AE34: =IFERROR(K34/$T34,0) | AF34: =IFERROR(L34/$T34,0) | AG34: =IFERROR(M34/$T34,0) | ... AM34: =IFERROR(S34/$T34,0) | AN34: =SUM(Z34:AC34) | AO34: =SUM(AD34:AL34) | AP34: =SUM(AM34,AB34) | AQ34: =SUM(AA34) | AR34: =(AP34+AQ34)-3% | AS34: =SUM(AO34+AM34) | AT34: =SUM(AH34+AN34) | AU34: =SUM(AN34+AO34) | AV34: =SUM(AN34+AD34+AE34+AF34+AG34+AH34+AJ34+AK34+AL34) | AW34: =SUM(AD34+AE34+AF34+AG34+AI34+AJ34+AK34+AL34)
A35: =A34+1 | T35: =SUM(F35:S35) | U35: =(HLOOKUP(B35,F:T,A35,FALSE)/T35) | W35: =YEAR(C35) | X35: =MONTH(C35) | Y35: =WEEKNUM(C35,21) | Z35: =IFERROR(F35/$T35,0) | AA35: =IFERROR(G35/$T35,0) | AB35: =IFERROR(H35/$T35,0) | AC35: =IFERROR(I35/$T35,0) | AD35: =IFERROR(J35/$T35,0) | AE35: =IFERROR(K35/$T35,0) | AF35: =IFERROR(L35/$T35,0) | AG35: =IFERROR(M35/$T35,0) | ... AM35: =IFERROR(S35/$T35,0) | AN35: =SUM(Z35:AC35) | AO35: =SUM(AD35:AL35) | AP35: =SUM(AM35,AB35) | AQ35: =SUM(AA35) | AR35: =(AP35+AQ35)-3% | AS35: =SUM(AO35+AM35) | AT35: =SUM(AH35+AN35) | AU35: =SUM(AN35+AO35) | AV35: =SUM(AN35+AD35+AE35+AF35+AG35+AH35+AJ35+AK35+AL35) | AW35: =SUM(AD35+AE35+AF35+AG35+AI35+AJ35+AK35+AL35)
A36: =A35+1 | T36: =SUM(F36:S36) | U36: =(HLOOKUP(B36,F:T,A36,FALSE)/T36) | W36: =YEAR(C36) | X36: =MONTH(C36) | Y36: =WEEKNUM(C36,21) | Z36: =IFERROR(F36/$T36,0) | AA36: =IFERROR(G36/$T36,0) | AB36: =IFERROR(H36/$T36,0) | AC36: =IFERROR(I36/$T36,0) | AD36: =IFERROR(J36/$T36,0) | AE36: =IFERROR(K36/$T36,0) | AF36: =IFERROR(L36/$T36,0) | AG36: =IFERROR(M36/$T36,0) | ... AM36: =IFERROR(S36/$T36,0) | AN36: =SUM(Z36:AC36) | AO36: =SUM(AD36:AL36) | AP36: =SUM(AM36,AB36) | AQ36: =SUM(AA36) | AR36: =(AP36+AQ36)-3% | AS36: =SUM(AO36+AM36) | AT36: =SUM(AH36+AN36) | AU36: =SUM(AN36+AO36) | AV36: =SUM(AN36+AD36+AE36+AF36+AG36+AH36+AJ36+AK36+AL36) | AW36: =SUM(AD36+AE36+AF36+AG36+AI36+AJ36+AK36+AL36)
A37: =A36+1 | T37: =SUM(F37:S37) | U37: =(HLOOKUP(B37,F:T,A37,FALSE)/T37) | W37: =YEAR(C37) | X37: =MONTH(C37) | Y37: =WEEKNUM(C37,21) | Z37: =IFERROR(F37/$T37,0) | AA37: =IFERROR(G37/$T37,0) | AB37: =IFERROR(H37/$T37,0) | AC37: =IFERROR(I37/$T37,0) | AD37: =IFERROR(J37/$T37,0) | AE37: =IFERROR(K37/$T37,0) | AF37: =IFERROR(L37/$T37,0) | AG37: =IFERROR(M37/$T37,0) | ... AM37: =IFERROR(S37/$T37,0) | AN37: =SUM(Z37:AC37) | AO37: =SUM(AD37:AL37) | AP37: =SUM(AM37,AB37) | AQ37: =SUM(AA37) | AR37: =(AP37+AQ37)-3% | AS37: =SUM(AO37+AM37) | AT37: =SUM(AH37+AN37) | AU37: =SUM(AN37+AO37) | AV37: =SUM(AN37+AD37+AE37+AF37+AG37+AH37+AJ37+AK37+AL37) | AW37: =SUM(AD37+AE37+AF37+AG37+AI37+AJ37+AK37+AL37)
A38: =A37+1 | T38: =SUM(F38:S38) | U38: =(HLOOKUP(B38,F:T,A38,FALSE)/T38) | W38: =YEAR(C38) | X38: =MONTH(C38) | Y38: =WEEKNUM(C38,21) | Z38: =IFERROR(F38/$T38,0) | AA38: =IFERROR(G38/$T38,0) | AB38: =IFERROR(H38/$T38,0) | AC38: =IFERROR(I38/$T38,0) | AD38: =IFERROR(J38/$T38,0) | AE38: =IFERROR(K38/$T38,0) | AF38: =IFERROR(L38/$T38,0) | AG38: =IFERROR(M38/$T38,0) | ... AM38: =IFERROR(S38/$T38,0) | AN38: =SUM(Z38:AC38) | AO38: =SUM(AD38:AL38) | AP38: =SUM(AM38,AB38) | AQ38: =SUM(AA38) | AR38: =(AP38+AQ38)-3% | AS38: =SUM(AO38+AM38) | AT38: =SUM(AH38+AN38) | AU38: =SUM(AN38+AO38) | AV38: =SUM(AN38+AD38+AE38+AF38+AG38+AH38+AJ38+AK38+AL38) | AW38: =SUM(AD38+AE38+AF38+AG38+AI38+AJ38+AK38+AL38)
A39: =A38+1 | T39: =SUM(F39:S39) | U39: =(HLOOKUP(B39,F:T,A39,FALSE)/T39) | W39: =YEAR(C39) | X39: =MONTH(C39) | Y39: =WEEKNUM(C39,21) | Z39: =IFERROR(F39/$T39,0) | AA39: =IFERROR(G39/$T39,0) | AB39: =IFERROR(H39/$T39,0) | AC39: =IFERROR(I39/$T39,0) | AD39: =IFERROR(J39/$T39,0) | AE39: =IFERROR(K39/$T39,0) | AF39: =IFERROR(L39/$T39,0) | AG39: =IFERROR(M39/$T39,0) | ... AM39: =IFERROR(S39/$T39,0) | AN39: =SUM(Z39:AC39) | AO39: =SUM(AD39:AL39) | AP39: =SUM(AM39,AB39) | AQ39: =SUM(AA39) | AR39: =(AP39+AQ39)-3% | AS39: =SUM(AO39+AM39) | AT39: =SUM(AH39+AN39) | AU39: =SUM(AN39+AO39) | AV39: =SUM(AN39+AD39+AE39+AF39+AG39+AH39+AJ39+AK39+AL39) | AW39: =SUM(AD39+AE39+AF39+AG39+AI39+AJ39+AK39+AL39)
A40: =A39+1 | T40: =SUM(F40:S40) | U40: =(HLOOKUP(B40,F:T,A40,FALSE)/T40) | W40: =YEAR(C40) | X40: =MONTH(C40) | Y40: =WEEKNUM(C40,21) | Z40: =IFERROR(F40/$T40,0) | AA40: =IFERROR(G40/$T40,0) | AB40: =IFERROR(H40/$T40,0) | AC40: =IFERROR(I40/$T40,0) | AD40: =IFERROR(J40/$T40,0) | AE40: =IFERROR(K40/$T40,0) | AF40: =IFERROR(L40/$T40,0) | AG40: =IFERROR(M40/$T40,0) | ... AM40: =IFERROR(S40/$T40,0) | AN40: =SUM(Z40:AC40) | AO40: =SUM(AD40:AL40) | AP40: =SUM(AM40,AB40) | AQ40: =SUM(AA40) | AR40: =(AP40+AQ40)-3% | AS40: =SUM(AO40+AM40) | AT40: =SUM(AH40+AN40) | AU40: =SUM(AN40+AO40) | AV40: =SUM(AN40+AD40+AE40+AF40+AG40+AH40+AJ40+AK40+AL40) | AW40: =SUM(AD40+AE40+AF40+AG40+AI40+AJ40+AK40+AL40)
A41: =A40+1 | T41: =SUM(F41:S41) | U41: =(HLOOKUP(B41,F:T,A41,FALSE)/T41) | W41: =YEAR(C41) | X41: =MONTH(C41) | Y41: =WEEKNUM(C41,21) | Z41: =IFERROR(F41/$T41,0) | AA41: =IFERROR(G41/$T41,0) | AB41: =IFERROR(H41/$T41,0) | AC41: =IFERROR(I41/$T41,0) | AD41: =IFERROR(J41/$T41,0) | AE41: =IFERROR(K41/$T41,0) | AF41: =IFERROR(L41/$T41,0) | AG41: =IFERROR(M41/$T41,0) | ... AM41: =IFERROR(S41/$T41,0) | AN41: =SUM(Z41:AC41) | AO41: =SUM(AD41:AL41) | AP41: =SUM(AM41,AB41) | AQ41: =SUM(AA41) | AR41: =(AP41+AQ41)-3% | AS41: =SUM(AO41+AM41) | AT41: =SUM(AH41+AN41) | AU41: =SUM(AN41+AO41) | AV41: =SUM(AN41+AD41+AE41+AF41+AG41+AH41+AJ41+AK41+AL41) | AW41: =SUM(AD41+AE41+AF41+AG41+AI41+AJ41+AK41+AL41)
A42: =A41+1 | T42: =SUM(F42:S42) | U42: =(HLOOKUP(B42,F:T,A42,FALSE)/T42) | W42: =YEAR(C42) | X42: =MONTH(C42) | Y42: =WEEKNUM(C42,21) | Z42: =IFERROR(F42/$T42,0) | AA42: =IFERROR(G42/$T42,0) | AB42: =IFERROR(H42/$T42,0) | AC42: =IFERROR(I42/$T42,0) | AD42: =IFERROR(J42/$T42,0) | AE42: =IFERROR(K42/$T42,0) | AF42: =IFERROR(L42/$T42,0) | AG42: =IFERROR(M42/$T42,0) | ... AM42: =IFERROR(S42/$T42,0) | AN42: =SUM(Z42:AC42) | AO42: =SUM(AD42:AL42) | AP42: =SUM(AM42,AB42) | AQ42: =SUM(AA42) | AR42: =(AP42+AQ42)-3% | AS42: =SUM(AO42+AM42) | AT42: =SUM(AH42+AN42) | AU42: =SUM(AN42+AO42) | AV42: =SUM(AN42+AD42+AE42+AF42+AG42+AH42+AJ42+AK42+AL42) | AW42: =SUM(AD42+AE42+AF42+AG42+AI42+AJ42+AK42+AL42)
A43: =A42+1 | T43: =SUM(F43:S43) | U43: =(HLOOKUP(B43,F:T,A43,FALSE)/T43) | W43: =YEAR(C43) | X43: =MONTH(C43) | Y43: =WEEKNUM(C43,21) | Z43: =IFERROR(F43/$T43,0) | AA43: =IFERROR(G43/$T43,0) | AB43: =IFERROR(H43/$T43,0) | AC43: =IFERROR(I43/$T43,0) | AD43: =IFERROR(J43/$T43,0) | AE43: =IFERROR(K43/$T43,0) | AF43: =IFERROR(L43/$T43,0) | AG43: =IFERROR(M43/$T43,0) | ... AM43: =IFERROR(S43/$T43,0) | AN43: =SUM(Z43:AC43) | AO43: =SUM(AD43:AL43) | AP43: =SUM(AM43,AB43) | AQ43: =SUM(AA43) | AR43: =(AP43+AQ43)-3% | AS43: =SUM(AO43+AM43) | AT43: =SUM(AH43+AN43) | AU43: =SUM(AN43+AO43) | AV43: =SUM(AN43+AD43+AE43+AF43+AG43+AH43+AJ43+AK43+AL43) | AW43: =SUM(AD43+AE43+AF43+AG43+AI43+AJ43+AK43+AL43)
A44: =A43+1 | T44: =SUM(F44:S44) | U44: =(HLOOKUP(B44,F:T,A44,FALSE)/T44) | W44: =YEAR(C44) | X44: =MONTH(C44) | Y44: =WEEKNUM(C44,21) | Z44: =IFERROR(F44/$T44,0) | AA44: =IFERROR(G44/$T44,0) | AB44: =IFERROR(H44/$T44,0) | AC44: =IFERROR(I44/$T44,0) | AD44: =IFERROR(J44/$T44,0) | AE44: =IFERROR(K44/$T44,0) | AF44: =IFERROR(L44/$T44,0) | AG44: =IFERROR(M44/$T44,0) | ... AM44: =IFERROR(S44/$T44,0) | AN44: =SUM(Z44:AC44) | AO44: =SUM(AD44:AL44) | AP44: =SUM(AM44,AB44) | AQ44: =SUM(AA44) | AR44: =(AP44+AQ44)-3% | AS44: =SUM(AO44+AM44) | AT44: =SUM(AH44+AN44) | AU44: =SUM(AN44+AO44) | AV44: =SUM(AN44+AD44+AE44+AF44+AG44+AH44+AJ44+AK44+AL44) | AW44: =SUM(AD44+AE44+AF44+AG44+AI44+AJ44+AK44+AL44)
... A102: =A101+1 | T102: =SUM(F102:S102) | U102: =(HLOOKUP(B102,F:T,A102,FALSE)/T102) | W102: =YEAR(C102) | X102: =MONTH(C102) | Y102: =WEEKNUM(C102,21) | Z102: =IFERROR(F102/$T102,0) | AA102: =IFERROR(G102/$T102,0) | AB102: =IFERROR(H102/$T102,0) | AC102: =IFERROR(I102/$T102,0) | AD102: =IFERROR(J102/$T102,0) | AE102: =IFERROR(K102/$T102,0) | AF102: =IFERROR(L102/$T102,0) | AG102: =IFERROR(M102/$T102,0) | ... AM102: =IFERROR(S102/$T102,0) | AN102: =SUM(Z102:AC102) | AO102: =SUM(AD102:AL102) | AP102: =SUM(AM102,AB102) | AQ102: =SUM(AA102) | AR102: =(AP102+AQ102)-3% | AS102: =SUM(AO102+AM102) | AT102: =SUM(AH102+AN102) | AU102: =SUM(AN102+AO102) | AV102: =SUM(AN102+AD102+AE102+AF102+AG102+AH102+AJ102+AK102+AL102) | AW102: =SUM(AD102+AE102+AF102+AG102+AI102+AJ102+AK102+AL102)
A103: =A102+1 | T103: =SUM(F103:S103) | U103: =(HLOOKUP(B103,F:T,A103,FALSE)/T103) | W103: =YEAR(C103) | X103: =MONTH(C103) | Y103: =WEEKNUM(C103,21) | Z103: =IFERROR(F103/$T103,0) | AA103: =IFERROR(G103/$T103,0) | AB103: =IFERROR(H103/$T103,0) | AC103: =IFERROR(I103/$T103,0) | AD103: =IFERROR(J103/$T103,0) | AE103: =IFERROR(K103/$T103,0) | AF103: =IFERROR(L103/$T103,0) | AG103: =IFERROR(N103/$T103,0) | AH103: =IFERROR(O103/$T103,0) | AI103: =IFERROR(P103/$T103,0) | AJ103: =IFERROR(Q103/$T103,0) | AK103: =IFERROR(R103/$T103,0) | AL103: =IFERROR(K103/$T103,0) | AN103: =SUM(Z103:AC103) | AO103: =SUM(AD103:AL103) | AP103: =SUM(AM103,AB103) | AQ103: =SUM(AA103) | AR103: =(AP103+AQ103)-3% | AS103: =SUM(AO103+AM103) | AT103: =SUM(AH103+AN103) | AU103: =SUM(AN103+AO103) | AV103: =SUM(AN103+AD103+AE103+AF103+AG103+AH103+AJ103+AK103+AL103) | AW103: =SUM(AD103+AE103+AF103+AG103+AI103+AJ103+AK103+AL103)
A104: =A103+1 | T104: =SUM(F104:S104) | U104: =(HLOOKUP(B104,F:T,A104,FALSE)/T104) | W104: =YEAR(C104) | X104: =MONTH(C104) | Y104: =WEEKNUM(C104,21) | Z104: =IFERROR(F104/$T104,0) | AA104: =IFERROR(G104/$T104,0) | AB104: =IFERROR(H104/$T104,0) | AC104: =IFERROR(I104/$T104,0) | AD104: =IFERROR(J104/$T104,0) | AE104: =IFERROR(K104/$T104,0) | AF104: =IFERROR(L104/$T104,0) | AG104: =IFERROR(N104/$T104,0) | AH104: =IFERROR(O104/$T104,0) | AI104: =IFERROR(P104/$T104,0) | AJ104: =IFERROR(Q104/$T104,0) | AK104: =IFERROR(R104/$T104,0) | AL104: =IFERROR(K104/$T104,0) | AN104: =SUM(Z104:AC104) | AO104: =SUM(AD104:AL104) | AP104: =SUM(AM104,AB104) | AQ104: =SUM(AA104) | AR104: =(AP104+AQ104)-3% | AS104: =SUM(AO104+AM104) | AT104: =SUM(AH104+AN104) | AU104: =SUM(AN104+AO104) | AV104: =SUM(AN104+AD104+AE104+AF104+AG104+AH104+AJ104+AK104+AL104) | AW104: =SUM(AD104+AE104+AF104+AG104+AI104+AJ104+AK104+AL104)
A105: =A104+1 | T105: =SUM(F105:S105) | U105: =(HLOOKUP(B105,F:T,A105,FALSE)/T105) | W105: =YEAR(C105) | X105: =MONTH(C105) | Y105: =WEEKNUM(C105,21) | Z105: =IFERROR(F105/$T105,0) | AA105: =IFERROR(G105/$T105,0) | AB105: =IFERROR(H105/$T105,0) | AC105: =IFERROR(I105/$T105,0) | AD105: =IFERROR(J105/$T105,0) | AE105: =IFERROR(K105/$T105,0) | AF105: =IFERROR(L105/$T105,0) | AG105: =IFERROR(N105/$T105,0) | AH105: =IFERROR(O105/$T105,0) | AI105: =IFERROR(P105/$T105,0) | AJ105: =IFERROR(Q105/$T105,0) | AK105: =IFERROR(R105/$T105,0) | AL105: =IFERROR(K105/$T105,0) | AN105: =SUM(Z105:AC105) | AO105: =SUM(AD105:AL105) | AP105: =SUM(AM105,AB105) | AQ105: =SUM(AA105) | AR105: =(AP105+AQ105)-3% | AS105: =SUM(AO105+AM105) | AT105: =SUM(AH105+AN105) | AU105: =SUM(AN105+AO105) | AV105: =SUM(AN105+AD105+AE105+AF105+AG105+AH105+AJ105+AK105+AL105) | AW105: =SUM(AD105+AE105+AF105+AG105+AI105+AJ105+AK105+AL105)
A106: =A105+1 | T106: =SUM(F106:S106) | U106: =(HLOOKUP(B106,F:T,A106,FALSE)/T106) | W106: =YEAR(C106) | X106: =MONTH(C106) | Y106: =WEEKNUM(C106,21) | Z106: =IFERROR(F106/$T106,0) | AA106: =IFERROR(G106/$T106,0) | AB106: =IFERROR(H106/$T106,0) | AC106: =IFERROR(I106/$T106,0) | AD106: =IFERROR(J106/$T106,0) | AE106: =IFERROR(K106/$T106,0) | AF106: =IFERROR(L106/$T106,0) | AG106: =IFERROR(N106/$T106,0) | AH106: =IFERROR(O106/$T106,0) | AI106: =IFERROR(P106/$T106,0) | AJ106: =IFERROR(Q106/$T106,0) | AK106: =IFERROR(R106/$T106,0) | AL106: =IFERROR(K106/$T106,0) | AN106: =SUM(Z106:AC106) | AO106: =SUM(AD106:AL106) | AP106: =SUM(AM106,AB106) | AQ106: =SUM(AA106) | AR106: =(AP106+AQ106)-3% | AS106: =SUM(AO106+AM106) | AT106: =SUM(AH106+AN106) | AU106: =SUM(AN106+AO106) | AV106: =SUM(AN106+AD106+AE106+AF106+AG106+AH106+AJ106+AK106+AL106) | AW106: =SUM(AD106+AE106+AF106+AG106+AI106+AJ106+AK106+AL106)
...

Sheet PLANNING
B2: CARACTERISATIONS ERIC
B5: Semaine | C5: Matin | E5: Après-Midi
B6: Lundi | C6: JRM | D6: EMR | E6: GM | F6: ELA
B7: Mardi | C7: Q4 | D7: Flux dev | F7: PE/PP
B8: Mercredi | C8: DECLASSEMENT | E8: REFUS ou FILM
B9: Jeudi | C9: Caract Client
B10: Vendredi | C10: Caract Client

Sheet BILAN
C1: 2 | D1: 3 | E1: 4 | H1: 2 | I1: 3 | J1: 4 | M1: 2 | N1: 3 | O1: 4 | R1: 2 | S1: 3 | T1: 4 | W1: 2 | X1: 3 | Y1: 4 | AB1: 2 | AC1: 3 | AD1: 4 | AG1: 2 | AH1: 3 | AI1: 4 | AL1: 2 | AM1: 3 | AN1: 4 | AQ1: 2 | AR1: 3 | AS1: 4 | AT1: 5 | AW1: 2 | AX1: 3 | AY1: 4 | BB1: 2 | BC1: 3 | BD1: 4 | BG1: 2 | BH1: 3 | BI1: 4 | BL1: 2 | BM1: 3 | BN1: 4 | BQ1: 2 | BR1: 3 | BS1: 4
B2: JRM | G2: EMR | L2: CARTON | Q2: GM | V2: Q9 | AA2: FLUX DEV | AF2: PET B | AK2: PEPP | AP2: ELA | AV2: FILM | BA2: ACIER | BF2: ALU | BK2: PETIT ALU | BP2: REFUS
B3: Semaine | C3: Taux de pureté | D3: Contaminant A | E3: Objectif JRM | G3: Semaine | H3: Taux de pureté | I3: CC + REFUS | J3: Objectif EMR | L3: Semaine | M3: Taux de pureté | N3: CC + REFUS | O3: Objectif CARTON | Q3: Semaine | R3: Taux de pureté | S3: CC + REFUS | T3: Objectif GM | V3: Semaine | W3: Taux de pureté | X3: PET B | Y3: Objectif Q9 | AA3: Semaine | AB3: Taux de pureté | AC3: PET Q9 | AD3: Objectif FLUX DEV | AF3: Semaine | AG3: Taux de pureté | AH3: Contaminant | AI3: Objectif PET B | AK3: Semaine | AL3: Taux de pureté | AM3: FIBREUX + ELA | AN3: Objectif PEPP | AP3: Semaine | AQ3: Taux de pureté | AR3: FIBREUX | AS3: Objectif ELA | AT3: CC | AV3: Semaine | AW3: Taux de pureté | AX3: FIBREUX + CC | AY3: Objectif FILM | BA3: Semaine | BB3: Taux de pureté | BC3: Contaminant | BD3: Objectif ACIER | BF3: Semaine | BG3: Taux de pureté | BH3: Contaminant | BI3: Objectif ALU | BK3: Semaine | BL3: Taux de pureté | BM3: ALU | BN3: Objectif PEPP | BP3: Semaine | BQ3: Taux de pureté | BR3: FIBREUX + CC | BS3: Objectif REFUS
A4: =A5-1 | B4: =$A4 | C4: =VLOOKUP($B4,$B$13:$E$64,C$1,0) | D4: =VLOOKUP($B4,$B$13:$E$64,D$1,0) | E4: =VLOOKUP($B4,$B$13:$E$64,E$1,0) | G4: =$A4 | H4: =VLOOKUP($G4,$G$13:$J$64,H$1,0) | I4: =VLOOKUP($G4,$G$13:$J$64,I$1,0) | J4: =VLOOKUP($G4,$G$13:$J$64,J$1,0) | L4: =$A4 | M4: =VLOOKUP($G4,$L$13:$O$64,M$1,0) | N4: =VLOOKUP($G4,$L$13:$O$64,N$1,0) | O4: =VLOOKUP($G4,$L$13:$O$64,O$1,0) | Q4: =$A4 | R4: =VLOOKUP($G4,$Q$12:$T$63,R$1,0) | S4: =VLOOKUP($G4,$Q$13:$T$64,S$1,0) | T4: =VLOOKUP($G4,$Q$13:$T$64,T$1,0) | V4: =$A4 | W4: =VLOOKUP($A4,$V$12:$Y$63,W$1,0) | X4: =VLOOKUP($G4,$V$13:$Y$64,X$1,0) | Y4: =VLOOKUP($G4,$V$13:$Y$64,Y$1,0) | AA4: =$A4 | AB4: =VLOOKUP($G4,$AA$13:$AD$64,AB$1,0) | AC4: =VLOOKUP($G4,$AA$13:$AD$64,AC$1,0) | AD4: =VLOOKUP($G4,$AA$13:$AD$64,AD$1,0) | AF4: =$A4 | AG4: =VLOOKUP($G4,$AF$13:$AI$64,AG$1,0) | AH4: =VLOOKUP($G4,$AF$13:$AI$64,AH$1,0) | AI4: =VLOOKUP($G4,$AF$13:$AI$64,AI$1,0) | AK4: =$A4 | AL4: =VLOOKUP($G4,$AK$13:$AN$64,AL$1,0) | AM4: =VLOOKUP($G4,$AK$13:$AN$64,AM$1,0) | AN4: =VLOOKUP($G4,$AF$13:$AI$64,AN$1,0) | AP4: =$A4 | AQ4: =VLOOKUP($G4,$AP$13:$AT$64,AQ$1,0) | AR4: =VLOOKUP($G4,$AP$13:$AT$64,AR$1,0) | AS4: =VLOOKUP($G4,$AF$13:$AI$64,AS$1,0) | AT4: =VLOOKUP($G4,$AP$13:$AT$64,AT$1,0) | AV4: =$A4 | AW4: =VLOOKUP($G4,$AV$13:$AY$64,AW$1,0) | AX4: =VLOOKUP($G4,$AV$13:$AY$64,AX$1,0) | AY4: =VLOOKUP($G4,$AF$13:$AI$64,AY$1,0) | BA4: =$A4 | BB4: =VLOOKUP($G4,$BA$13:$BD$64,BB$1,0) | BC4: =VLOOKUP($G4,$BA$13:$BD$64,BC$1,0) | BD4: =VLOOKUP($G4,$AF$13:$AI$64,BD$1,0) | BF4: =$A4 | BG4: =VLOOKUP($G4,$BF$13:$BI$64,BG$1,0) | BH4: =VLOOKUP($G4,$BF$13:$BI$64,BH$1,0) | BI4: =VLOOKUP($G4,$AF$13:$AI$64,BI$1,0) | BK4: =$A4 | BL4: =VLOOKUP($G4,$BK$13:$BN$64,BG$1,0) | BM4: =VLOOKUP($G4,$BK$13:$BN$64,BM$1,0) | BN4: =VLOOKUP($G4,$AF$13:$AI$64,BN$1,0) | BP4: =$A4 | BQ4: =VLOOKUP($G4,$BP$13:$BS$64,BQ$1,0) | BR4: =VLOOKUP($G4,$BP$13:$BS$64,BR$1,0) | BS4: =VLOOKUP($G4,$AF$13:$AI$64,BS$1,0)
A5: =A6-1 | B5: =$A5 | C5: =VLOOKUP($B5,$B$13:$E$64,C$1,0) | D5: =VLOOKUP($B5,$B$13:$E$64,D$1,0) | E5: =VLOOKUP($B5,$B$13:$E$64,E$1,0) | G5: =$A5 | H5: =VLOOKUP($G5,$G$13:$J$64,H$1,0) | I5: =VLOOKUP($G5,$G$13:$J$64,I$1,0) | J5: =VLOOKUP($G5,$G$13:$J$64,J$1,0) | L5: =$A5 | M5: =VLOOKUP($G5,$L$13:$O$64,M$1,0) | N5: =VLOOKUP($G5,$L$13:$O$64,N$1,0) | O5: =VLOOKUP($G5,$L$13:$O$64,O$1,0) | Q5: =$A5 | R5: =VLOOKUP($G5,$Q$12:$T$63,R$1,0) | S5: =VLOOKUP($G5,$Q$13:$T$64,S$1,0) | T5: =VLOOKUP($G5,$Q$13:$T$64,T$1,0) | V5: =$A5 | W5: =VLOOKUP($G5,$V$12:$Y$63,W$1,0) | X5: =VLOOKUP($G5,$V$13:$Y$64,X$1,0) | Y5: =VLOOKUP($G5,$V$13:$Y$64,Y$1,0) | AA5: =$A5 | AB5: =VLOOKUP($G5,$AA$13:$AD$64,AB$1,0) | AC5: =VLOOKUP($G5,$AA$13:$AD$64,AC$1,0) | AD5: =VLOOKUP($G5,$AA$13:$AD$64,AD$1,0) | AF5: =$A5 | AG5: =VLOOKUP($G5,$AF$13:$AI$64,AG$1,0) | AH5: =VLOOKUP($G5,$AF$13:$AI$64,AH$1,0) | AI5: =VLOOKUP($G5,$AF$13:$AI$64,AI$1,0) | AK5: =$A5 | AL5: =VLOOKUP($G5,$AK$13:$AN$64,AL$1,0) | AM5: =VLOOKUP($G5,$AK$13:$AN$64,AM$1,0) | AN5: =VLOOKUP($G5,$AF$13:$AI$64,AN$1,0) | AP5: =$A5 | AQ5: =VLOOKUP($G5,$AP$13:$AT$64,AQ$1,0) | AR5: =VLOOKUP($G5,$AP$13:$AT$64,AR$1,0) | AS5: =VLOOKUP($G5,$AF$13:$AI$64,AS$1,0) | AT5: =VLOOKUP($G5,$AP$13:$AT$64,AT$1,0) | AV5: =$A5 | AW5: =VLOOKUP($G5,$AV$13:$AY$64,AW$1,0) | AX5: =VLOOKUP($G5,$AV$13:$AY$64,AX$1,0) | AY5: =VLOOKUP($G5,$AF$13:$AI$64,AY$1,0) | BA5: =$A5 | BB5: =VLOOKUP($G5,$BA$13:$BD$64,BB$1,0) | BC5: =VLOOKUP($G5,$BA$13:$BD$64,BC$1,0) | BD5: =VLOOKUP($G5,$AF$13:$AI$64,BD$1,0) | BF5: =$A5 | BG5: =VLOOKUP($G5,$BF$13:$BI$64,BG$1,0) | BH5: =VLOOKUP($G5,$BF$13:$BI$64,BH$1,0) | BI5: =VLOOKUP($G5,$AF$13:$AI$64,BI$1,0) | BK5: =$A5 | BL5: =VLOOKUP($G5,$BK$13:$BN$64,BG$1,0) | BM5: =VLOOKUP($G5,$BK$13:$BN$64,BM$1,0) | BN5: =VLOOKUP($G5,$AF$13:$AI$64,BN$1,0) | BP5: =$A5 | BQ5: =VLOOKUP($G5,$BP$13:$BS$64,BQ$1,0) | BR5: =VLOOKUP($G5,$BP$13:$BS$64,BR$1,0) | BS5: =VLOOKUP($G5,$AF$13:$AI$64,BS$1,0)
A6: =A7-1 | B6: =$A6 | C6: =VLOOKUP($B6,$B$13:$E$64,C$1,0) | D6: =VLOOKUP($B6,$B$13:$E$64,D$1,0) | E6: =VLOOKUP($B6,$B$13:$E$64,E$1,0) | G6: =$A6 | H6: =VLOOKUP($G6,$G$13:$J$64,H$1,0) | I6: =VLOOKUP($G6,$G$13:$J$64,I$1,0) | J6: =VLOOKUP($G6,$G$13:$J$64,J$1,0) | L6: =$A6 | M6: =VLOOKUP($G6,$L$13:$O$64,M$1,0) | N6: =VLOOKUP($G6,$L$13:$O$64,N$1,0) | O6: =VLOOKUP($G6,$L$13:$O$64,O$1,0) | Q6: =$A6 | R6: =VLOOKUP($G6,$Q$12:$T$63,R$1,0) | S6: =VLOOKUP($G6,$Q$13:$T$64,S$1,0) | T6: =VLOOKUP($G6,$Q$13:$T$64,T$1,0) | V6: =$A6 | W6: =VLOOKUP($G6,$V$12:$Y$63,W$1,0) | X6: =VLOOKUP($G6,$V$13:$Y$64,X$1,0) | Y6: =VLOOKUP($G6,$V$13:$Y$64,Y$1,0) | AA6: =$A6 | AB6: =VLOOKUP($G6,$AA$13:$AD$64,AB$1,0) | AC6: =VLOOKUP($G6,$AA$13:$AD$64,AC$1,0) | AD6: =VLOOKUP($G6,$AA$13:$AD$64,AD$1,0) | AF6: =$A6 | AG6: =VLOOKUP($G6,$AF$13:$AI$64,AG$1,0) | AH6: =VLOOKUP($G6,$AF$13:$AI$64,AH$1,0) | AI6: =VLOOKUP($G6,$AF$13:$AI$64,AI$1,0) | AK6: =$A6 | AL6: =VLOOKUP($G6,$AK$13:$AN$64,AL$1,0) | AM6: =VLOOKUP($G6,$AK$13:$AN$64,AM$1,0) | AN6: =VLOOKUP($G6,$AF$13:$AI$64,AN$1,0) | AP6: =$A6 | AQ6: =VLOOKUP($G6,$AP$13:$AT$64,AQ$1,0) | AR6: =VLOOKUP($G6,$AP$13:$AT$64,AR$1,0) | AS6: =VLOOKUP($G6,$AF$13:$AI$64,AS$1,0) | AT6: =VLOOKUP($G6,$AP$13:$AT$64,AT$1,0) | AV6: =$A6 | AW6: =VLOOKUP($G6,$AV$13:$AY$64,AW$1,0) | AX6: =VLOOKUP($G6,$AV$13:$AY$64,AX$1,0) | AY6: =VLOOKUP($G6,$AF$13:$AI$64,AY$1,0) | BA6: =$A6 | BB6: =VLOOKUP($G6,$BA$13:$BD$64,BB$1,0) | BC6: =VLOOKUP($G6,$BA$13:$BD$64,BC$1,0) | BD6: =VLOOKUP($G6,$AF$13:$AI$64,BD$1,0) | BF6: =$A6 | BG6: =VLOOKUP($G6,$BF$13:$BI$64,BG$1,0) | BH6: =VLOOKUP($G6,$BF$13:$BI$64,BH$1,0) | BI6: =VLOOKUP($G6,$AF$13:$AI$64,BI$1,0) | BK6: =$A6 | BL6: =VLOOKUP($G6,$BK$13:$BN$64,BG$1,0) | BM6: =VLOOKUP($G6,$BK$13:$BN$64,BM$1,0) | BN6: =VLOOKUP($G6,$AF$13:$AI$64,BN$1,0) | BP6: =$A6 | BQ6: =VLOOKUP($G6,$BP$13:$BS$64,BQ$1,0) | BR6: =VLOOKUP($G6,$BP$13:$BS$64,BR$1,0) | BS6: =VLOOKUP($G6,$AF$13:$AI$64,BS$1,0)
A7: =A8-1 | B7: =$A7 | C7: =VLOOKUP($B7,$B$13:$E$64,C$1,0) | D7: =VLOOKUP($B7,$B$13:$E$64,D$1,0) | E7: =VLOOKUP($B7,$B$13:$E$64,E$1,0) | G7: =$A7 | H7: =VLOOKUP($G7,$G$13:$J$64,H$1,0) | I7: =VLOOKUP($G7,$G$13:$J$64,I$1,0) | J7: =VLOOKUP($G7,$G$13:$J$64,J$1,0) | L7: =$A7 | M7: =VLOOKUP($G7,$L$13:$O$64,M$1,0) | N7: =VLOOKUP($G7,$L$13:$O$64,N$1,0) | O7: =VLOOKUP($G7,$L$13:$O$64,O$1,0) | Q7: =$A7 | R7: =VLOOKUP($G7,$Q$12:$T$63,R$1,0) | S7: =VLOOKUP($G7,$Q$13:$T$64,S$1,0) | T7: =VLOOKUP($G7,$Q$13:$T$64,T$1,0) | V7: =$A7 | W7: =VLOOKUP($G7,$V$12:$Y$63,W$1,0) | X7: =VLOOKUP($G7,$V$13:$Y$64,X$1,0) | Y7: =VLOOKUP($G7,$V$13:$Y$64,Y$1,0) | AA7: =$A7 | AB7: =VLOOKUP($G7,$AA$13:$AD$64,AB$1,0) | AC7: =VLOOKUP($G7,$AA$13:$AD$64,AC$1,0) | AD7: =VLOOKUP($G7,$AA$13:$AD$64,AD$1,0) | AF7: =$A7 | AG7: =VLOOKUP($G7,$AF$13:$AI$64,AG$1,0) | AH7: =VLOOKUP($G7,$AF$13:$AI$64,AH$1,0) | AI7: =VLOOKUP($G7,$AF$13:$AI$64,AI$1,0) | AK7: =$A7 | AL7: =VLOOKUP($G7,$AK$13:$AN$64,AL$1,0) | AM7: =VLOOKUP($G7,$AK$13:$AN$64,AM$1,0) | AN7: =VLOOKUP($G7,$AF$13:$AI$64,AN$1,0) | AP7: =$A7 | AQ7: =VLOOKUP($G7,$AP$13:$AT$64,AQ$1,0) | AR7: =VLOOKUP($G7,$AP$13:$AT$64,AR$1,0) | AS7: =VLOOKUP($G7,$AF$13:$AI$64,AS$1,0) | AT7: =VLOOKUP($G7,$AP$13:$AT$64,AT$1,0) | AV7: =$A7 | AW7: =VLOOKUP($G7,$AV$13:$AY$64,AW$1,0) | AX7: =VLOOKUP($G7,$AV$13:$AY$64,AX$1,0) | AY7: =VLOOKUP($G7,$AF$13:$AI$64,AY$1,0) | BA7: =$A7 | BB7: =VLOOKUP($G7,$BA$13:$BD$64,BB$1,0) | BC7: =VLOOKUP($G7,$BA$13:$BD$64,BC$1,0) | BD7: =VLOOKUP($G7,$AF$13:$AI$64,BD$1,0) | BF7: =$A7 | BG7: =VLOOKUP($G7,$BF$13:$BI$64,BG$1,0) | BH7: =VLOOKUP($G7,$BF$13:$BI$64,BH$1,0) | BI7: =VLOOKUP($G7,$AF$13:$AI$64,BI$1,0) | BK7: =$A7 | BL7: =VLOOKUP($G7,$BK$13:$BN$64,BG$1,0) | BM7: =VLOOKUP($G7,$BK$13:$BN$64,BM$1,0) | BN7: =VLOOKUP($G7,$AF$13:$AI$64,BN$1,0) | BP7: =$A7 | BQ7: =VLOOKUP($G7,$BP$13:$BS$64,BQ$1,0) | BR7: =VLOOKUP($G7,$BP$13:$BS$64,BR$1,0) | BS7: =VLOOKUP($G7,$AF$13:$AI$64,BS$1,0)
A8: 8 | B8: =$A8 | C8: =VLOOKUP($B8,$B$13:$E$64,C$1,0) | D8: =VLOOKUP($B8,$B$13:$E$64,D$1,0) | E8: =VLOOKUP($B8,$B$13:$E$64,E$1,0) | G8: =$A8 | H8: =VLOOKUP($G8,$G$13:$J$64,H$1,0) | I8: =VLOOKUP($G8,$G$13:$J$64,I$1,0) | J8: =VLOOKUP($G8,$G$13:$J$64,J$1,0) | L8: =$A8 | M8: =VLOOKUP($G8,$L$13:$O$64,M$1,0) | N8: =VLOOKUP($G8,$L$13:$O$64,N$1,0) | O8: =VLOOKUP($G8,$L$13:$O$64,O$1,0) | Q8: =$A8 | R8: =VLOOKUP($G8,$Q$12:$T$63,R$1,0) | S8: =VLOOKUP($G8,$Q$13:$T$64,S$1,0) | T8: =VLOOKUP($G8,$Q$13:$T$64,T$1,0) | V8: =$A8 | W8: =VLOOKUP($G8,$V$12:$Y$63,W$1,0) | X8: =VLOOKUP($G8,$V$13:$Y$64,X$1,0) | Y8: =VLOOKUP($G8,$V$13:$Y$64,Y$1,0) | AA8: =$A8 | AB8: =VLOOKUP($G8,$AA$13:$AD$64,AB$1,0) | AC8: =VLOOKUP($G8,$AA$13:$AD$64,AC$1,0) | AD8: =VLOOKUP($G8,$AA$13:$AD$64,AD$1,0) | AF8: =$A8 | AG8: =VLOOKUP($G8,$AF$13:$AI$64,AG$1,0) | AH8: =VLOOKUP($G8,$AF$13:$AI$64,AH$1,0) | AI8: =VLOOKUP($G8,$AF$13:$AI$64,AI$1,0) | AK8: =$A8 | AL8: =VLOOKUP($G8,$AK$13:$AN$64,AL$1,0) | AM8: =VLOOKUP($G8,$AK$13:$AN$64,AM$1,0) | AN8: =VLOOKUP($G8,$AF$13:$AI$64,AN$1,0) | AP8: =$A8 | AQ8: =VLOOKUP($G8,$AP$13:$AT$64,AQ$1,0) | AR8: =VLOOKUP($G8,$AP$13:$AT$64,AR$1,0) | AS8: =VLOOKUP($G8,$AF$13:$AI$64,AS$1,0) | AT8: =VLOOKUP($G8,$AP$13:$AT$64,AT$1,0) | AV8: =$A8 | AW8: =VLOOKUP($G8,$AV$13:$AY$64,AW$1,0) | AX8: =VLOOKUP($G8,$AV$13:$AY$64,AX$1,0) | AY8: =VLOOKUP($G8,$AF$13:$AI$64,AY$1,0) | BA8: =$A8 | BB8: =VLOOKUP($G8,$BA$13:$BD$64,BB$1,0) | BC8: =VLOOKUP($G8,$BA$13:$BD$64,BC$1,0) | BD8: =VLOOKUP($G8,$AF$13:$AI$64,BD$1,0) | BF8: =$A8 | BG8: =VLOOKUP($G8,$BF$13:$BI$64,BG$1,0) | BH8: =VLOOKUP($G8,$BF$13:$BI$64,BH$1,0) | BI8: =VLOOKUP($G8,$AF$13:$AI$64,BI$1,0) | BK8: =$A8 | BL8: =VLOOKUP($G8,$BK$13:$BN$64,BG$1,0) | BM8: =VLOOKUP($G8,$BK$13:$BN$64,BM$1,0) | BN8: =VLOOKUP($G8,$AF$13:$AI$64,BN$1,0) | BP8: =$A8 | BQ8: =VLOOKUP($G8,$BP$13:$BS$64,BQ$1,0) | BR8: =VLOOKUP($G8,$BP$13:$BS$64,BR$1,0) | BS8: =VLOOKUP($G8,$AF$13:$AI$64,BS$1,0)
B11: JRM | G11: EMR | L11: CARTON | Q11: GM | V11: Q9 | AA11: FLUX DEV | AF11: PET B | AK11: PEPP | AP11: ELA | AV11: FILM | BA11: ACIER | BF11: ALU | BK11: PETIT ALU | BP11: REFUS
B12: Semaine | C12: Taux de pureté | D12: Contaminant A | E12: Objectif JRM | G12: Semaine | H12: Taux de pureté | I12: CC + REFUS | J12: Objectif EMR | L12: Semaine | M12: Taux de pureté | N12: CC + REFUS | O12: Objectif CARTON | Q12: Semaine | R12: Taux de pureté | S12: CC + REFUS | T12: Objectif GM | V12: Semaine | W12: Taux de pureté | X12: PET B | Y12: Objectif Q9 | AA12: Semaine | AB12: Taux de pureté | AC12: PET Q9 | AD12: Objectif FLUX DEV | AF12: Semaine | AG12: Taux de pureté | AH12: Contaminant | AI12: Objectif PET B | AK12: Semaine | AL12: Taux de pureté | AM12: FIBREUX + ELA | AN12: Objectif PEPP | AP12: Semaine | AQ12: Taux de pureté | AR12: FIBREUX | AS12: Objectif ELA | AT12: CC | AV12: Semaine | AW12: Taux de pureté | AX12: FIBREUX + CC | AY12: Objectif FILM | BA12: Semaine | BB12: Taux de pureté | BC12: Contaminant | BD12: Objectif ACIER | BF12: Semaine | BG12: Taux de pureté | BH12: Contaminant | BI12: Objectif ALU | BK12: Semaine | BL12: Taux de pureté | BM12: ALU | BN12: Objectif PEPP | BP12: Semaine | BQ12: Taux de pureté | BR12: FIBREUX + CC | BS12: Objectif REFUS
B13: 1 | C13: =IFERROR(AVERAGEIFS(SAISIE!Z:Z,SAISIE!Y:Y,BILAN!B13,SAISIE!B:B,"JRM"),"") | D13: =IFERROR(AVERAGEIFS(SAISIE!AP:AP,SAISIE!Y:Y,BILAN!B13,SAISIE!B:B,"JRM"),"") | E13: 0.97 | G13: 1 | H13: =IFERROR(AVERAGEIFS(SAISIE!AA:AA,SAISIE!Y:Y,BILAN!B13,SAISIE!B:B,"EMR"),"") | I13: =IFERROR(AVERAGEIFS(SAISIE!AS:AS,SAISIE!Y:Y,BILAN!B13,SAISIE!B:B,"EMR"),"") | J13: 0.95 | L13: 1 | M13: =IFERROR(AVERAGEIFS(SAISIE!AB:AB,SAISIE!Y:Y,BILAN!B13,SAISIE!B:B,"CARTON"),"") | N13: =IFERROR(AVERAGEIFS(SAISIE!AS:AS,SAISIE!Y:Y,BILAN!B13,SAISIE!B:B,"CARTON"),"") | O13: 0.95 | Q13: 1 | R13: =IFERROR(AVERAGEIFS(SAISIE!AC:AC,SAISIE!Y:Y,BILAN!B13,SAISIE!B:B,"GM"),"") | S13: =IFERROR(AVERAGEIFS(SAISIE!AS:AS,SAISIE!Y:Y,BILAN!B13,SAISIE!B:B,"GM"),"") | T13: 0.98 | V13: 1 | W13: =IFERROR(AVERAGEIFS(SAISIE!AD:AD,SAISIE!Y:Y,BILAN!B13,SAISIE!B:B,"PETQ9"),"") | X13: =IFERROR(AVERAGEIFS(SAISIE!AF:AF,SAISIE!Y:Y,BILAN!B13,SAISIE!B:B,"PETQ9"),"") | Y13: 0.98 | AA13: 1 | AB13: =IFERROR(AVERAGEIFS(SAISIE!AE:AE,SAISIE!Y:Y,BILAN!B13,SAISIE!B:B,"FLUX DEV"),"") | AC13: =IFERROR(AVERAGEIFS(SAISIE!AD:AD,SAISIE!Y:Y,BILAN!B13,SAISIE!B:B,"FLUX DEV"),"") | AD13: 0.98 | AF13: 1 | AG13: =IFERROR(AVERAGEIFS(SAISIE!AF:AF,SAISIE!Y:Y,BILAN!B13,SAISIE!B:B,"PETB"),"") | AI13: 0.95 | AK13: 1 | AL13: =IFERROR(AVERAGEIFS(SAISIE!AG:AG,SAISIE!Y:Y,BILAN!B13,SAISIE!B:B,"PEPP"),"") | AM13: =IFERROR(AVERAGEIFS(SAISIE!AT:AT,SAISIE!Y:Y,BILAN!B13,SAISIE!B:B,"PEPP"),"") | AN13: 0.95 | AP13: 1 | AQ13: =IFERROR(AVERAGEIFS(SAISIE!AH:AH,SAISIE!Y:Y,BILAN!B13,SAISIE!B:B,"ELA"),"") | AR13: =IFERROR(AVERAGEIFS(SAISIE!AN:AN,SAISIE!Y:Y,BILAN!B13,SAISIE!B:B,"ELA"),"") | AS13: 0.95 | AT13: =IFERROR(AVERAGEIFS(SAISIE!AW:AW,SAISIE!Y:Y,BILAN!B13,SAISIE!B:B,"ELA"),"") | AV13: 1 | AW13: =IFERROR(AVERAGEIFS(SAISIE!AI:AI,SAISIE!Y:Y,BILAN!B13,SAISIE!B:B,"FILM"),"") | AX13: =IFERROR(AVERAGEIFS(SAISIE!AV:AV,SAISIE!Y:Y,BILAN!B13,SAISIE!B:B,"FILM"),"") | AY13: 0.95 | BA13: 1 | BB13: =IFERROR(AVERAGEIFS(SAISIE!AJ:AJ,SAISIE!Y:Y,BILAN!B13,SAISIE!B:B,"ACIER"),"") | BD13: 0.95 | BF13: 1 | BG13: =IFERROR(AVERAGEIFS(SAISIE!AK:AK,SAISIE!Y:Y,BILAN!B13,SAISIE!B:B,"ALU"),"") | BI13: 0.95 | BK13: 1 | BL13: =IFERROR(AVERAGEIFS(SAISIE!AL:AL,SAISIE!Y:Y,BILAN!B13,SAISIE!B:B,"PETIT ALU"),"") | BM13: =IFERROR(AVERAGEIFS(SAISIE!AK:AK,SAISIE!Y:Y,BILAN!B13,SAISIE!B:B,"PETIT ALU"),"") | BN13: 0.95 | BP13: 1 | BQ13: =IFERROR(AVERAGEIFS(SAISIE!AM:AM,SAISIE!Y:Y,BILAN!B13,SAISIE!B:B,"REFUS"),"") | BR13: =IFERROR(AVERAGEIFS(SAISIE!AU:AU,SAISIE!Y:Y,BILAN!B13,SAISIE!B:B,"REFUS"),"") | BS13: 0.95
B14: 2 | C14: =IFERROR(AVERAGEIFS(SAISIE!Z:Z,SAISIE!Y:Y,BILAN!B14,SAISIE!B:B,"JRM"),"") | D14: =IFERROR(AVERAGEIFS(SAISIE!AP:AP,SAISIE!Y:Y,BILAN!B14,SAISIE!B:B,"JRM"),"") | E14: 0.97 | G14: 2 | H14: =IFERROR(AVERAGEIFS(SAISIE!AA:AA,SAISIE!Y:Y,BILAN!B14,SAISIE!B:B,"EMR"),"") | I14: =IFERROR(AVERAGEIFS(SAISIE!AS:AS,SAISIE!Y:Y,BILAN!B14,SAISIE!B:B,"EMR"),"") | J14: 0.95 | L14: 2 | M14: =IFERROR(AVERAGEIFS(SAISIE!AB:AB,SAISIE!Y:Y,BILAN!B14,SAISIE!B:B,"CARTON"),"") | N14: =IFERROR(AVERAGEIFS(SAISIE!AS:AS,SAISIE!Y:Y,BILAN!B14,SAISIE!B:B,"CARTON"),"") | O14: 0.95 | Q14: 2 | R14: =IFERROR(AVERAGEIFS(SAISIE!AC:AC,SAISIE!Y:Y,BILAN!B14,SAISIE!B:B,"GM"),"") | S14: =IFERROR(AVERAGEIFS(SAISIE!AS:AS,SAISIE!Y:Y,BILAN!B14,SAISIE!B:B,"GM"),"") | T14: 0.98 | V14: 2 | W14: =IFERROR(AVERAGEIFS(SAISIE!AD:AD,SAISIE!Y:Y,BILAN!B14,SAISIE!B:B,"PETQ9"),"") | X14: =IFERROR(AVERAGEIFS(SAISIE!AF:AF,SAISIE!Y:Y,BILAN!B14,SAISIE!B:B,"PETQ9"),"") | Y14: 0.98 | AA14: 2 | AB14: =IFERROR(AVERAGEIFS(SAISIE!AE:AE,SAISIE!Y:Y,BILAN!B14,SAISIE!B:B,"FLUX DEV"),"") | AC14: =IFERROR(AVERAGEIFS(SAISIE!AD:AD,SAISIE!Y:Y,BILAN!B14,SAISIE!B:B,"FLUX DEV"),"") | AD14: 0.98 | AF14: 2 | AG14: =IFERROR(AVERAGEIFS(SAISIE!AF:AF,SAISIE!Y:Y,BILAN!B14,SAISIE!B:B,"PETB"),"") | AI14: 0.95 | AK14: 2 | AL14: =IFERROR(AVERAGEIFS(SAISIE!AG:AG,SAISIE!Y:Y,BILAN!B14,SAISIE!B:B,"PEPP"),"") | AM14: =IFERROR(AVERAGEIFS(SAISIE!AT:AT,SAISIE!Y:Y,BILAN!B14,SAISIE!B:B,"PEPP"),"") | AN14: 0.95 | AP14: 2 | AQ14: =IFERROR(AVERAGEIFS(SAISIE!AH:AH,SAISIE!Y:Y,BILAN!B14,SAISIE!B:B,"ELA"),"") | AR14: =IFERROR(AVERAGEIFS(SAISIE!AN:AN,SAISIE!Y:Y,BILAN!B14,SAISIE!B:B,"ELA"),"") | AS14: 0.95 | AT14: =IFERROR(AVERAGEIFS(SAISIE!AW:AW,SAISIE!Y:Y,BILAN!B14,SAISIE!B:B,"ELA"),"") | AV14: 2 | AW14: =IFERROR(AVERAGEIFS(SAISIE!AI:AI,SAISIE!Y:Y,BILAN!B14,SAISIE!B:B,"FILM"),"") | AX14: =IFERROR(AVERAGEIFS(SAISIE!AV:AV,SAISIE!Y:Y,BILAN!B14,SAISIE!B:B,"FILM"),"") | AY14: 0.95 | BA14: 2 | BB14: =IFERROR(AVERAGEIFS(SAISIE!AJ:AJ,SAISIE!Y:Y,BILAN!B14,SAISIE!B:B,"ACIER"),"") | BD14: 0.95 | BF14: 2 | BG14: =IFERROR(AVERAGEIFS(SAISIE!AK:AK,SAISIE!Y:Y,BILAN!B14,SAISIE!B:B,"ALU"),"") | BI14: 0.95 | BK14: 2 | BL14: =IFERROR(AVERAGEIFS(SAISIE!AL:AL,SAISIE!Y:Y,BILAN!B14,SAISIE!B:B,"PETIT ALU"),"") | BM14: =IFERROR(AVERAGEIFS(SAISIE!AK:AK,SAISIE!Y:Y,BILAN!B14,SAISIE!B:B,"PETIT ALU"),"") | BN14: 0.95 | BP14: 2 | BQ14: =IFERROR(AVERAGEIFS(SAISIE!AM:AM,SAISIE!Y:Y,BILAN!B14,SAISIE!B:B,"REFUS"),"") | BR14: =IFERROR(AVERAGEIFS(SAISIE!AU:AU,SAISIE!Y:Y,BILAN!B14,SAISIE!B:B,"REFUS"),"") | BS14: 0.95
B15: 3 | C15: =IFERROR(AVERAGEIFS(SAISIE!Z:Z,SAISIE!Y:Y,BILAN!B15,SAISIE!B:B,"JRM"),"") | D15: =IFERROR(AVERAGEIFS(SAISIE!AP:AP,SAISIE!Y:Y,BILAN!B15,SAISIE!B:B,"JRM"),"") | E15: 0.97 | G15: 3 | H15: =IFERROR(AVERAGEIFS(SAISIE!AA:AA,SAISIE!Y:Y,BILAN!B15,SAISIE!B:B,"EMR"),"") | I15: =IFERROR(AVERAGEIFS(SAISIE!AS:AS,SAISIE!Y:Y,BILAN!B15,SAISIE!B:B,"EMR"),"") | J15: 0.95 | L15: 3 | M15: =IFERROR(AVERAGEIFS(SAISIE!AB:AB,SAISIE!Y:Y,BILAN!B15,SAISIE!B:B,"CARTON"),"") | N15: =IFERROR(AVERAGEIFS(SAISIE!AS:AS,SAISIE!Y:Y,BILAN!B15,SAISIE!B:B,"CARTON"),"") | O15: 0.95 | Q15: 3 | R15: =IFERROR(AVERAGEIFS(SAISIE!AC:AC,SAISIE!Y:Y,BILAN!B15,SAISIE!B:B,"GM"),"") | S15: =IFERROR(AVERAGEIFS(SAISIE!AS:AS,SAISIE!Y:Y,BILAN!B15,SAISIE!B:B,"GM"),"") | T15: 0.98 | V15: 3 | W15: =IFERROR(AVERAGEIFS(SAISIE!AD:AD,SAISIE!Y:Y,BILAN!B15,SAISIE!B:B,"PETQ9"),"") | X15: =IFERROR(AVERAGEIFS(SAISIE!AF:AF,SAISIE!Y:Y,BILAN!B15,SAISIE!B:B,"PETQ9"),"") | Y15: 0.98 | AA15: 3 | AB15: =IFERROR(AVERAGEIFS(SAISIE!AE:AE,SAISIE!Y:Y,BILAN!B15,SAISIE!B:B,"FLUX DEV"),"") | AC15: =IFERROR(AVERAGEIFS(SAISIE!AD:AD,SAISIE!Y:Y,BILAN!B15,SAISIE!B:B,"FLUX DEV"),"") | AD15: 0.98 | AF15: 3 | AG15: =IFERROR(AVERAGEIFS(SAISIE!AF:AF,SAISIE!Y:Y,BILAN!B15,SAISIE!B:B,"PETB"),"") | AI15: 0.95 | AK15: 3 | AL15: =IFERROR(AVERAGEIFS(SAISIE!AG:AG,SAISIE!Y:Y,BILAN!B15,SAISIE!B:B,"PEPP"),"") | AM15: =IFERROR(AVERAGEIFS(SAISIE!AT:AT,SAISIE!Y:Y,BILAN!B15,SAISIE!B:B,"PEPP"),"") | AN15: 0.95 | AP15: 3 | AQ15: =IFERROR(AVERAGEIFS(SAISIE!AH:AH,SAISIE!Y:Y,BILAN!B15,SAISIE!B:B,"ELA"),"") | AR15: =IFERROR(AVERAGEIFS(SAISIE!AN:AN,SAISIE!Y:Y,BILAN!B15,SAISIE!B:B,"ELA"),"") | AS15: 0.95 | AT15: =IFERROR(AVERAGEIFS(SAISIE!AW:AW,SAISIE!Y:Y,BILAN!B15,SAISIE!B:B,"ELA"),"") | AV15: 3 | AW15: =IFERROR(AVERAGEIFS(SAISIE!AI:AI,SAISIE!Y:Y,BILAN!B15,SAISIE!B:B,"FILM"),"") | AX15: =IFERROR(AVERAGEIFS(SAISIE!AV:AV,SAISIE!Y:Y,BILAN!B15,SAISIE!B:B,"FILM"),"") | AY15: 0.95 | BA15: 3 | BB15: =IFERROR(AVERAGEIFS(SAISIE!AJ:AJ,SAISIE!Y:Y,BILAN!B15,SAISIE!B:B,"ACIER"),"") | BD15: 0.95 | BF15: 3 | BG15: =IFERROR(AVERAGEIFS(SAISIE!AK:AK,SAISIE!Y:Y,BILAN!B15,SAISIE!B:B,"ALU"),"") | BI15: 0.95 | BK15: 3 | BL15: =IFERROR(AVERAGEIFS(SAISIE!AL:AL,SAISIE!Y:Y,BILAN!B15,SAISIE!B:B,"PETIT ALU"),"") | BM15: =IFERROR(AVERAGEIFS(SAISIE!AK:AK,SAISIE!Y:Y,BILAN!B15,SAISIE!B:B,"PETIT ALU"),"") | BN15: 0.95 | BP15: 3 | BQ15: =IFERROR(AVERAGEIFS(SAISIE!AM:AM,SAISIE!Y:Y,BILAN!B15,SAISIE!B:B,"REFUS"),"") | BR15: =IFERROR(AVERAGEIFS(SAISIE!AU:AU,SAISIE!Y:Y,BILAN!B15,SAISIE!B:B,"REFUS"),"") | BS15: 0.95
B16: 4 | C16: =IFERROR(AVERAGEIFS(SAISIE!Z:Z,SAISIE!Y:Y,BILAN!B16,SAISIE!B:B,"JRM"),"") | D16: =IFERROR(AVERAGEIFS(SAISIE!AP:AP,SAISIE!Y:Y,BILAN!B16,SAISIE!B:B,"JRM"),"") | E16: 0.97 | G16: 4 | H16: =IFERROR(AVERAGEIFS(SAISIE!AA:AA,SAISIE!Y:Y,BILAN!B16,SAISIE!B:B,"EMR"),"") | I16: =IFERROR(AVERAGEIFS(SAISIE!AS:AS,SAISIE!Y:Y,BILAN!B16,SAISIE!B:B,"EMR"),"") | J16: 0.95 | L16: 4 | M16: =IFERROR(AVERAGEIFS(SAISIE!AB:AB,SAISIE!Y:Y,BILAN!B16,SAISIE!B:B,"CARTON"),"") | N16: =IFERROR(AVERAGEIFS(SAISIE!AS:AS,SAISIE!Y:Y,BILAN!B16,SAISIE!B:B,"CARTON"),"") | O16: 0.95 | Q16: 4 | R16: =IFERROR(AVERAGEIFS(SAISIE!AC:AC,SAISIE!Y:Y,BILAN!B16,SAISIE!B:B,"GM"),"") | S16: =IFERROR(AVERAGEIFS(SAISIE!AS:AS,SAISIE!Y:Y,BILAN!B16,SAISIE!B:B,"GM"),"") | T16: 0.98 | V16: 4 | W16: =IFERROR(AVERAGEIFS(SAISIE!AD:AD,SAISIE!Y:Y,BILAN!B16,SAISIE!B:B,"PETQ9"),"") | X16: =IFERROR(AVERAGEIFS(SAISIE!AF:AF,SAISIE!Y:Y,BILAN!B16,SAISIE!B:B,"PETQ9"),"") | Y16: 0.98 | AA16: 4 | AB16: =IFERROR(AVERAGEIFS(SAISIE!AE:AE,SAISIE!Y:Y,BILAN!B16,SAISIE!B:B,"FLUX DEV"),"") | AC16: =IFERROR(AVERAGEIFS(SAISIE!AD:AD,SAISIE!Y:Y,BILAN!B16,SAISIE!B:B,"FLUX DEV"),"") | AD16: 0.98 | AF16: 4 | AG16: =IFERROR(AVERAGEIFS(SAISIE!AF:AF,SAISIE!Y:Y,BILAN!B16,SAISIE!B:B,"PETB"),"") | AI16: 0.95 | AK16: 4 | AL16: =IFERROR(AVERAGEIFS(SAISIE!AG:AG,SAISIE!Y:Y,BILAN!B16,SAISIE!B:B,"PEPP"),"") | AM16: =IFERROR(AVERAGEIFS(SAISIE!AT:AT,SAISIE!Y:Y,BILAN!B16,SAISIE!B:B,"PEPP"),"") | AN16: 0.95 | AP16: 4 | AQ16: =IFERROR(AVERAGEIFS(SAISIE!AH:AH,SAISIE!Y:Y,BILAN!B16,SAISIE!B:B,"ELA"),"") | AR16: =IFERROR(AVERAGEIFS(SAISIE!AN:AN,SAISIE!Y:Y,BILAN!B16,SAISIE!B:B,"ELA"),"") | AS16: 0.95 | AT16: =IFERROR(AVERAGEIFS(SAISIE!AW:AW,SAISIE!Y:Y,BILAN!B16,SAISIE!B:B,"ELA"),"") | AV16: 4 | AW16: =IFERROR(AVERAGEIFS(SAISIE!AI:AI,SAISIE!Y:Y,BILAN!B16,SAISIE!B:B,"FILM"),"") | AX16: =IFERROR(AVERAGEIFS(SAISIE!AV:AV,SAISIE!Y:Y,BILAN!B16,SAISIE!B:B,"FILM"),"") | AY16: 0.95 | BA16: 4 | BB16: =IFERROR(AVERAGEIFS(SAISIE!AJ:AJ,SAISIE!Y:Y,BILAN!B16,SAISIE!B:B,"ACIER"),"") | BD16: 0.95 | BF16: 4 | BG16: =IFERROR(AVERAGEIFS(SAISIE!AK:AK,SAISIE!Y:Y,BILAN!B16,SAISIE!B:B,"ALU"),"") | BI16: 0.95 | BK16: 4 | BL16: =IFERROR(AVERAGEIFS(SAISIE!AL:AL,SAISIE!Y:Y,BILAN!B16,SAISIE!B:B,"PETIT ALU"),"") | BM16: =IFERROR(AVERAGEIFS(SAISIE!AK:AK,SAISIE!Y:Y,BILAN!B16,SAISIE!B:B,"PETIT ALU"),"") | BN16: 0.95 | BP16: 4 | BQ16: =IFERROR(AVERAGEIFS(SAISIE!AM:AM,SAISIE!Y:Y,BILAN!B16,SAISIE!B:B,"REFUS"),"") | BR16: =IFERROR(AVERAGEIFS(SAISIE!AU:AU,SAISIE!Y:Y,BILAN!B16,SAISIE!B:B,"REFUS"),"") | BS16: 0.95
B17: 5 | C17: =IFERROR(AVERAGEIFS(SAISIE!Z:Z,SAISIE!Y:Y,BILAN!B17,SAISIE!B:B,"JRM"),"") | D17: =IFERROR(AVERAGEIFS(SAISIE!AP:AP,SAISIE!Y:Y,BILAN!B17,SAISIE!B:B,"JRM"),"") | E17: 0.97 | G17: 5 | H17: =IFERROR(AVERAGEIFS(SAISIE!AA:AA,SAISIE!Y:Y,BILAN!B17,SAISIE!B:B,"EMR"),"") | I17: =IFERROR(AVERAGEIFS(SAISIE!AS:AS,SAISIE!Y:Y,BILAN!B17,SAISIE!B:B,"EMR"),"") | J17: 0.95 | L17: 5 | M17: =IFERROR(AVERAGEIFS(SAISIE!AB:AB,SAISIE!Y:Y,BILAN!B17,SAISIE!B:B,"CARTON"),"") | N17: =IFERROR(AVERAGEIFS(SAISIE!AS:AS,SAISIE!Y:Y,BILAN!B17,SAISIE!B:B,"CARTON"),"") | O17: 0.95 | Q17: 5 | R17: =IFERROR(AVERAGEIFS(SAISIE!AC:AC,SAISIE!Y:Y,BILAN!B17,SAISIE!B:B,"GM"),"") | S17: =IFERROR(AVERAGEIFS(SAISIE!AS:AS,SAISIE!Y:Y,BILAN!B17,SAISIE!B:B,"GM"),"") | T17: 0.98 | V17: 5 | W17: =IFERROR(AVERAGEIFS(SAISIE!AD:AD,SAISIE!Y:Y,BILAN!B17,SAISIE!B:B,"PETQ9"),"") | X17: =IFERROR(AVERAGEIFS(SAISIE!AF:AF,SAISIE!Y:Y,BILAN!B17,SAISIE!B:B,"PETQ9"),"") | Y17: 0.98 | AA17: 5 | AB17: =IFERROR(AVERAGEIFS(SAISIE!AE:AE,SAISIE!Y:Y,BILAN!B17,SAISIE!B:B,"FLUX DEV"),"") | AC17: =IFERROR(AVERAGEIFS(SAISIE!AD:AD,SAISIE!Y:Y,BILAN!B17,SAISIE!B:B,"FLUX DEV"),"") | AD17: 0.98 | AF17: 5 | AG17: =IFERROR(AVERAGEIFS(SAISIE!AF:AF,SAISIE!Y:Y,BILAN!B17,SAISIE!B:B,"PETB"),"") | AI17: 0.95 | AK17: 5 | AL17: =IFERROR(AVERAGEIFS(SAISIE!AG:AG,SAISIE!Y:Y,BILAN!B17,SAISIE!B:B,"PEPP"),"") | AM17: =IFERROR(AVERAGEIFS(SAISIE!AT:AT,SAISIE!Y:Y,BILAN!B17,SAISIE!B:B,"PEPP"),"") | AN17: 0.95 | AP17: 5 | AQ17: =IFERROR(AVERAGEIFS(SAISIE!AH:AH,SAISIE!Y:Y,BILAN!B17,SAISIE!B:B,"ELA"),"") | AR17: =IFERROR(AVERAGEIFS(SAISIE!AN:AN,SAISIE!Y:Y,BILAN!B17,SAISIE!B:B,"ELA"),"") | AS17: 0.95 | AT17: =IFERROR(AVERAGEIFS(SAISIE!AW:AW,SAISIE!Y:Y,BILAN!B17,SAISIE!B:B,"ELA"),"") | AV17: 5 | AW17: =IFERROR(AVERAGEIFS(SAISIE!AI:AI,SAISIE!Y:Y,BILAN!B17,SAISIE!B:B,"FILM"),"") | AX17: =IFERROR(AVERAGEIFS(SAISIE!AV:AV,SAISIE!Y:Y,BILAN!B17,SAISIE!B:B,"FILM"),"") | AY17: 0.95 | BA17: 5 | BB17: =IFERROR(AVERAGEIFS(SAISIE!AJ:AJ,SAISIE!Y:Y,BILAN!B17,SAISIE!B:B,"ACIER"),"") | BD17: 0.95 | BF17: 5 | BG17: =IFERROR(AVERAGEIFS(SAISIE!AK:AK,SAISIE!Y:Y,BILAN!B17,SAISIE!B:B,"ALU"),"") | BI17: 0.95 | BK17: 5 | BL17: =IFERROR(AVERAGEIFS(SAISIE!AL:AL,SAISIE!Y:Y,BILAN!B17,SAISIE!B:B,"PETIT ALU"),"") | BM17: =IFERROR(AVERAGEIFS(SAISIE!AK:AK,SAISIE!Y:Y,BILAN!B17,SAISIE!B:B,"PETIT ALU"),"") | BN17: 0.95 | BP17: 5 | BQ17: =IFERROR(AVERAGEIFS(SAISIE!AM:AM,SAISIE!Y:Y,BILAN!B17,SAISIE!B:B,"REFUS"),"") | BR17: =IFERROR(AVERAGEIFS(SAISIE!AU:AU,SAISIE!Y:Y,BILAN!B17,SAISIE!B:B,"REFUS"),"") | BS17: 0.95
B18: 6 | C18: =IFERROR(AVERAGEIFS(SAISIE!Z:Z,SAISIE!Y:Y,BILAN!B18,SAISIE!B:B,"JRM"),"") | D18: =IFERROR(AVERAGEIFS(SAISIE!AP:AP,SAISIE!Y:Y,BILAN!B18,SAISIE!B:B,"JRM"),"") | E18: 0.97 | G18: 6 | H18: =IFERROR(AVERAGEIFS(SAISIE!AA:AA,SAISIE!Y:Y,BILAN!B18,SAISIE!B:B,"EMR"),"") | I18: =IFERROR(AVERAGEIFS(SAISIE!AS:AS,SAISIE!Y:Y,BILAN!B18,SAISIE!B:B,"EMR"),"") | J18: 0.95 | L18: 6 | M18: =IFERROR(AVERAGEIFS(SAISIE!AB:AB,SAISIE!Y:Y,BILAN!B18,SAISIE!B:B,"CARTON"),"") | N18: =IFERROR(AVERAGEIFS(SAISIE!AS:AS,SAISIE!Y:Y,BILAN!B18,SAISIE!B:B,"CARTON"),"") | O18: 0.95 | Q18: 6 | R18: =IFERROR(AVERAGEIFS(SAISIE!AC:AC,SAISIE!Y:Y,BILAN!B18,SAISIE!B:B,"GM"),"") | S18: =IFERROR(AVERAGEIFS(SAISIE!AS:AS,SAISIE!Y:Y,BILAN!B18,SAISIE!B:B,"GM"),"") | T18: 0.98 | V18: 6 | W18: =IFERROR(AVERAGEIFS(SAISIE!AD:AD,SAISIE!Y:Y,BILAN!B18,SAISIE!B:B,"PETQ9"),"") | X18: =IFERROR(AVERAGEIFS(SAISIE!AF:AF,SAISIE!Y:Y,BILAN!B18,SAISIE!B:B,"PETQ9"),"") | Y18: 0.98 | AA18: 6 | AB18: =IFERROR(AVERAGEIFS(SAISIE!AE:AE,SAISIE!Y:Y,BILAN!B18,SAISIE!B:B,"FLUX DEV"),"") | AC18: =IFERROR(AVERAGEIFS(SAISIE!AD:AD,SAISIE!Y:Y,BILAN!B18,SAISIE!B:B,"FLUX DEV"),"") | AD18: 0.98 | AF18: 6 | AG18: =IFERROR(AVERAGEIFS(SAISIE!AF:AF,SAISIE!Y:Y,BILAN!B18,SAISIE!B:B,"PETB"),"") | AI18: 0.95 | AK18: 6 | AL18: =IFERROR(AVERAGEIFS(SAISIE!AG:AG,SAISIE!Y:Y,BILAN!B18,SAISIE!B:B,"PEPP"),"") | AM18: =IFERROR(AVERAGEIFS(SAISIE!AT:AT,SAISIE!Y:Y,BILAN!B18,SAISIE!B:B,"PEPP"),"") | AN18: 0.95 | AP18: 6 | AQ18: =IFERROR(AVERAGEIFS(SAISIE!AH:AH,SAISIE!Y:Y,BILAN!B18,SAISIE!B:B,"ELA"),"") | AR18: =IFERROR(AVERAGEIFS(SAISIE!AN:AN,SAISIE!Y:Y,BILAN!B18,SAISIE!B:B,"ELA"),"") | AS18: 0.95 | AT18: =IFERROR(AVERAGEIFS(SAISIE!AW:AW,SAISIE!Y:Y,BILAN!B18,SAISIE!B:B,"ELA"),"") | AV18: 6 | AW18: =IFERROR(AVERAGEIFS(SAISIE!AI:AI,SAISIE!Y:Y,BILAN!B18,SAISIE!B:B,"FILM"),"") | AX18: =IFERROR(AVERAGEIFS(SAISIE!AV:AV,SAISIE!Y:Y,BILAN!B18,SAISIE!B:B,"FILM"),"") | AY18: 0.95 | BA18: 6 | BB18: =IFERROR(AVERAGEIFS(SAISIE!AJ:AJ,SAISIE!Y:Y,BILAN!B18,SAISIE!B:B,"ACIER"),"") | BD18: 0.95 | BF18: 6 | BG18: =IFERROR(AVERAGEIFS(SAISIE!AK:AK,SAISIE!Y:Y,BILAN!B18,SAISIE!B:B,"ALU"),"") | BI18: 0.95 | BK18: 6 | BL18: =IFERROR(AVERAGEIFS(SAISIE!AL:AL,SAISIE!Y:Y,BILAN!B18,SAISIE!B:B,"PETIT ALU"),"") | BM18: =IFERROR(AVERAGEIFS(SAISIE!AK:AK,SAISIE!Y:Y,BILAN!B18,SAISIE!B:B,"PETIT ALU"),"") | BN18: 0.95 | BP18: 6 | BQ18: =IFERROR(AVERAGEIFS(SAISIE!AM:AM,SAISIE!Y:Y,BILAN!B18,SAISIE!B:B,"REFUS"),"") | BR18: =IFERROR(AVERAGEIFS(SAISIE!AU:AU,SAISIE!Y:Y,BILAN!B18,SAISIE!B:B,"REFUS"),"") | BS18: 0.95
B19: 7 | C19: =IFERROR(AVERAGEIFS(SAISIE!Z:Z,SAISIE!Y:Y,BILAN!B19,SAISIE!B:B,"JRM"),"") | D19: =IFERROR(AVERAGEIFS(SAISIE!AP:AP,SAISIE!Y:Y,BILAN!B19,SAISIE!B:B,"JRM"),"") | E19: 0.97 | G19: 7 | H19: =IFERROR(AVERAGEIFS(SAISIE!AA:AA,SAISIE!Y:Y,BILAN!B19,SAISIE!B:B,"EMR"),"") | I19: =IFERROR(AVERAGEIFS(SAISIE!AS:AS,SAISIE!Y:Y,BILAN!B19,SAISIE!B:B,"EMR"),"") | J19: 0.95 | L19: 7 | M19: =IFERROR(AVERAGEIFS(SAISIE!AB:AB,SAISIE!Y:Y,BILAN!B19,SAISIE!B:B,"CARTON"),"") | N19: =IFERROR(AVERAGEIFS(SAISIE!AS:AS,SAISIE!Y:Y,BILAN!B19,SAISIE!B:B,"CARTON"),"") | O19: 0.95 | Q19: 7 | R19: =IFERROR(AVERAGEIFS(SAISIE!AC:AC,SAISIE!Y:Y,BILAN!B19,SAISIE!B:B,"GM"),"") | S19: =IFERROR(AVERAGEIFS(SAISIE!AS:AS,SAISIE!Y:Y,BILAN!B19,SAISIE!B:B,"GM"),"") | T19: 0.98 | V19: 7 | W19: =IFERROR(AVERAGEIFS(SAISIE!AD:AD,SAISIE!Y:Y,BILAN!B19,SAISIE!B:B,"PETQ9"),"") | X19: =IFERROR(AVERAGEIFS(SAISIE!AF:AF,SAISIE!Y:Y,BILAN!B19,SAISIE!B:B,"PETQ9"),"") | Y19: 0.98 | AA19: 7 | AB19: =IFERROR(AVERAGEIFS(SAISIE!AE:AE,SAISIE!Y:Y,BILAN!B19,SAISIE!B:B,"FLUX DEV"),"") | AC19: =IFERROR(AVERAGEIFS(SAISIE!AD:AD,SAISIE!Y:Y,BILAN!B19,SAISIE!B:B,"FLUX DEV"),"") | AD19: 0.98 | AF19: 7 | AG19: =IFERROR(AVERAGEIFS(SAISIE!AF:AF,SAISIE!Y:Y,BILAN!B19,SAISIE!B:B,"PETB"),"") | AI19: 0.95 | AK19: 7 | AL19: =IFERROR(AVERAGEIFS(SAISIE!AG:AG,SAISIE!Y:Y,BILAN!B19,SAISIE!B:B,"PEPP"),"") | AM19: =IFERROR(AVERAGEIFS(SAISIE!AT:AT,SAISIE!Y:Y,BILAN!B19,SAISIE!B:B,"PEPP"),"") | AN19: 0.95 | AP19: 7 | AQ19: =IFERROR(AVERAGEIFS(SAISIE!AH:AH,SAISIE!Y:Y,BILAN!B19,SAISIE!B:B,"ELA"),"") | AR19: =IFERROR(AVERAGEIFS(SAISIE!AN:AN,SAISIE!Y:Y,BILAN!B19,SAISIE!B:B,"ELA"),"") | AS19: 0.95 | AT19: =IFERROR(AVERAGEIFS(SAISIE!AW:AW,SAISIE!Y:Y,BILAN!B19,SAISIE!B:B,"ELA"),"") | AV19: 7 | AW19: =IFERROR(AVERAGEIFS(SAISIE!AI:AI,SAISIE!Y:Y,BILAN!B19,SAISIE!B:B,"FILM"),"") | AX19: =IFERROR(AVERAGEIFS(SAISIE!AV:AV,SAISIE!Y:Y,BILAN!B19,SAISIE!B:B,"FILM"),"") | AY19: 0.95 | BA19: 7 | BB19: =IFERROR(AVERAGEIFS(SAISIE!AJ:AJ,SAISIE!Y:Y,BILAN!B19,SAISIE!B:B,"ACIER"),"") | BD19: 0.95 | BF19: 7 | BG19: =IFERROR(AVERAGEIFS(SAISIE!AK:AK,SAISIE!Y:Y,BILAN!B19,SAISIE!B:B,"ALU"),"") | BI19: 0.95 | BK19: 7 | BL19: =IFERROR(AVERAGEIFS(SAISIE!AL:AL,SAISIE!Y:Y,BILAN!B19,SAISIE!B:B,"PETIT ALU"),"") | BM19: =IFERROR(AVERAGEIFS(SAISIE!AK:AK,SAISIE!Y:Y,BILAN!B19,SAISIE!B:B,"PETIT ALU"),"") | BN19: 0.95 | BP19: 7 | BQ19: =IFERROR(AVERAGEIFS(SAISIE!AM:AM,SAISIE!Y:Y,BILAN!B19,SAISIE!B:B,"REFUS"),"") | BR19: =IFERROR(AVERAGEIFS(SAISIE!AU:AU,SAISIE!Y:Y,BILAN!B19,SAISIE!B:B,"REFUS"),"") | BS19: 0.95
