Workbook

Sheet SAISIE
A1: 1 | B1: Provenance | C1: Date | D1: CARTON | E1: CARTONNETTE | F1: ECRIT COULEUR | G1: JRM | H1: GM | I1: ELA | J1: PEPP | K1: PET Q9 | L1: PET Q5 | M1: PET B | N1: FILM | O1: ACIER | P1: ALU | Q1: PETIT ALU | R1: PB REFUSES | S1: FILM REFUSES | T1: EMBALLAGES NOIRS | U1: AUTES EMBALLAGES NON RECYCLABES | V1: BOIS | W1: VERRE | X1: DDS | Y1: D3E | Z1: IMBRIQUES | AA1: PLASTIQUES NON EMBALLAGES | AB1: FERRAILLES | AC1: GRAVATS | AD1: TEXTILE | AE1: EMBALLAGES NON VIDES / SOUILL2S | AF1: REFUS | AG1: PAPIER MOUILLE | AH1: FINES | AI1: Total (kg) | AJ1: Taux de valorisable | AK1: Taux de fibreux | AL1: Taux de refus | AM1: Commentaire | AN1: Année | AO1: Mois | AP1: Semaine | AQ1: CARTON | AR1: CARTONNETTE | AS1: ECRIT COULEUR | AT1: JRM | AU1: GM | AV1: ELA | AW1: PEPP | AX1: PET Q9 | AY1: PET Q5 | AZ1: PET B | BA1: FILM | BB1: ACIER | BC1: ALU | BD1: PETIT ALU | BE1: PB REFUSES | BF1: FILM REFUSES | BG1: EMBALLAGES NOIRS | BH1: AUTES EMBALLAGES NON RECYCLABES | BI1: BOIS | BJ1: VERRE | BK1: DDS | BL1: D3E | BM1: IMBRIQUES | BN1: PLASTIQUES NON EMBALLAGES | BO1: FERRAILLES | BP1: GRAVATS | BQ1: TEXTILE | BR1: EMBALLAGES NON VIDES / SOUILL2S | BS1: REFUS | BT1: PAPIER MOUILLE | BU1: FINES | BV1: Taux Valorisable | BW1: Taux Refus | BX1: Taux Fibreux | BZ1: matiere | CA1: taux
A2: =A1+1 | B2: PSM - ADP BEAUVAIS | C2: 23/02/26 | D2: 20 | E2: 2 | F2: 2 | G2: 0 | H2: 0 | I2: 1.2 | J2: 0.3 | K2: 0.3 | L2: 0.2 | M2: 0.1 | N2: 0 | O2: 0.2 | P2: 0.4 | Q2: 0.6 | R2: 0 | S2: 0 | T2: 0 | U2: 0 | V2: 0 | W2: 0 | X2: 0 | Y2: 0 | Z2: 0 | AA2: 0 | AB2: 0 | AC2: 0 | AD2: 0 | AE2: 0 | AF2: 0 | AG2: 0 | AH2: 0 | AI2: =SUM(D2:AG2,AH2) | AJ2: =(SUM($D2:$Q2))/AI2 | AK2: =(SUM($D2:$H2))/AI2 | AL2: =(SUM($R2:$AH2))/AI2 | AN2: 2026 | AO2: 2 | AP2: 8 | AQ2: =IFERROR(D2/$AI2,"") | AR2: =IFERROR(E2/$AI2,"") | AS2: =IFERROR(F2/$AI2,"") | AT2: =IFERROR(G2/$AI2,"") | AU2: =IFERROR(H2/$AI2,"") | AV2: =IFERROR(I2/$AI2,"") | AW2: =IFERROR(J2/$AI2,"") | AX2: =IFERROR(K2/$AI2,"") | ... BU2: =IFERROR(AH2/$AI2,"") | BV2: =SUM(AQ2:BD2) | BW2: =SUM(BE2:BU2) | BX2: =SUM(AQ2:AU2) | BZ2: CARTON | CA2: =AVERAGE(AQ2:AQ1015)
A3: =A2+1 | B3: GARE MONTPARNASSE | C3: 24/02/26 | D3: 0.7 | E3: 0.6 | F3: 0 | G3: 0 | H3: 0 | I3: 0 | J3: 0 | K3: 0 | L3: 0 | M3: 0 | N3: 0 | O3: 0 | P3: 0 | Q3: 0 | R3: 0 | S3: 0 | T3: 0 | U3: 0 | V3: 0 | W3: 0 | X3: 0 | Y3: 0 | Z3: 0 | AA3: 0 | AB3: 0 | AC3: 0 | AD3: 0 | AE3: 0 | AF3: 0 | AG3: 0 | AH3: 0 | AI3: 0 | AJ3: =(SUM($D3:$Q3))/AI3 | AK3: =(SUM($D3:$H3))/AI3 | AL3: =(SUM($R3:$AH3))/AI3 | AN3: 2026 | AO3: 2 | AP3: 8 | AQ3: =IFERROR(D3/$AI3,"") | AR3: =IFERROR(E3/$AI3,"") | AS3: =IFERROR(F3/$AI3,"") | AT3: =IFERROR(H3/$AI3,"") | AU3: =IFERROR(I3/$AI3,"") | AV3: =IFERROR(J3/$AI3,"") | AW3: =IFERROR(K3/$AI3,"") | AX3: =IFERROR(L3/$AI3,"") | AY3: =IFERROR(M3/$AI3,"") | AZ3: =IFERROR(N3/$AI3,"") | BA3: =IFERROR(O3/$AI3,"") | BB3: =IFERROR(P3/$AI3,"") | BC3: =IFERROR(AG3/$AI3,"") | BD3: =IFERROR(AH3/$AI3,"") | BE3: =IFERROR(R3/$AI3,"") | BF3: =IFERROR(S3/$AI3,"") | BG3: =IFERROR(T3/$AI3,"") | BH3: =IFERROR(U3/$AI3,"") | BI3: =IFERROR(V3/$AI3,"") | BJ3: =IFERROR(W3/$AI3,"") | BK3: =IFERROR(X3/$AI3,"") | BL3: =IFERROR(Y3/$AI3,"") | ... BU3: =IFERROR(AH3/$AI3,"") | BV3: =SUM(AQ3:BD3) | BW3: =SUM(BE3:BU3) | BX3: =SUM(AQ3:AU3) | BZ3: CARTONNETTE | CA3: =AVERAGE(AR2:AR1015)
A4: =A3+1 | B4: GARE MONTPARNASSE | C4: 24/02/26 | D4: 0.7 | E4: 0.6 | F4: 0 | G4: 0 | H4: 0 | I4: 0 | J4: 0 | K4: 0 | L4: 0 | M4: 0 | N4: 0 | O4: 0 | P4: 0 | Q4: 0 | R4: 0 | S4: 0 | T4: 0 | U4: 0 | V4: 0 | W4: 0 | X4: 0 | Y4: 0 | Z4: 0 | AA4: 0 | AB4: 0 | AC4: 0 | AD4: 0 | AE4: 0 | AF4: 0 | AG4: 0 | AH4: 0 | AI4: 0 | AJ4: =(SUM($D4:$Q4))/AI4 | AK4: =(SUM($D4:$H4))/AI4 | AL4: =(SUM($R4:$AH4))/AI4 | AN4: =YEAR(C4) | AO4: =MONTH(C4) | AP4: =WEEKNUM(C4,2) | AQ4: =IFERROR(D4/$AI4,"") | AR4: =IFERROR(E4/$AI4,"") | AS4: =IFERROR(F4/$AI4,"") | AT4: =IFERROR(H4/$AI4,"") | AU4: =IFERROR(I4/$AI4,"") | AV4: =IFERROR(J4/$AI4,"") | AW4: =IFERROR(K4/$AI4,"") | AX4: =IFERROR(L4/$AI4,"") | AY4: =IFERROR(M4/$AI4,"") | AZ4: =IFERROR(N4/$AI4,"") | BA4: =IFERROR(O4/$AI4,"") | BB4: =IFERROR(P4/$AI4,"") | BC4: =IFERROR(AG4/$AI4,"") | BD4: =IFERROR(AH4/$AI4,"") | BE4: =IFERROR(R4/$AI4,"") | BF4: =IFERROR(S4/$AI4,"") | BG4: =IFERROR(T4/$AI4,"") | BH4: =IFERROR(U4/$AI4,"") | BI4: =IFERROR(V4/$AI4,"") | BJ4: =IFERROR(W4/$AI4,"") | BK4: =IFERROR(X4/$AI4,"") | BL4: =IFERROR(Y4/$AI4,"") | ... BU4: =IFERROR(AH4/$AI4,"") | BV4: =SUM(AQ4:BD4) | BW4: =SUM(BE4:BU4) | BX4: =SUM(AQ4:AU4) | BZ4: ECRIT COULEUR | CA4: =AVERAGE(AS2:AS1015)
A5: =A4+1 | B5: GARE MONTPARNASSE | C5: 24/02/26 | D5: 0.5 | E5: 0.4 | F5: 0 | G5: 0 | H5: 0 | I5: 0.1 | J5: 0.1 | K5: 0.1 | L5: 0.1 | M5: 0.1 | N5: 0.1 | O5: 0 | P5: 0 | Q5: 0 | R5: 0 | S5: 0 | T5: 0 | U5: 0 | V5: 0 | W5: 0 | X5: 0 | Y5: 0 | Z5: 0 | AA5: 0 | AB5: 0 | AC5: 0 | AD5: 0 | AE5: 0 | AF5: 0 | AG5: 0 | AH5: 0 | AI5: =SUM(D5:AG5,AH5) | AJ5: =(SUM($D5:$Q5))/AI5 | AK5: =(SUM($D5:$H5))/AI5 | AL5: =(SUM($R5:$AH5))/AI5 | AN5: =YEAR(C5) | AO5: =MONTH(C5) | AP5: =WEEKNUM(C5,2) | AQ5: =IFERROR(D5/$AI5,"") | AR5: =IFERROR(E5/$AI5,"") | AS5: =IFERROR(F5/$AI5,"") | AT5: =IFERROR(H5/$AI5,"") | AU5: =IFERROR(I5/$AI5,"") | AV5: =IFERROR(J5/$AI5,"") | AW5: =IFERROR(K5/$AI5,"") | AX5: =IFERROR(L5/$AI5,"") | AY5: =IFERROR(M5/$AI5,"") | AZ5: =IFERROR(N5/$AI5,"") | BA5: =IFERROR(O5/$AI5,"") | BB5: =IFERROR(P5/$AI5,"") | BC5: =IFERROR(AG5/$AI5,"") | BD5: =IFERROR(AH5/$AI5,"") | BE5: =IFERROR(R5/$AI5,"") | BF5: =IFERROR(S5/$AI5,"") | BG5: =IFERROR(T5/$AI5,"") | BH5: =IFERROR(U5/$AI5,"") | BI5: =IFERROR(V5/$AI5,"") | BJ5: =IFERROR(W5/$AI5,"") | BK5: =IFERROR(X5/$AI5,"") | BL5: =IFERROR(Y5/$AI5,"") | ... BU5: =IFERROR(AH5/$AI5,"") | BV5: =SUM(AQ5:BD5) | BW5: =SUM(BE5:BU5) | BX5: =SUM(AQ5:AU5) | BZ5: JRM | CA5: =AVERAGE(AT2:AT1015) | CF5: {=_xlfn._xlws.SORT(BZ2:CA32, 2, 1)} | CG5: #DIV/0!
A6: =A5+1 | B6: GARE MONTPARNASSE | C6: 24/02/26 | D6: 0.2 | E6: 0.1 | F6: 0.1 | G6: 0.1 | H6: 0.2 | I6: 0.5 | J6: 0.1 | K6: 0.1 | L6: 0 | M6: 0.1 | N6: 0.1 | O6: 0.1 | P6: 0.2 | Q6: 0.1 | R6: 0.1 | S6: 0.3 | T6: 0.1 | U6: 0.1 | V6: 0.1 | W6: 0.1 | X6: 0.4 | Y6: 0.4 | Z6: 0.1 | AA6: 0.1 | AB6: 0.3 | AC6: 0.1 | AD6: 0.1 | AE6: 0.4 | AF6: 0.5 | AG6: 0.1 | AH6: 0.1 | AI6: =SUM(D6:AG6,AH6) | AJ6: =(SUM($D6:$Q6))/AI6 | AK6: =(SUM($D6:$H6))/AI6 | AL6: =(SUM($R6:$AH6))/AI6 | AN6: =YEAR(C6) | AO6: =MONTH(C6) | AP6: =WEEKNUM(C6,2) | AQ6: =IFERROR(D6/$AI6,"") | AR6: =IFERROR(E6/$AI6,"") | AS6: =IFERROR(F6/$AI6,"") | AT6: =IFERROR(H6/$AI6,"") | AU6: =IFERROR(I6/$AI6,"") | AV6: =IFERROR(J6/$AI6,"") | AW6: =IFERROR(K6/$AI6,"") | AX6: =IFERROR(L6/$AI6,"") | AY6: =IFERROR(M6/$AI6,"") | AZ6: =IFERROR(N6/$AI6,"") | BA6: =IFERROR(O6/$AI6,"") | BB6: =IFERROR(P6/$AI6,"") | BC6: =IFERROR(AG6/$AI6,"") | BD6: =IFERROR(AH6/$AI6,"") | BE6: =IFERROR(R6/$AI6,"") | BF6: =IFERROR(S6/$AI6,"") | BG6: =IFERROR(T6/$AI6,"") | BH6: =IFERROR(U6/$AI6,"") | BI6: =IFERROR(V6/$AI6,"") | BJ6: =IFERROR(W6/$AI6,"") | BK6: =IFERROR(X6/$AI6,"") | BL6: =IFERROR(Y6/$AI6,"") | ... BU6: =IFERROR(AH6/$AI6,"") | BV6: =SUM(AQ6:BD6) | BW6: =SUM(BE6:BU6) | BX6: =SUM(AQ6:AU6) | BZ6: GM | CA6: =AVERAGE(AU2:AU1015) | CF6: CARTONNETTE | CG6: #DIV/0!
A7: =A6+1 | B7: GARE MONTPARNASSE | C7: 24-02-2026 | D7: 2.7 | E7: 0.1 | F7: 0.1 | G7: 0.2 | H7: 0.2 | I7: 0 | J7: 0 | K7: 0 | L7: 0 | M7: 0 | N7: 0 | O7: 0 | P7: 0 | Q7: 0 | R7: 0 | S7: 0 | T7: 0 | U7: 0 | V7: 0 | W7: 0 | X7: 0 | Y7: 0 | Z7: 0 | AA7: 0 | AB7: 0 | AC7: 0 | AD7: 0.1 | AE7: 0 | AF7: 0.2 | AG7: 0 | AH7: 0.1 | AI7: =SUM(D7:AG7,AH7) | AJ7: =(SUM($D7:$Q7))/AI7 | AK7: =(SUM($D7:$H7))/AI7 | AL7: =(SUM($R7:$AH7))/AI7 | AN7: =YEAR(C7) | AO7: =MONTH(C7) | AP7: =WEEKNUM(C7,2) | AQ7: =IFERROR(D7/$AI7,"") | AR7: =IFERROR(E7/$AI7,"") | AS7: =IFERROR(F7/$AI7,"") | AT7: =IFERROR(H7/$AI7,"") | AU7: =IFERROR(I7/$AI7,"") | AV7: =IFERROR(J7/$AI7,"") | AW7: =IFERROR(K7/$AI7,"") | AX7: =IFERROR(L7/$AI7,"") | AY7: =IFERROR(M7/$AI7,"") | AZ7: =IFERROR(N7/$AI7,"") | BA7: =IFERROR(O7/$AI7,"") | BB7: =IFERROR(P7/$AI7,"") | BC7: =IFERROR(AG7/$AI7,"") | BD7: =IFERROR(AH7/$AI7,"") | BE7: =IFERROR(R7/$AI7,"") | BF7: =IFERROR(S7/$AI7,"") | BG7: =IFERROR(T7/$AI7,"") | BH7: =IFERROR(U7/$AI7,"") | BI7: =IFERROR(V7/$AI7,"") | BJ7: =IFERROR(W7/$AI7,"") | BK7: =IFERROR(X7/$AI7,"") | BL7: =IFERROR(Y7/$AI7,"") | ... BU7: =IFERROR(AH7/$AI7,"") | BV7: =SUM(AQ7:BD7) | BW7: =SUM(BE7:BU7) | BX7: =SUM(AQ7:AU7) | BZ7: ELA | CA7: =AVERAGE(AV2:AV1015) | CF7: ECRIT COULEUR | CG7: #DIV/0!
A8: =A7+1 | AI8: =SUM(D8:AG8,AH8) | AJ8: =(SUM($D8:$Q8))/AI8 | AK8: =(SUM($D8:$H8))/AI8 | AL8: =(SUM($R8:$AH8))/AI8 | AN8: =YEAR(C8) | AO8: =MONTH(C8) | AP8: =WEEKNUM(C8,2) | AQ8: =IFERROR(D8/$AI8,"") | AR8: =IFERROR(E8/$AI8,"") | AS8: =IFERROR(F8/$AI8,"") | AT8: =IFERROR(H8/$AI8,"") | AU8: =IFERROR(I8/$AI8,"") | AV8: =IFERROR(J8/$AI8,"") | AW8: =IFERROR(K8/$AI8,"") | AX8: =IFERROR(L8/$AI8,"") | AY8: =IFERROR(M8/$AI8,"") | AZ8: =IFERROR(N8/$AI8,"") | BA8: =IFERROR(O8/$AI8,"") | BB8: =IFERROR(P8/$AI8,"") | BC8: =IFERROR(AG8/$AI8,"") | BD8: =IFERROR(AH8/$AI8,"") | BE8: =IFERROR(R8/$AI8,"") | BF8: =IFERROR(S8/$AI8,"") | BG8: =IFERROR(T8/$AI8,"") | BH8: =IFERROR(U8/$AI8,"") | BI8: =IFERROR(V8/$AI8,"") | BJ8: =IFERROR(W8/$AI8,"") | BK8: =IFERROR(X8/$AI8,"") | BL8: =IFERROR(Y8/$AI8,"") | ... BU8: =IFERROR(AH8/$AI8,"") | BV8: =SUM(AQ8:BD8) | BW8: =SUM(BE8:BU8) | BX8: =SUM(AQ8:AU8) | BZ8: PEPP | CA8: =AVERAGE(AW2:AW1015) | CF8: JRM | CG8: #DIV/0!
A9: =A8+1 | AI9: =SUM(D9:AG9,AH9) | AJ9: =(SUM($D9:$Q9))/AI9 | AK9: =(SUM($D9:$H9))/AI9 | AL9: =(SUM($R9:$AH9))/AI9 | AN9: =YEAR(C9) | AO9: =MONTH(C9) | AP9: =WEEKNUM(C9,2) | AQ9: =IFERROR(D9/$AI9,"") | AR9: =IFERROR(E9/$AI9,"") | AS9: =IFERROR(F9/$AI9,"") | AT9: =IFERROR(H9/$AI9,"") | AU9: =IFERROR(I9/$AI9,"") | AV9: =IFERROR(J9/$AI9,"") | AW9: =IFERROR(K9/$AI9,"") | AX9: =IFERROR(L9/$AI9,"") | AY9: =IFERROR(M9/$AI9,"") | AZ9: =IFERROR(N9/$AI9,"") | BA9: =IFERROR(O9/$AI9,"") | BB9: =IFERROR(P9/$AI9,"") | BC9: =IFERROR(AG9/$AI9,"") | BD9: =IFERROR(AH9/$AI9,"") | BE9: =IFERROR(R9/$AI9,"") | BF9: =IFERROR(S9/$AI9,"") | BG9: =IFERROR(T9/$AI9,"") | BH9: =IFERROR(U9/$AI9,"") | BI9: =IFERROR(V9/$AI9,"") | BJ9: =IFERROR(W9/$AI9,"") | BK9: =IFERROR(X9/$AI9,"") | BL9: =IFERROR(Y9/$AI9,"") | ... BU9: =IFERROR(AH9/$AI9,"") | BV9: =SUM(AQ9:BD9) | BW9: =SUM(BE9:BU9) | BX9: =SUM(AQ9:AU9) | BZ9: PET Q9 | CA9: =AVERAGE(AX2:AX1015) | CF9: GM | CG9: #DIV/0!
A10: =A9+1 | AI10: =SUM(D10:AG10,AH10) | AJ10: =(SUM($D10:$Q10))/AI10 | AK10: =(SUM($D10:$H10))/AI10 | AL10: =(SUM($R10:$AH10))/AI10 | AN10: =YEAR(C10) | AO10: =MONTH(C10) | AP10: =WEEKNUM(C10,2) | AQ10: =IFERROR(D10/$AI10,"") | AR10: =IFERROR(E10/$AI10,"") | AS10: =IFERROR(F10/$AI10,"") | AT10: =IFERROR(H10/$AI10,"") | AU10: =IFERROR(I10/$AI10,"") | AV10: =IFERROR(J10/$AI10,"") | AW10: =IFERROR(K10/$AI10,"") | AX10: =IFERROR(L10/$AI10,"") | AY10: =IFERROR(M10/$AI10,"") | AZ10: =IFERROR(N10/$AI10,"") | BA10: =IFERROR(O10/$AI10,"") | BB10: =IFERROR(P10/$AI10,"") | BC10: =IFERROR(AG10/$AI10,"") | BD10: =IFERROR(AH10/$AI10,"") | BE10: =IFERROR(R10/$AI10,"") | BF10: =IFERROR(S10/$AI10,"") | BG10: =IFERROR(T10/$AI10,"") | BH10: =IFERROR(U10/$AI10,"") | BI10: =IFERROR(V10/$AI10,"") | BJ10: =IFERROR(W10/$AI10,"") | BK10: =IFERROR(X10/$AI10,"") | BL10: =IFERROR(Y10/$AI10,"") | ... BU10: =IFERROR(AH10/$AI10,"") | BV10: =SUM(AQ10:BD10) | BW10: =SUM(BE10:BU10) | BX10: =SUM(AQ10:AU10) | BZ10: PET Q5 | CA10: =AVERAGE(AY2:AY1015) | CF10: ELA | CG10: #DIV/0!
A11: =A10+1 | AI11: =SUM(D11:AG11,AH11) | AJ11: =(SUM($D11:$Q11))/AI11 | AK11: =(SUM($D11:$H11))/AI11 | AL11: =(SUM($R11:$AH11))/AI11 | AN11: =YEAR(C11) | AO11: =MONTH(C11) | AP11: =WEEKNUM(C11,2) | AQ11: =IFERROR(D11/$AI11,"") | AR11: =IFERROR(E11/$AI11,"") | AS11: =IFERROR(F11/$AI11,"") | AT11: =IFERROR(H11/$AI11,"") | AU11: =IFERROR(I11/$AI11,"") | AV11: =IFERROR(J11/$AI11,"") | AW11: =IFERROR(K11/$AI11,"") | AX11: =IFERROR(L11/$AI11,"") | AY11: =IFERROR(M11/$AI11,"") | AZ11: =IFERROR(N11/$AI11,"") | BA11: =IFERROR(O11/$AI11,"") | BB11: =IFERROR(P11/$AI11,"") | BC11: =IFERROR(AG11/$AI11,"") | BD11: =IFERROR(AH11/$AI11,"") | BE11: =IFERROR(R11/$AI11,"") | BF11: =IFERROR(S11/$AI11,"") | BG11: =IFERROR(T11/$AI11,"") | BH11: =IFERROR(U11/$AI11,"") | BI11: =IFERROR(V11/$AI11,"") | BJ11: =IFERROR(W11/$AI11,"") | BK11: =IFERROR(X11/$AI11,"") | BL11: =IFERROR(Y11/$AI11,"") | ... BU11: =IFERROR(AH11/$AI11,"") | BV11: =SUM(AQ11:BD11) | BW11: =SUM(BE11:BU11) | BX11: =SUM(AQ11:AU11) | BZ11: PET B | CA11: =AVERAGE(AZ2:AZ1015) | CF11: PEPP | CG11: #DIV/0!
A12: =A11+1 | AI12: =SUM(D12:AG12,AH12) | AJ12: =(SUM($D12:$Q12))/AI12 | AK12: =(SUM($D12:$H12))/AI12 | AL12: =(SUM($R12:$AH12))/AI12 | AN12: =YEAR(C12) | AO12: =MONTH(C12) | AP12: =WEEKNUM(C12,2) | AQ12: =IFERROR(D12/$AI12,"") | AR12: =IFERROR(E12/$AI12,"") | AS12: =IFERROR(F12/$AI12,"") | AT12: =IFERROR(H12/$AI12,"") | AU12: =IFERROR(I12/$AI12,"") | AV12: =IFERROR(J12/$AI12,"") | AW12: =IFERROR(K12/$AI12,"") | AX12: =IFERROR(L12/$AI12,"") | AY12: =IFERROR(M12/$AI12,"") | AZ12: =IFERROR(N12/$AI12,"") | BA12: =IFERROR(O12/$AI12,"") | BB12: =IFERROR(P12/$AI12,"") | BC12: =IFERROR(AG12/$AI12,"") | BD12: =IFERROR(AH12/$AI12,"") | BE12: =IFERROR(R12/$AI12,"") | BF12: =IFERROR(S12/$AI12,"") | BG12: =IFERROR(T12/$AI12,"") | BH12: =IFERROR(U12/$AI12,"") | BI12: =IFERROR(V12/$AI12,"") | BJ12: =IFERROR(W12/$AI12,"") | BK12: =IFERROR(X12/$AI12,"") | BL12: =IFERROR(Y12/$AI12,"") | ... BU12: =IFERROR(AH12/$AI12,"") | BV12: =SUM(AQ12:BD12) | BW12: =SUM(BE12:BU12) | BX12: =SUM(AQ12:AU12) | BZ12: FILM | CA12: =AVERAGE(BA2:BA1015) | CF12: PET Q9 | CG12: #DIV/0!
A13: =A12+1 | AI13: =SUM(D13:AG13,AH13) | AJ13: =(SUM($D13:$Q13))/AI13 | AK13: =(SUM($D13:$H13))/AI13 | AL13: =(SUM($R13:$AH13))/AI13 | AN13: =YEAR(C13) | AO13: =MONTH(C13) | AP13: =WEEKNUM(C13,2) | AQ13: =IFERROR(D13/$AI13,"") | AR13: =IFERROR(E13/$AI13,"") | AS13: =IFERROR(F13/$AI13,"") | AT13: =IFERROR(H13/$AI13,"") | AU13: =IFERROR(I13/$AI13,"") | AV13: =IFERROR(J13/$AI13,"") | AW13: =IFERROR(K13/$AI13,"") | AX13: =IFERROR(L13/$AI13,"") | AY13: =IFERROR(M13/$AI13,"") | AZ13: =IFERROR(N13/$AI13,"") | BA13: =IFERROR(O13/$AI13,"") | BB13: =IFERROR(P13/$AI13,"") | BC13: =IFERROR(AG13/$AI13,"") | BD13: =IFERROR(AH13/$AI13,"") | BE13: =IFERROR(R13/$AI13,"") | BF13: =IFERROR(S13/$AI13,"") | BG13: =IFERROR(T13/$AI13,"") | BH13: =IFERROR(U13/$AI13,"") | BI13: =IFERROR(V13/$AI13,"") | BJ13: =IFERROR(W13/$AI13,"") | BK13: =IFERROR(X13/$AI13,"") | BL13: =IFERROR(Y13/$AI13,"") | ... BU13: =IFERROR(AH13/$AI13,"") | BV13: =SUM(AQ13:BD13) | BW13: =SUM(BE13:BU13) | BX13: =SUM(AQ13:AU13) | BZ13: ACIER | CA13: =AVERAGE(BB2:BB1015) | CF13: PET Q5 | CG13: #DIV/0!
A14: =A13+1 | AI14: =SUM(D14:AG14,AH14) | AJ14: =(SUM($D14:$Q14))/AI14 | AK14: =(SUM($D14:$H14))/AI14 | AL14: =(SUM($R14:$AH14))/AI14 | AN14: =YEAR(C14) | AO14: =MONTH(C14) | AP14: =WEEKNUM(C14,2) | AQ14: =IFERROR(D14/$AI14,"") | AR14: =IFERROR(E14/$AI14,"") | AS14: =IFERROR(F14/$AI14,"") | AT14: =IFERROR(H14/$AI14,"") | AU14: =IFERROR(I14/$AI14,"") | AV14: =IFERROR(J14/$AI14,"") | AW14: =IFERROR(K14/$AI14,"") | AX14: =IFERROR(L14/$AI14,"") | AY14: =IFERROR(M14/$AI14,"") | AZ14: =IFERROR(N14/$AI14,"") | BA14: =IFERROR(O14/$AI14,"") | BB14: =IFERROR(P14/$AI14,"") | BC14: =IFERROR(AG14/$AI14,"") | BD14: =IFERROR(AH14/$AI14,"") | BE14: =IFERROR(R14/$AI14,"") | BF14: =IFERROR(S14/$AI14,"") | BG14: =IFERROR(T14/$AI14,"") | BH14: =IFERROR(U14/$AI14,"") | BI14: =IFERROR(V14/$AI14,"") | BJ14: =IFERROR(W14/$AI14,"") | BK14: =IFERROR(X14/$AI14,"") | BL14: =IFERROR(Y14/$AI14,"") | ... BU14: =IFERROR(AH14/$AI14,"") | BV14: =SUM(AQ14:BD14) | BW14: =SUM(BE14:BU14) | BX14: =SUM(AQ14:AU14) | BZ14: ALU | CA14: =AVERAGE(BC2:BC1015) | CF14: PET B | CG14: #DIV/0!
A15: =A14+1 | AI15: =SUM(D15:AG15,AH15) | AJ15: =(SUM($D15:$Q15))/AI15 | AK15: =(SUM($D15:$H15))/AI15 | AL15: =(SUM($R15:$AH15))/AI15 | AN15: =YEAR(C15) | AO15: =MONTH(C15) | AP15: =WEEKNUM(C15,2) | AQ15: =IFERROR(D15/$AI15,"") | AR15: =IFERROR(E15/$AI15,"") | AS15: =IFERROR(F15/$AI15,"") | AT15: =IFERROR(H15/$AI15,"") | AU15: =IFERROR(I15/$AI15,"") | AV15: =IFERROR(J15/$AI15,"") | AW15: =IFERROR(K15/$AI15,"") | AX15: =IFERROR(L15/$AI15,"") | AY15: =IFERROR(M15/$AI15,"") | AZ15: =IFERROR(N15/$AI15,"") | BA15: =IFERROR(O15/$AI15,"") | BB15: =IFERROR(P15/$AI15,"") | BC15: =IFERROR(AG15/$AI15,"") | BD15: =IFERROR(AH15/$AI15,"") | BE15: =IFERROR(R15/$AI15,"") | BF15: =IFERROR(S15/$AI15,"") | BG15: =IFERROR(T15/$AI15,"") | BH15: =IFERROR(U15/$AI15,"") | BI15: =IFERROR(V15/$AI15,"") | BJ15: =IFERROR(W15/$AI15,"") | BK15: =IFERROR(X15/$AI15,"") | BL15: =IFERROR(Y15/$AI15,"") | ... BU15: =IFERROR(AH15/$AI15,"") | BV15: =SUM(AQ15:BD15) | BW15: =SUM(BE15:BU15) | BX15: =SUM(AQ15:AU15) | BZ15: PETIT ALU | CA15: =AVERAGE(BD2:BD1015) | CF15: FILM | CG15: #DIV/0!
A16: =A15+1 | AI16: =SUM(D16:AG16,AH16) | AJ16: =(SUM($D16:$Q16))/AI16 | AK16: =(SUM($D16:$H16))/AI16 | AL16: =(SUM($R16:$AH16))/AI16 | AN16: =YEAR(C16) | AO16: =MONTH(C16) | AP16: =WEEKNUM(C16,2) | AQ16: =IFERROR(D16/$AI16,"") | AR16: =IFERROR(E16/$AI16,"") | AS16: =IFERROR(F16/$AI16,"") | AT16: =IFERROR(H16/$AI16,"") | AU16: =IFERROR(I16/$AI16,"") | AV16: =IFERROR(J16/$AI16,"") | AW16: =IFERROR(K16/$AI16,"") | AX16: =IFERROR(L16/$AI16,"") | AY16: =IFERROR(M16/$AI16,"") | AZ16: =IFERROR(N16/$AI16,"") | BA16: =IFERROR(O16/$AI16,"") | BB16: =IFERROR(P16/$AI16,"") | BC16: =IFERROR(AG16/$AI16,"") | BD16: =IFERROR(AH16/$AI16,"") | BE16: =IFERROR(R16/$AI16,"") | BF16: =IFERROR(S16/$AI16,"") | BG16: =IFERROR(T16/$AI16,"") | BH16: =IFERROR(U16/$AI16,"") | BI16: =IFERROR(V16/$AI16,"") | BJ16: =IFERROR(W16/$AI16,"") | BK16: =IFERROR(X16/$AI16,"") | BL16: =IFERROR(Y16/$AI16,"") | ... BU16: =IFERROR(AH16/$AI16,"") | BV16: =SUM(AQ16:BD16) | BW16: =SUM(BE16:BU16) | BX16: =SUM(AQ16:AU16) | BZ16: PB REFUSES | CA16: =AVERAGE(BE2:BE1015) | CF16: ACIER | CG16: #DIV/0!
A17: =A16+1 | AI17: =SUM(D17:AG17,AH17) | AJ17: =(SUM($D17:$Q17))/AI17 | AK17: =(SUM($D17:$H17))/AI17 | AL17: =(SUM($R17:$AH17))/AI17 | AN17: =YEAR(C17) | AO17: =MONTH(C17) | AP17: =WEEKNUM(C17,2) | AQ17: =IFERROR(D17/$AI17,"") | AR17: =IFERROR(E17/$AI17,"") | AS17: =IFERROR(F17/$AI17,"") | AT17: =IFERROR(H17/$AI17,"") | AU17: =IFERROR(I17/$AI17,"") | AV17: =IFERROR(J17/$AI17,"") | AW17: =IFERROR(K17/$AI17,"") | AX17: =IFERROR(L17/$AI17,"") | AY17: =IFERROR(M17/$AI17,"") | AZ17: =IFERROR(N17/$AI17,"") | BA17: =IFERROR(O17/$AI17,"") | BB17: =IFERROR(P17/$AI17,"") | BC17: =IFERROR(AG17/$AI17,"") | BD17: =IFERROR(AH17/$AI17,"") | BE17: =IFERROR(R17/$AI17,"") | BF17: =IFERROR(S17/$AI17,"") | BG17: =IFERROR(T17/$AI17,"") | BH17: =IFERROR(U17/$AI17,"") | BI17: =IFERROR(V17/$AI17,"") | BJ17: =IFERROR(W17/$AI17,"") | BK17: =IFERROR(X17/$AI17,"") | BL17: =IFERROR(Y17/$AI17,"") | ... BU17: =IFERROR(AH17/$AI17,"") | BV17: =SUM(AQ17:BD17) | BW17: =SUM(BE17:BU17) | BX17: =SUM(AQ17:AU17) | BZ17: FILM REFUSES | CA17: =AVERAGE(BF2:BF1015) | CF17: ALU | CG17: #DIV/0!
A18: =A17+1 | AI18: =SUM(D18:AG18,AH18) | AJ18: =(SUM($D18:$Q18))/AI18 | AK18: =(SUM($D18:$H18))/AI18 | AL18: =(SUM($R18:$AH18))/AI18 | AN18: =YEAR(C18) | AO18: =MONTH(C18) | AP18: =WEEKNUM(C18,2) | AQ18: =IFERROR(D18/$AI18,"") | AR18: =IFERROR(E18/$AI18,"") | AS18: =IFERROR(F18/$AI18,"") | AT18: =IFERROR(H18/$AI18,"") | AU18: =IFERROR(I18/$AI18,"") | AV18: =IFERROR(J18/$AI18,"") | AW18: =IFERROR(K18/$AI18,"") | AX18: =IFERROR(L18/$AI18,"") | AY18: =IFERROR(M18/$AI18,"") | AZ18: =IFERROR(N18/$AI18,"") | BA18: =IFERROR(O18/$AI18,"") | BB18: =IFERROR(P18/$AI18,"") | BC18: =IFERROR(AG18/$AI18,"") | BD18: =IFERROR(AH18/$AI18,"") | BE18: =IFERROR(R18/$AI18,"") | BF18: =IFERROR(S18/$AI18,"") | BG18: =IFERROR(T18/$AI18,"") | BH18: =IFERROR(U18/$AI18,"") | BI18: =IFERROR(V18/$AI18,"") | BJ18: =IFERROR(W18/$AI18,"") | BK18: =IFERROR(X18/$AI18,"") | BL18: =IFERROR(Y18/$AI18,"") | ... BU18: =IFERROR(AH18/$AI18,"") | BV18: =SUM(AQ18:BD18) | BW18: =SUM(BE18:BU18) | BX18: =SUM(AQ18:AU18) | BZ18: EMBALLAGES NOIRS | CA18: =AVERAGE(BG2:BG1015) | CF18: PETIT ALU | CG18: #DIV/0!
A19: =A18+1 | AI19: =SUM(D19:AG19,AH19) | AJ19: =(SUM($D19:$Q19))/AI19 | AK19: =(SUM($D19:$H19))/AI19 | AL19: =(SUM($R19:$AH19))/AI19 | AN19: =YEAR(C19) | AO19: =MONTH(C19) | AP19: =WEEKNUM(C19,2) | AQ19: =IFERROR(D19/$AI19,"") | AR19: =IFERROR(E19/$AI19,"") | AS19: =IFERROR(F19/$AI19,"") | AT19: =IFERROR(H19/$AI19,"") | AU19: =IFERROR(I19/$AI19,"") | AV19: =IFERROR(J19/$AI19,"") | AW19: =IFERROR(K19/$AI19,"") | AX19: =IFERROR(L19/$AI19,"") | AY19: =IFERROR(M19/$AI19,"") | AZ19: =IFERROR(N19/$AI19,"") | BA19: =IFERROR(O19/$AI19,"") | BB19: =IFERROR(P19/$AI19,"") | BC19: =IFERROR(AG19/$AI19,"") | BD19: =IFERROR(AH19/$AI19,"") | BE19: =IFERROR(R19/$AI19,"") | BF19: =IFERROR(S19/$AI19,"") | BG19: =IFERROR(T19/$AI19,"") | BH19: =IFERROR(U19/$AI19,"") | BI19: =IFERROR(V19/$AI19,"") | BJ19: =IFERROR(W19/$AI19,"") | BK19: =IFERROR(X19/$AI19,"") | BL19: =IFERROR(Y19/$AI19,"") | ... BU19: =IFERROR(AH19/$AI19,"") | BV19: =SUM(AQ19:BD19) | BW19: =SUM(BE19:BU19) | BX19: =SUM(AQ19:AU19) | BZ19: AUTES EMBALLAGES NON RECYCLABES | CA19: =AVERAGE(BH2:BH1015) | CF19: PB REFUSES | CG19: #DIV/0!
A20: =A19+1 | AI20: =SUM(D20:AG20,AH20) | AJ20: =(SUM($D20:$Q20))/AI20 | AK20: =(SUM($D20:$H20))/AI20 | AL20: =(SUM($R20:$AH20))/AI20 | AN20: =YEAR(C20) | AO20: =MONTH(C20) | AP20: =WEEKNUM(C20,2) | AQ20: =IFERROR(D20/$AI20,"") | AR20: =IFERROR(E20/$AI20,"") | AS20: =IFERROR(F20/$AI20,"") | AT20: =IFERROR(H20/$AI20,"") | AU20: =IFERROR(I20/$AI20,"") | AV20: =IFERROR(J20/$AI20,"") | AW20: =IFERROR(K20/$AI20,"") | AX20: =IFERROR(L20/$AI20,"") | AY20: =IFERROR(M20/$AI20,"") | AZ20: =IFERROR(N20/$AI20,"") | BA20: =IFERROR(O20/$AI20,"") | BB20: =IFERROR(P20/$AI20,"") | BC20: =IFERROR(AG20/$AI20,"") | BD20: =IFERROR(AH20/$AI20,"") | BE20: =IFERROR(R20/$AI20,"") | BF20: =IFERROR(S20/$AI20,"") | BG20: =IFERROR(T20/$AI20,"") | BH20: =IFERROR(U20/$AI20,"") | BI20: =IFERROR(V20/$AI20,"") | BJ20: =IFERROR(W20/$AI20,"") | BK20: =IFERROR(X20/$AI20,"") | BL20: =IFERROR(Y20/$AI20,"") | ... BU20: =IFERROR(AH20/$AI20,"") | BV20: =SUM(AQ20:BD20) | BW20: =SUM(BE20:BU20) | BX20: =SUM(AQ20:AU20) | BZ20: BOIS | CA20: =AVERAGE(BI2:BI1015) | CF20: FILM REFUSES | CG20: #DIV/0!
A21: =A20+1 | AI21: =SUM(D21:AG21,AH21) | AJ21: =(SUM($D21:$Q21))/AI21 | AK21: =(SUM($D21:$H21))/AI21 | AL21: =(SUM($R21:$AH21))/AI21 | AN21: =YEAR(C21) | AO21: =MONTH(C21) | AP21: =WEEKNUM(C21,2) | AQ21: =IFERROR(D21/$AI21,"") | AR21: =IFERROR(E21/$AI21,"") | AS21: =IFERROR(F21/$AI21,"") | AT21: =IFERROR(H21/$AI21,"") | AU21: =IFERROR(I21/$AI21,"") | AV21: =IFERROR(J21/$AI21,"") | AW21: =IFERROR(K21/$AI21,"") | AX21: =IFERROR(L21/$AI21,"") | AY21: =IFERROR(M21/$AI21,"") | AZ21: =IFERROR(N21/$AI21,"") | BA21: =IFERROR(O21/$AI21,"") | BB21: =IFERROR(P21/$AI21,"") | BC21: =IFERROR(AG21/$AI21,"") | BD21: =IFERROR(AH21/$AI21,"") | BE21: =IFERROR(R21/$AI21,"") | BF21: =IFERROR(S21/$AI21,"") | BG21: =IFERROR(T21/$AI21,"") | BH21: =IFERROR(U21/$AI21,"") | BI21: =IFERROR(V21/$AI21,"") | BJ21: =IFERROR(W21/$AI21,"") | BK21: =IFERROR(X21/$AI21,"") | BL21: =IFERROR(Y21/$AI21,"") | ... BU21: =IFERROR(AH21/$AI21,"") | BV21: =SUM(AQ21:BD21) | BW21: =SUM(BE21:BU21) | BX21: =SUM(AQ21:AU21) | BZ21: VERRE | CA21: =AVERAGE(BJ2:BJ1015) | CF21: EMBALLAGES NOIRS | CG21: #DIV/0!
A22: =A21+1 | AI22: =SUM(D22:AG22,AH22) | AJ22: =(SUM($D22:$Q22))/AI22 | AK22: =(SUM($D22:$H22))/AI22 | AL22: =(SUM($R22:$AH22))/AI22 | AN22: =YEAR(C22) | AO22: =MONTH(C22) | AP22: =WEEKNUM(C22,2) | AQ22: =IFERROR(D22/$AI22,"") | AR22: =IFERROR(E22/$AI22,"") | AS22: =IFERROR(F22/$AI22,"") | AT22: =IFERROR(H22/$AI22,"") | AU22: =IFERROR(I22/$AI22,"") | AV22: =IFERROR(J22/$AI22,"") | AW22: =IFERROR(K22/$AI22,"") | AX22: =IFERROR(L22/$AI22,"") | AY22: =IFERROR(M22/$AI22,"") | AZ22: =IFERROR(N22/$AI22,"") | BA22: =IFERROR(O22/$AI22,"") | BB22: =IFERROR(P22/$AI22,"") | BC22: =IFERROR(AG22/$AI22,"") | BD22: =IFERROR(AH22/$AI22,"") | BE22: =IFERROR(R22/$AI22,"") | BF22: =IFERROR(S22/$AI22,"") | BG22: =IFERROR(T22/$AI22,"") | BH22: =IFERROR(U22/$AI22,"") | BI22: =IFERROR(V22/$AI22,"") | BJ22: =IFERROR(W22/$AI22,"") | BK22: =IFERROR(X22/$AI22,"") | BL22: =IFERROR(Y22/$AI22,"") | ... BU22: =IFERROR(AH22/$AI22,"") | BV22: =SUM(AQ22:BD22) | BW22: =SUM(BE22:BU22) | BX22: =SUM(AQ22:AU22) | BZ22: DDS | CA22: =AVERAGE(BK2:BK1015) | CF22: AUTES EMBALLAGES NON RECYCLABES | CG22: #DIV/0!
A23: =A22+1 | AI23: =SUM(D23:AG23,AH23) | AJ23: =(SUM($D23:$Q23))/AI23 | AK23: =(SUM($D23:$H23))/AI23 | AL23: =(SUM($R23:$AH23))/AI23 | AN23: =YEAR(C23) | AO23: =MONTH(C23) | AP23: =WEEKNUM(C23,2) | AQ23: =IFERROR(D23/$AI23,"") | AR23: =IFERROR(E23/$AI23,"") | AS23: =IFERROR(F23/$AI23,"") | AT23: =IFERROR(H23/$AI23,"") | AU23: =IFERROR(I23/$AI23,"") | AV23: =IFERROR(J23/$AI23,"") | AW23: =IFERROR(K23/$AI23,"") | AX23: =IFERROR(L23/$AI23,"") | AY23: =IFERROR(M23/$AI23,"") | AZ23: =IFERROR(N23/$AI23,"") | BA23: =IFERROR(O23/$AI23,"") | BB23: =IFERROR(P23/$AI23,"") | BC23: =IFERROR(AG23/$AI23,"") | BD23: =IFERROR(AH23/$AI23,"") | BE23: =IFERROR(R23/$AI23,"") | BF23: =IFERROR(S23/$AI23,"") | BG23: =IFERROR(T23/$AI23,"") | BH23: =IFERROR(U23/$AI23,"") | BI23: =IFERROR(V23/$AI23,"") | BJ23: =IFERROR(W23/$AI23,"") | BK23: =IFERROR(X23/$AI23,"") | BL23: =IFERROR(Y23/$AI23,"") | ... BU23: =IFERROR(AH23/$AI23,"") | BV23: =SUM(AQ23:BD23) | BW23: =SUM(BE23:BU23) | BX23: =SUM(AQ23:AU23) | BZ23: D3E | CA23: =AVERAGE(BL2:BL1015) | CF23: BOIS | CG23: #DIV/0!
A24: =A23+1 | AI24: =SUM(D24:AG24,AH24) | AJ24: =(SUM($D24:$Q24))/AI24 | AK24: =(SUM($D24:$H24))/AI24 | AL24: =(SUM($R24:$AH24))/AI24 | AN24: =YEAR(C24) | AO24: =MONTH(C24) | AP24: =WEEKNUM(C24,2) | AQ24: =IFERROR(D24/$AI24,"") | AR24: =IFERROR(E24/$AI24,"") | AS24: =IFERROR(F24/$AI24,"") | AT24: =IFERROR(H24/$AI24,"") | AU24: =IFERROR(I24/$AI24,"") | AV24: =IFERROR(J24/$AI24,"") | AW24: =IFERROR(K24/$AI24,"") | AX24: =IFERROR(L24/$AI24,"") | AY24: =IFERROR(M24/$AI24,"") | AZ24: =IFERROR(N24/$AI24,"") | BA24: =IFERROR(O24/$AI24,"") | BB24: =IFERROR(P24/$AI24,"") | BC24: =IFERROR(AG24/$AI24,"") | BD24: =IFERROR(AH24/$AI24,"") | BE24: =IFERROR(R24/$AI24,"") | BF24: =IFERROR(S24/$AI24,"") | BG24: =IFERROR(T24/$AI24,"") | BH24: =IFERROR(U24/$AI24,"") | BI24: =IFERROR(V24/$AI24,"") | BJ24: =IFERROR(W24/$AI24,"") | BK24: =IFERROR(X24/$AI24,"") | BL24: =IFERROR(Y24/$AI24,"") | ... BU24: =IFERROR(AH24/$AI24,"") | BV24: =SUM(AQ24:BD24) | BW24: =SUM(BE24:BU24) | BX24: =SUM(AQ24:AU24) | BZ24: IMBRIQUES | CA24: =AVERAGE(BM2:BM1015) | CF24: VERRE | CG24: #DIV/0!
A25: =A24+1 | AI25: =SUM(D25:AG25,AH25) | AJ25: =(SUM($D25:$Q25))/AI25 | AK25: =(SUM($D25:$H25))/AI25 | AL25: =(SUM($R25:$AH25))/AI25 | AN25: =YEAR(C25) | AO25: =MONTH(C25) | AP25: =WEEKNUM(C25,2) | AQ25: =IFERROR(D25/$AI25,"") | AR25: =IFERROR(E25/$AI25,"") | AS25: =IFERROR(F25/$AI25,"") | AT25: =IFERROR(H25/$AI25,"") | AU25: =IFERROR(I25/$AI25,"") | AV25: =IFERROR(J25/$AI25,"") | AW25: =IFERROR(K25/$AI25,"") | AX25: =IFERROR(L25/$AI25,"") | AY25: =IFERROR(M25/$AI25,"") | AZ25: =IFERROR(N25/$AI25,"") | BA25: =IFERROR(O25/$AI25,"") | BB25: =IFERROR(P25/$AI25,"") | BC25: =IFERROR(AG25/$AI25,"") | BD25: =IFERROR(AH25/$AI25,"") | BE25: =IFERROR(R25/$AI25,"") | BF25: =IFERROR(S25/$AI25,"") | BG25: =IFERROR(T25/$AI25,"") | BH25: =IFERROR(U25/$AI25,"") | BI25: =IFERROR(V25/$AI25,"") | BJ25: =IFERROR(W25/$AI25,"") | BK25: =IFERROR(X25/$AI25,"") | BL25: =IFERROR(Y25/$AI25,"") | ... BU25: =IFERROR(AH25/$AI25,"") | BV25: =SUM(AQ25:BD25) | BW25: =SUM(BE25:BU25) | BX25: =SUM(AQ25:AU25) | BZ25: PLASTIQUES NON EMBALLAGES | CA25: =AVERAGE(BN2:BN1015) | CF25: DDS | CG25: #DIV/0!
A26: =A25+1 | AI26: =SUM(D26:AG26,AH26) | AJ26: =(SUM($D26:$Q26))/AI26 | AK26: =(SUM($D26:$H26))/AI26 | AL26: =(SUM($R26:$AH26))/AI26 | AN26: =YEAR(C26) | AO26: =MONTH(C26) | AP26: =WEEKNUM(C26,2) | AQ26: =IFERROR(D26/$AI26,"") | AR26: =IFERROR(E26/$AI26,"") | AS26: =IFERROR(F26/$AI26,"") | AT26: =IFERROR(H26/$AI26,"") | AU26: =IFERROR(I26/$AI26,"") | AV26: =IFERROR(J26/$AI26,"") | AW26: =IFERROR(K26/$AI26,"") | AX26: =IFERROR(L26/$AI26,"") | AY26: =IFERROR(M26/$AI26,"") | AZ26: =IFERROR(N26/$AI26,"") | BA26: =IFERROR(O26/$AI26,"") | BB26: =IFERROR(P26/$AI26,"") | BC26: =IFERROR(AG26/$AI26,"") | BD26: =IFERROR(AH26/$AI26,"") | BE26: =IFERROR(R26/$AI26,"") | BF26: =IFERROR(S26/$AI26,"") | BG26: =IFERROR(T26/$AI26,"") | BH26: =IFERROR(U26/$AI26,"") | BI26: =IFERROR(V26/$AI26,"") | BJ26: =IFERROR(W26/$AI26,"") | BK26: =IFERROR(X26/$AI26,"") | BL26: =IFERROR(Y26/$AI26,"") | ... BU26: =IFERROR(AH26/$AI26,"") | BV26: =SUM(AQ26:BD26) | BW26: =SUM(BE26:BU26) | BX26: =SUM(AQ26:AU26) | BZ26: FERRAILLES | CA26: =AVERAGE(BO2:BO1015) | CF26: D3E | CG26: #DIV/0!
A27: =A26+1 | AI27: =SUM(D27:AG27,AH27) | AJ27: =(SUM($D27:$Q27))/AI27 | AK27: =(SUM($D27:$H27))/AI27 | AL27: =(SUM($R27:$AH27))/AI27 | AN27: =YEAR(C27) | AO27: =MONTH(C27) | AP27: =WEEKNUM(C27,2) | AQ27: =IFERROR(D27/$AI27,"") | AR27: =IFERROR(E27/$AI27,"") | AS27: =IFERROR(F27/$AI27,"") | AT27: =IFERROR(H27/$AI27,"") | AU27: =IFERROR(I27/$AI27,"") | AV27: =IFERROR(J27/$AI27,"") | AW27: =IFERROR(K27/$AI27,"") | AX27: =IFERROR(L27/$AI27,"") | AY27: =IFERROR(M27/$AI27,"") | AZ27: =IFERROR(N27/$AI27,"") | BA27: =IFERROR(O27/$AI27,"") | BB27: =IFERROR(P27/$AI27,"") | BC27: =IFERROR(AG27/$AI27,"") | BD27: =IFERROR(AH27/$AI27,"") | BE27: =IFERROR(R27/$AI27,"") | BF27: =IFERROR(S27/$AI27,"") | BG27: =IFERROR(T27/$AI27,"") | BH27: =IFERROR(U27/$AI27,"") | BI27: =IFERROR(V27/$AI27,"") | BJ27: =IFERROR(W27/$AI27,"") | BK27: =IFERROR(X27/$AI27,"") | BL27: =IFERROR(Y27/$AI27,"") | ... BU27: =IFERROR(AH27/$AI27,"") | BV27: =SUM(AQ27:BD27) | BW27: =SUM(BE27:BU27) | BX27: =SUM(AQ27:AU27) | BZ27: GRAVATS | CA27: =AVERAGE(BP2:BP1015) | CF27: IMBRIQUES | CG27: #DIV/0!
A28: =A27+1 | AI28: =SUM(D28:AG28,AH28) | AJ28: =(SUM($D28:$Q28))/AI28 | AK28: =(SUM($D28:$H28))/AI28 | AL28: =(SUM($R28:$AH28))/AI28 | AN28: =YEAR(C28) | AO28: =MONTH(C28) | AP28: =WEEKNUM(C28,2) | AQ28: =IFERROR(D28/$AI28,"") | AR28: =IFERROR(E28/$AI28,"") | AS28: =IFERROR(F28/$AI28,"") | AT28: =IFERROR(H28/$AI28,"") | AU28: =IFERROR(I28/$AI28,"") | AV28: =IFERROR(J28/$AI28,"") | AW28: =IFERROR(K28/$AI28,"") | AX28: =IFERROR(L28/$AI28,"") | AY28: =IFERROR(M28/$AI28,"") | AZ28: =IFERROR(N28/$AI28,"") | BA28: =IFERROR(O28/$AI28,"") | BB28: =IFERROR(P28/$AI28,"") | BC28: =IFERROR(AG28/$AI28,"") | BD28: =IFERROR(AH28/$AI28,"") | BE28: =IFERROR(R28/$AI28,"") | BF28: =IFERROR(S28/$AI28,"") | BG28: =IFERROR(T28/$AI28,"") | BH28: =IFERROR(U28/$AI28,"") | BI28: =IFERROR(V28/$AI28,"") | BJ28: =IFERROR(W28/$AI28,"") | BK28: =IFERROR(X28/$AI28,"") | BL28: =IFERROR(Y28/$AI28,"") | ... BU28: =IFERROR(AH28/$AI28,"") | BV28: =SUM(AQ28:BD28) | BW28: =SUM(BE28:BU28) | BX28: =SUM(AQ28:AU28) | BZ28: TEXTILE | CA28: =AVERAGE(BQ2:BQ1015) | CF28: PLASTIQUES NON EMBALLAGES | CG28: #DIV/0!
A29: =A28+1 | AI29: =SUM(D29:AG29,AH29) | AJ29: =(SUM($D29:$Q29))/AI29 | AK29: =(SUM($D29:$H29))/AI29 | AL29: =(SUM($R29:$AH29))/AI29 | AN29: =YEAR(C29) | AO29: =MONTH(C29) | AP29: =WEEKNUM(C29,2) | AQ29: =IFERROR(D29/$AI29,"") | AR29: =IFERROR(E29/$AI29,"") | AS29: =IFERROR(F29/$AI29,"") | AT29: =IFERROR(H29/$AI29,"") | AU29: =IFERROR(I29/$AI29,"") | AV29: =IFERROR(J29/$AI29,"") | AW29: =IFERROR(K29/$AI29,"") | AX29: =IFERROR(L29/$AI29,"") | AY29: =IFERROR(M29/$AI29,"") | AZ29: =IFERROR(N29/$AI29,"") | BA29: =IFERROR(O29/$AI29,"") | BB29: =IFERROR(P29/$AI29,"") | BC29: =IFERROR(AG29/$AI29,"") | BD29: =IFERROR(AH29/$AI29,"") | BE29: =IFERROR(R29/$AI29,"") | BF29: =IFERROR(S29/$AI29,"") | BG29: =IFERROR(T29/$AI29,"") | BH29: =IFERROR(U29/$AI29,"") | BI29: =IFERROR(V29/$AI29,"") | BJ29: =IFERROR(W29/$AI29,"") | BK29: =IFERROR(X29/$AI29,"") | BL29: =IFERROR(Y29/$AI29,"") | ... BU29: =IFERROR(AH29/$AI29,"") | BV29: =SUM(AQ29:BD29) | BW29: =SUM(BE29:BU29) | BX29: =SUM(AQ29:AU29) | BZ29: EMBALLAGES NON VIDES / SOUILL2S | CA29: =AVERAGE(BR2:BR1015) | CF29: FERRAILLES | CG29: #DIV/0!
A30: =A29+1 | AI30: =SUM(D30:AG30,AH30) | AJ30: =(SUM($D30:$Q30))/AI30 | AK30: =(SUM($D30:$H30))/AI30 | AL30: =(SUM($R30:$AH30))/AI30 | AN30: =YEAR(C30) | AO30: =MONTH(C30) | AP30: =WEEKNUM(C30,2) | AQ30: =IFERROR(D30/$AI30,"") | AR30: =IFERROR(E30/$AI30,"") | AS30: =IFERROR(F30/$AI30,"") | AT30: =IFERROR(H30/$AI30,"") | AU30: =IFERROR(I30/$AI30,"") | AV30: =IFERROR(J30/$AI30,"") | AW30: =IFERROR(K30/$AI30,"") | AX30: =IFERROR(L30/$AI30,"") | AY30: =IFERROR(M30/$AI30,"") | AZ30: =IFERROR(N30/$AI30,"") | BA30: =IFERROR(O30/$AI30,"") | BB30: =IFERROR(P30/$AI30,"") | BC30: =IFERROR(AG30/$AI30,"") | BD30: =IFERROR(AH30/$AI30,"") | BE30: =IFERROR(R30/$AI30,"") | BF30: =IFERROR(S30/$AI30,"") | BG30: =IFERROR(T30/$AI30,"") | BH30: =IFERROR(U30/$AI30,"") | BI30: =IFERROR(V30/$AI30,"") | BJ30: =IFERROR(W30/$AI30,"") | BK30: =IFERROR(X30/$AI30,"") | BL30: =IFERROR(Y30/$AI30,"") | ... BU30: =IFERROR(AH30/$AI30,"") | BV30: =SUM(AQ30:BD30) | BW30: =SUM(BE30:BU30) | BX30: =SUM(AQ30:AU30) | BZ30: REFUS | CA30: =AVERAGE(BS2:BS1015) | CF30: GRAVATS | CG30: #DIV/0!
A31: =A30+1 | AI31: =SUM(D31:AG31,AH31) | AJ31: =(SUM($D31:$Q31))/AI31 | AK31: =(SUM($D31:$H31))/AI31 | AL31: =(SUM($R31:$AH31))/AI31 | AN31: =YEAR(C31) | AO31: =MONTH(C31) | AP31: =WEEKNUM(C31,2) | AQ31: =IFERROR(D31/$AI31,"") | AR31: =IFERROR(E31/$AI31,"") | AS31: =IFERROR(F31/$AI31,"") | AT31: =IFERROR(H31/$AI31,"") | AU31: =IFERROR(I31/$AI31,"") | AV31: =IFERROR(J31/$AI31,"") | AW31: =IFERROR(K31/$AI31,"") | AX31: =IFERROR(L31/$AI31,"") | AY31: =IFERROR(M31/$AI31,"") | AZ31: =IFERROR(N31/$AI31,"") | BA31: =IFERROR(O31/$AI31,"") | BB31: =IFERROR(P31/$AI31,"") | BC31: =IFERROR(AG31/$AI31,"") | BD31: =IFERROR(AH31/$AI31,"") | BE31: =IFERROR(R31/$AI31,"") | BF31: =IFERROR(S31/$AI31,"") | BG31: =IFERROR(T31/$AI31,"") | BH31: =IFERROR(U31/$AI31,"") | BI31: =IFERROR(V31/$AI31,"") | BJ31: =IFERROR(W31/$AI31,"") | BK31: =IFERROR(X31/$AI31,"") | BL31: =IFERROR(Y31/$AI31,"") | ... BU31: =IFERROR(AH31/$AI31,"") | BV31: =SUM(AQ31:BD31) | BW31: =SUM(BE31:BU31) | BX31: =SUM(AQ31:AU31) | BZ31: PAPIER MOUILLE | CA31: =AVERAGE(BT2:BT1015) | CF31: TEXTILE | CG31: #DIV/0!
A32: =A31+1 | AI32: =SUM(D32:AG32,AH32) | AJ32: =(SUM($D32:$Q32))/AI32 | AK32: =(SUM($D32:$H32))/AI32 | AL32: =(SUM($R32:$AH32))/AI32 | AN32: =YEAR(C32) | AO32: =MONTH(C32) | AP32: =WEEKNUM(C32,2) | AQ32: =IFERROR(D32/$AI32,"") | AR32: =IFERROR(E32/$AI32,"") | AS32: =IFERROR(F32/$AI32,"") | AT32: =IFERROR(H32/$AI32,"") | AU32: =IFERROR(I32/$AI32,"") | AV32: =IFERROR(J32/$AI32,"") | AW32: =IFERROR(K32/$AI32,"") | AX32: =IFERROR(L32/$AI32,"") | AY32: =IFERROR(M32/$AI32,"") | AZ32: =IFERROR(N32/$AI32,"") | BA32: =IFERROR(O32/$AI32,"") | BB32: =IFERROR(P32/$AI32,"") | BC32: =IFERROR(AG32/$AI32,"") | BD32: =IFERROR(AH32/$AI32,"") | BE32: =IFERROR(R32/$AI32,"") | BF32: =IFERROR(S32/$AI32,"") | BG32: =IFERROR(T32/$AI32,"") | BH32: =IFERROR(U32/$AI32,"") | BI32: =IFERROR(V32/$AI32,"") | BJ32: =IFERROR(W32/$AI32,"") | BK32: =IFERROR(X32/$AI32,"") | BL32: =IFERROR(Y32/$AI32,"") | ... BU32: =IFERROR(AH32/$AI32,"") | BV32: =SUM(AQ32:BD32) | BW32: =SUM(BE32:BU32) | BX32: =SUM(AQ32:AU32) | BZ32: FINES | CA32: =AVERAGE(BU2:BU1015) | CF32: EMBALLAGES NON VIDES / SOUILL2S | CG32: #DIV/0!
A33: =A32+1 | AI33: =SUM(D33:AG33,AH33) | AJ33: =(SUM($D33:$Q33))/AI33 | AK33: =(SUM($D33:$H33))/AI33 | AL33: =(SUM($R33:$AH33))/AI33 | AN33: =YEAR(C33) | AO33: =MONTH(C33) | AP33: =WEEKNUM(C33,2) | AQ33: =IFERROR(D33/$AI33,"") | AR33: =IFERROR(E33/$AI33,"") | AS33: =IFERROR(F33/$AI33,"") | AT33: =IFERROR(H33/$AI33,"") | AU33: =IFERROR(I33/$AI33,"") | AV33: =IFERROR(J33/$AI33,"") | AW33: =IFERROR(K33/$AI33,"") | AX33: =IFERROR(L33/$AI33,"") | AY33: =IFERROR(M33/$AI33,"") | AZ33: =IFERROR(N33/$AI33,"") | BA33: =IFERROR(O33/$AI33,"") | BB33: =IFERROR(P33/$AI33,"") | BC33: =IFERROR(AG33/$AI33,"") | BD33: =IFERROR(AH33/$AI33,"") | BE33: =IFERROR(R33/$AI33,"") | BF33: =IFERROR(S33/$AI33,"") | BG33: =IFERROR(T33/$AI33,"") | BH33: =IFERROR(U33/$AI33,"") | BI33: =IFERROR(V33/$AI33,"") | BJ33: =IFERROR(W33/$AI33,"") | BK33: =IFERROR(X33/$AI33,"") | BL33: =IFERROR(Y33/$AI33,"") | ... BU33: =IFERROR(AH33/$AI33,"") | BV33: =SUM(AQ33:BD33) | BW33: =SUM(BE33:BU33) | BX33: =SUM(AQ33:AU33) | CF33: REFUS | CG33: #DIV/0!
A34: =A33+1 | AI34: =SUM(D34:AG34,AH34) | AJ34: =(SUM($D34:$Q34))/AI34 | AK34: =(SUM($D34:$H34))/AI34 | AL34: =(SUM($R34:$AH34))/AI34 | AN34: =YEAR(C34) | AO34: =MONTH(C34) | AP34: =WEEKNUM(C34,2) | AQ34: =IFERROR(D34/$AI34,"") | AR34: =IFERROR(E34/$AI34,"") | AS34: =IFERROR(F34/$AI34,"") | AT34: =IFERROR(H34/$AI34,"") | AU34: =IFERROR(I34/$AI34,"") | AV34: =IFERROR(J34/$AI34,"") | AW34: =IFERROR(K34/$AI34,"") | AX34: =IFERROR(L34/$AI34,"") | AY34: =IFERROR(M34/$AI34,"") | AZ34: =IFERROR(N34/$AI34,"") | BA34: =IFERROR(O34/$AI34,"") | BB34: =IFERROR(P34/$AI34,"") | BC34: =IFERROR(AG34/$AI34,"") | BD34: =IFERROR(AH34/$AI34,"") | BE34: =IFERROR(R34/$AI34,"") | BF34: =IFERROR(S34/$AI34,"") | BG34: =IFERROR(T34/$AI34,"") | BH34: =IFERROR(U34/$AI34,"") | BI34: =IFERROR(V34/$AI34,"") | BJ34: =IFERROR(W34/$AI34,"") | BK34: =IFERROR(X34/$AI34,"") | BL34: =IFERROR(Y34/$AI34,"") | ... BU34: =IFERROR(AH34/$AI34,"") | BV34: =SUM(AQ34:BD34) | BW34: =SUM(BE34:BU34) | BX34: =SUM(AQ34:AU34) | CF34: PAPIER MOUILLE | CG34: #DIV/0!
A35: =A34+1 | AI35: =SUM(D35:AG35,AH35) | AJ35: =(SUM($D35:$Q35))/AI35 | AK35: =(SUM($D35:$H35))/AI35 | AL35: =(SUM($R35:$AH35))/AI35 | AN35: =YEAR(C35) | AO35: =MONTH(C35) | AP35: =WEEKNUM(C35,2) | AQ35: =IFERROR(D35/$AI35,"") | AR35: =IFERROR(E35/$AI35,"") | AS35: =IFERROR(F35/$AI35,"") | AT35: =IFERROR(H35/$AI35,"") | AU35: =IFERROR(I35/$AI35,"") | AV35: =IFERROR(J35/$AI35,"") | AW35: =IFERROR(K35/$AI35,"") | AX35: =IFERROR(L35/$AI35,"") | AY35: =IFERROR(M35/$AI35,"") | AZ35: =IFERROR(N35/$AI35,"") | BA35: =IFERROR(O35/$AI35,"") | BB35: =IFERROR(P35/$AI35,"") | BC35: =IFERROR(AG35/$AI35,"") | BD35: =IFERROR(AH35/$AI35,"") | BE35: =IFERROR(R35/$AI35,"") | BF35: =IFERROR(S35/$AI35,"") | BG35: =IFERROR(T35/$AI35,"") | BH35: =IFERROR(U35/$AI35,"") | BI35: =IFERROR(V35/$AI35,"") | BJ35: =IFERROR(W35/$AI35,"") | BK35: =IFERROR(X35/$AI35,"") | BL35: =IFERROR(Y35/$AI35,"") | ... BU35: =IFERROR(AH35/$AI35,"") | BV35: =SUM(AQ35:BD35) | BW35: =SUM(BE35:BU35) | BX35: =SUM(AQ35:AU35) | CF35: FINES | CG35: #DIV/0!
A36: =A35+1 | AI36: =SUM(D36:AG36,AH36) | AJ36: =(SUM($D36:$Q36))/AI36 | AK36: =(SUM($D36:$H36))/AI36 | AL36: =(SUM($R36:$AH36))/AI36 | AN36: =YEAR(C36) | AO36: =MONTH(C36) | AP36: =WEEKNUM(C36,2) | AQ36: =IFERROR(D36/$AI36,"") | AR36: =IFERROR(E36/$AI36,"") | AS36: =IFERROR(F36/$AI36,"") | AT36: =IFERROR(H36/$AI36,"") | AU36: =IFERROR(I36/$AI36,"") | AV36: =IFERROR(J36/$AI36,"") | AW36: =IFERROR(K36/$AI36,"") | AX36: =IFERROR(L36/$AI36,"") | AY36: =IFERROR(M36/$AI36,"") | AZ36: =IFERROR(N36/$AI36,"") | BA36: =IFERROR(O36/$AI36,"") | BB36: =IFERROR(P36/$AI36,"") | BC36: =IFERROR(AG36/$AI36,"") | BD36: =IFERROR(AH36/$AI36,"") | BE36: =IFERROR(R36/$AI36,"") | BF36: =IFERROR(S36/$AI36,"") | BG36: =IFERROR(T36/$AI36,"") | BH36: =IFERROR(U36/$AI36,"") | BI36: =IFERROR(V36/$AI36,"") | BJ36: =IFERROR(W36/$AI36,"") | BK36: =IFERROR(X36/$AI36,"") | BL36: =IFERROR(Y36/$AI36,"") | ... BU36: =IFERROR(AH36/$AI36,"") | BV36: =SUM(AQ36:BD36) | BW36: =SUM(BE36:BU36) | BX36: =SUM(AQ36:AU36)
A37: =A36+1 | AI37: =SUM(D37:AG37,AH37) | AJ37: =(SUM($D37:$Q37))/AI37 | AK37: =(SUM($D37:$H37))/AI37 | AL37: =(SUM($R37:$AH37))/AI37 | AN37: =YEAR(C37) | AO37: =MONTH(C37) | AP37: =WEEKNUM(C37,2) | AQ37: =IFERROR(D37/$AI37,"") | AR37: =IFERROR(E37/$AI37,"") | AS37: =IFERROR(F37/$AI37,"") | AT37: =IFERROR(H37/$AI37,"") | AU37: =IFERROR(I37/$AI37,"") | AV37: =IFERROR(J37/$AI37,"") | AW37: =IFERROR(K37/$AI37,"") | AX37: =IFERROR(L37/$AI37,"") | AY37: =IFERROR(M37/$AI37,"") | AZ37: =IFERROR(N37/$AI37,"") | BA37: =IFERROR(O37/$AI37,"") | BB37: =IFERROR(P37/$AI37,"") | BC37: =IFERROR(AG37/$AI37,"") | BD37: =IFERROR(AH37/$AI37,"") | BE37: =IFERROR(R37/$AI37,"") | BF37: =IFERROR(S37/$AI37,"") | BG37: =IFERROR(T37/$AI37,"") | BH37: =IFERROR(U37/$AI37,"") | BI37: =IFERROR(V37/$AI37,"") | BJ37: =IFERROR(W37/$AI37,"") | BK37: =IFERROR(X37/$AI37,"") | BL37: =IFERROR(Y37/$AI37,"") | ... BU37: =IFERROR(AH37/$AI37,"") | BV37: =SUM(AQ37:BD37) | BW37: =SUM(BE37:BU37) | BX37: =SUM(AQ37:AU37)
A38: =A37+1 | AI38: =SUM(D38:AG38,AH38) | AJ38: =(SUM($D38:$Q38))/AI38 | AK38: =(SUM($D38:$H38))/AI38 | AL38: =(SUM($R38:$AH38))/AI38 | AN38: =YEAR(C38) | AO38: =MONTH(C38) | AP38: =WEEKNUM(C38,2) | AQ38: =IFERROR(D38/$AI38,"") | AR38: =IFERROR(E38/$AI38,"") | AS38: =IFERROR(F38/$AI38,"") | AT38: =IFERROR(H38/$AI38,"") | AU38: =IFERROR(I38/$AI38,"") | AV38: =IFERROR(J38/$AI38,"") | AW38: =IFERROR(K38/$AI38,"") | AX38: =IFERROR(L38/$AI38,"") | AY38: =IFERROR(M38/$AI38,"") | AZ38: =IFERROR(N38/$AI38,"") | BA38: =IFERROR(O38/$AI38,"") | BB38: =IFERROR(P38/$AI38,"") | BC38: =IFERROR(AG38/$AI38,"") | BD38: =IFERROR(AH38/$AI38,"") | BE38: =IFERROR(R38/$AI38,"") | BF38: =IFERROR(S38/$AI38,"") | BG38: =IFERROR(T38/$AI38,"") | BH38: =IFERROR(U38/$AI38,"") | BI38: =IFERROR(V38/$AI38,"") | BJ38: =IFERROR(W38/$AI38,"") | BK38: =IFERROR(X38/$AI38,"") | BL38: =IFERROR(Y38/$AI38,"") | ... BU38: =IFERROR(AH38/$AI38,"") | BV38: =SUM(AQ38:BD38) | BW38: =SUM(BE38:BU38) | BX38: =SUM(AQ38:AU38)
A39: =A38+1 | AI39: =SUM(D39:AG39,AH39) | AJ39: =(SUM($D39:$Q39))/AI39 | AK39: =(SUM($D39:$H39))/AI39 | AL39: =(SUM($R39:$AH39))/AI39 | AN39: =YEAR(C39) | AO39: =MONTH(C39) | AP39: =WEEKNUM(C39,2) | AQ39: =IFERROR(D39/$AI39,"") | AR39: =IFERROR(E39/$AI39,"") | AS39: =IFERROR(F39/$AI39,"") | AT39: =IFERROR(H39/$AI39,"") | AU39: =IFERROR(I39/$AI39,"") | AV39: =IFERROR(J39/$AI39,"") | AW39: =IFERROR(K39/$AI39,"") | AX39: =IFERROR(L39/$AI39,"") | AY39: =IFERROR(M39/$AI39,"") | AZ39: =IFERROR(N39/$AI39,"") | BA39: =IFERROR(O39/$AI39,"") | BB39: =IFERROR(P39/$AI39,"") | BC39: =IFERROR(AG39/$AI39,"") | BD39: =IFERROR(AH39/$AI39,"") | BE39: =IFERROR(R39/$AI39,"") | BF39: =IFERROR(S39/$AI39,"") | BG39: =IFERROR(T39/$AI39,"") | BH39: =IFERROR(U39/$AI39,"") | BI39: =IFERROR(V39/$AI39,"") | BJ39: =IFERROR(W39/$AI39,"") | BK39: =IFERROR(X39/$AI39,"") | BL39: =IFERROR(Y39/$AI39,"") | ... BU39: =IFERROR(AH39/$AI39,"") | BV39: =SUM(AQ39:BD39) | BW39: =SUM(BE39:BU39) | BX39: =SUM(AQ39:AU39)
A40: =A39+1 | AI40: =SUM(D40:AG40,AH40) | AJ40: =(SUM($D40:$Q40))/AI40 | AK40: =(SUM($D40:$H40))/AI40 | AL40: =(SUM($R40:$AH40))/AI40 | AN40: =YEAR(C40) | AO40: =MONTH(C40) | AP40: =WEEKNUM(C40,2) | AQ40: =IFERROR(D40/$AI40,"") | AR40: =IFERROR(E40/$AI40,"") | AS40: =IFERROR(F40/$AI40,"") | AT40: =IFERROR(H40/$AI40,"") | AU40: =IFERROR(I40/$AI40,"") | AV40: =IFERROR(J40/$AI40,"") | AW40: =IFERROR(K40/$AI40,"") | AX40: =IFERROR(L40/$AI40,"") | AY40: =IFERROR(M40/$AI40,"") | AZ40: =IFERROR(N40/$AI40,"") | BA40: =IFERROR(O40/$AI40,"") | BB40: =IFERROR(P40/$AI40,"") | BC40: =IFERROR(AG40/$AI40,"") | BD40: =IFERROR(AH40/$AI40,"") | BE40: =IFERROR(R40/$AI40,"") | BF40: =IFERROR(S40/$AI40,"") | BG40: =IFERROR(T40/$AI40,"") | BH40: =IFERROR(U40/$AI40,"") | BI40: =IFERROR(V40/$AI40,"") | BJ40: =IFERROR(W40/$AI40,"") | BK40: =IFERROR(X40/$AI40,"") | BL40: =IFERROR(Y40/$AI40,"") | ... BU40: =IFERROR(AH40/$AI40,"") | BV40: =SUM(AQ40:BD40) | BW40: =SUM(BE40:BU40) | BX40: =SUM(AQ40:AU40)
...

Sheet TABLEAU
A1: matiere | B1: taux | D1: matiere | E1: taux
A2: CARTON | B2: =TABLEAU!CA2 | D2: {=_xlfn._xlws.SORT(BZ2:CA32, 2, 1)} | E2: 0
A3: CARTONNETTE | B3: =TABLEAU!CA3 | D3: 0 | E3: 0
A4: ECRIT COULEUR | B4: =TABLEAU!CA4 | D4: 0 | E4: 0
A5: JRM | B5: =TABLEAU!CA5 | D5: 0 | E5: 0
A6: GM | B6: =TABLEAU!CA6 | D6: 0 | E6: 0
A7: ELA | B7: =TABLEAU!CA7 | D7: 0 | E7: 0
A8: PEPP | B8: =TABLEAU!CA8 | D8: 0 | E8: 0
A9: PET Q9 | B9: =TABLEAU!CA9 | D9: 0 | E9: 0
A10: PET Q5 | B10: =TABLEAU!CA10 | D10: 0 | E10: 0
A11: PET B | B11: =TABLEAU!CA11 | D11: 0 | E11: 0
A12: FILM | B12: =TABLEAU!CA12 | D12: 0 | E12: 0
A13: ACIER | B13: =TABLEAU!CA13 | D13: 0 | E13: 0
A14: ALU | B14: =TABLEAU!CA14 | D14: 0 | E14: 0
... A32: FINES | B32: =TABLEAU!CA32 | D32: 0 | E32: 0

Sheet Fiche caract
B1: Numéro | C1: 0
B3: Caractérisation
K4: Catégorie | L4: Poids Brut (en kg) | M4: Poids net (en kg) | N4: % dans le refus
B5: Provenance | C5: =VLOOKUP(C1,SAISIE!A:BS,2,FALSE) | F5: Date : | G5: =VLOOKUP(C1,SAISIE!A:BS,3,FALSE) | I5: 23 | J5: Refus | K5: Autre indésirable | M5: =IF(VLOOKUP($C$1,SAISIE!A:BH,I5,FALSE)="","",VLOOKUP($C$1,SAISIE!A:BH,I5,FALSE)) | N5: =M5/E27
I6: 25 | K6: Verre | M6: =IF(VLOOKUP($C$1,SAISIE!A:BH,I6,FALSE)="","",VLOOKUP($C$1,SAISIE!A:BH,I6,FALSE)) | N6: =M6/E27
I7: 26 | K7: Film complexes | M7: =IF(VLOOKUP($C$1,SAISIE!A:BH,I7,FALSE)="","",VLOOKUP($C$1,SAISIE!A:BH,I7,FALSE)) | N7: =M7/E27
C8: Catégorie | D8: Poids Brut (en kg) | E8: Poids net (en kg) | F8: % | G8: % | I8: 27 | K8: Ordure menagere | M8: =IF(VLOOKUP($C$1,SAISIE!A:BH,I8,FALSE)="","",VLOOKUP($C$1,SAISIE!A:BH,I8,FALSE)) | N8: =M8/E27
A9: 4 | B9: Fibreux | C9: JRM (1.11) | E9: =IF(VLOOKUP($C$1,SAISIE!A:BH,A9,FALSE)="","",VLOOKUP($C$1,SAISIE!A:BH,A9,FALSE)) | F9: =E9/C29 | G9: =SUM(F9:F14) | I9: 28 | K9: Film non PE | M9: =IF(VLOOKUP($C$1,SAISIE!A:BH,I9,FALSE)="","",VLOOKUP($C$1,SAISIE!A:BH,I9,FALSE)) | N9: =M9/E27
A10: 5 | C10: Papier blanc (2.05) | E10: =IF(VLOOKUP($C$1,SAISIE!A:BH,A10,FALSE)="","",VLOOKUP($C$1,SAISIE!A:BH,A10,FALSE)) | F10: =E10/C29 | I10: 29 | K10: Textiles | M10: =IF(VLOOKUP($C$1,SAISIE!A:BH,I10,FALSE)="","",VLOOKUP($C$1,SAISIE!A:BH,I10,FALSE)) | N10: =M10/E27
A11: 6 | C11: EMR (1.04 CS) | E11: =IF(VLOOKUP($C$1,SAISIE!A:BH,A11,FALSE)="","",VLOOKUP($C$1,SAISIE!A:BH,A11,FALSE)) | F11: =E11/C29 | I11: 30 | K11: Plastique divers | M11: =IF(VLOOKUP($C$1,SAISIE!A:BH,I11,FALSE)="","",VLOOKUP($C$1,SAISIE!A:BH,I11,FALSE)) | N11: =M11/E27
C12: Cartons/ Cartonnettes | I12: 21 | K12: Imbriqué | M12: =IF(VLOOKUP($C$1,SAISIE!A:BH,I12,FALSE)="","",VLOOKUP($C$1,SAISIE!A:BH,I12,FALSE)) | N12: =M12/E27
A13: 7 | C13: 1.05 | E13: =IF(VLOOKUP($C$1,SAISIE!A:BH,A13,FALSE)="","",VLOOKUP($C$1,SAISIE!A:BH,A13,FALSE)) | F13: =E13/C29 | I13: 31 | K13: D3E | M13: =IF(VLOOKUP($C$1,SAISIE!A:BH,I13,FALSE)="","",VLOOKUP($C$1,SAISIE!A:BH,I13,FALSE)) | N13: =M13/E27
A14: 8 | C14: GM (1.02 CS) | E14: =IF(VLOOKUP($C$1,SAISIE!A:BH,A14,FALSE)="","",VLOOKUP($C$1,SAISIE!A:BH,A14,FALSE)) | F14: =E14/C29 | I14: 32 | K14: P & B multi | M14: =IF(VLOOKUP($C$1,SAISIE!A:BH,I14,FALSE)="","",VLOOKUP($C$1,SAISIE!A:BH,I14,FALSE)) | N14: =M14/E27
A15: 9 | B15: Corps creux | C15: PET clair (Q4) | E15: =IF(VLOOKUP($C$1,SAISIE!A:BH,A15,FALSE)="","",VLOOKUP($C$1,SAISIE!A:BH,A15,FALSE)) | F15: =E15/C29 | G15: =SUM(F15:F23) | I15: 33 | K15: Non vide | M15: =IF(VLOOKUP($C$1,SAISIE!A:BH,I15,FALSE)="","",VLOOKUP($C$1,SAISIE!A:BH,I15,FALSE)) | N15: =M15/E27
A16: 10 | C16: PET foncé (Q5) | E16: =IF(VLOOKUP($C$1,SAISIE!A:BH,A16,FALSE)="","",VLOOKUP($C$1,SAISIE!A:BH,A16,FALSE)) | F16: =E16/C29 | I16: 19 | K16: Petit alu | M16: =IF(VLOOKUP($C$1,SAISIE!A:BH,I16,FALSE)="","",VLOOKUP($C$1,SAISIE!A:BH,I16,FALSE)) | N16: =M16/E27
A17: 11 | C17: PET Opaque | E17: =IF(VLOOKUP($C$1,SAISIE!A:BH,A17,FALSE)="","",VLOOKUP($C$1,SAISIE!A:BH,A17,FALSE)) | F17: =E17/C29 | M17: =SUM(M5:M16) | N17: =M17/C29
A18: 12 | C18: PET B | E18: =IF(VLOOKUP($C$1,SAISIE!A:BH,A18,FALSE)="","",VLOOKUP($C$1,SAISIE!A:BH,A18,FALSE)) | F18: =E18/C29
A19: 13 | C19: PS | E19: =IF(VLOOKUP($C$1,SAISIE!A:BH,A19,FALSE)="","",VLOOKUP($C$1,SAISIE!A:BH,A19,FALSE)) | F19: =E19/C29
A20: 14 | C20: PEHD | E20: =IF(VLOOKUP($C$1,SAISIE!A:BH,A20,FALSE)="","",VLOOKUP($C$1,SAISIE!A:BH,A20,FALSE)) | F20: =E20/C29
A21: 15 | C21: PP | E21: =IF(VLOOKUP($C$1,SAISIE!A:BH,A21,FALSE)="","",VLOOKUP($C$1,SAISIE!A:BH,A21,FALSE)) | F21: =E21/C29
A22: 16 | C22: TETRA | E22: =IF(VLOOKUP($C$1,SAISIE!A:BH,A22,FALSE)="","",VLOOKUP($C$1,SAISIE!A:BH,A22,FALSE)) | F22: =E22/C29
A23: 17 | C23: Film PE | E23: =IF(VLOOKUP($C$1,SAISIE!A:BH,A23,FALSE)="","",VLOOKUP($C$1,SAISIE!A:BH,A23,FALSE)) | F23: =E23/C29
A24: 18 | B24: Ferreux / Non Ferreux | C24: Aciers | E24: =IF(VLOOKUP($C$1,SAISIE!A:BH,A24,FALSE)="","",VLOOKUP($C$1,SAISIE!A:BH,A24,FALSE)) | F24: =E24/C29 | G24: =SUM(F24:F25)
A25: 20 | C25: Alu | E25: =IF(VLOOKUP($C$1,SAISIE!A:BH,A25,FALSE)="","",VLOOKUP($C$1,SAISIE!A:BH,A25,FALSE)) | F25: =E25/C29
A26: 22 | B26: Refus | C26: Refus fines | E26: =IF(VLOOKUP($C$1,SAISIE!A:BH,A26,FALSE)="","",VLOOKUP($C$1,SAISIE!A:BH,A26,FALSE)) | F26: =E26/C29 | G26: =SUM(F26:F27)
A27: 34 | C27: Refus | E27: =M17 | F27: =E27/C29
A28: 39
B29: Poids total net | C29: =SUM(E9:E27) | D29: Kg
B31: REMARQUES
B32: =IF(VLOOKUP($C$1,SAISIE!A:BH,A28,FALSE)="","",VLOOKUP($C$1,SAISIE!A:BH,A28,FALSE))

Sheet FICHE
A2: Caractérisation
B4: Provenance | F4: Date :
C7: Catégorie | D7: Poids Brut (en kg) | E7: Poids net (en kg) | F7: % | G7: %
A8: 4 | B8: Fibreux | C8: JRM
A9: 5 | C9: EMR (1.04 CS)
A10: 6 | C10: CARTON
C11: GM (1.02 CS)
A12: 7 | B12: Corps creux | C12: PET Q9
A13: 8 | C13: FLUX DEV
A14: 9 | C14: PET B
A15: 10 | C15: PEPP
A16: 11 | C16: ELA
A17: 12 | C17: Film PE
A18: 13 | C18: Aciers
A19: 14 | B19: Ferreux / Non Ferreux | C19: ACIER
A20: 15 | C20: ALU
A21: 16 | C21: PETIT ALU
A22: 17 | B22: Refus | C22: REFUS FINES
A23: 18
B24: Poids total net | D24: Kg
B26: REMARQUES

Sheet BILAN

Sheet BDD
A1: GARE MONTPARNASSE
A2: LE PETIT PLUS
A3: LA COURNEUVE
A4: PSM
A5: PSM - ADP BEAUVAIS
A6: LBM
A7: AEROVILLE
A8: CDG
A9: HAUSSMAN
A10: ORLY
A11: CEMEX
A12: LE BOURGET & LBM
... A22: AUTRES

Sheet Détails1
A1: Détails pou for Moyenne de Taux de valorisable - Mois : 2
A3: Provenance | B3: Date | C3: JRM | D3: 2.06 | E3: EMR | F3: 1.05 | G3: GM | H3: PET Q4 | I3: PET Q5 | J3: PET O | K3: PET B | L3: PS | M3: PEHD | N3: PP | O3: ELA | P3: Films PE | Q3: ACIER | R3: Petit ALU | S3: ALU | T3: Refus | U3: Total (kg) | V3: Taux de valorisable | W3: Taux de fibreux | X3: Taux de refus | Y3: Commentaire | Z3: Année | AA3: Mois | AB3: Semaine | AC3: JRM2 | AD3: 2.05 | AE3: EMR2 | AF3: GM2 | AG3: PET Q42 | AH3: PET Q52 | AI3: PET O2 | AJ3: PET B2 | AK3: PS2 | AL3: PEHD2 | AM3: PP2 | AN3: ELA2 | AO3: Films PE2 | AP3: ACIER2 | AQ3: Petit ALU2 | AR3: ALU2 | AS3: Refus2 | AT3: Taux Valorisable | AU3: Taux Refus | AV3: Taux Fibreux
A4: SYCTOM | B4: 46068 | C4: 2 | D4: 4 | E4: 6 | F4: 12 | G4: 8 | H4: 88 | I4: 4 | J4: 0 | K4: 1 | L4: 0 | M4: 6 | N4: 5 | O4: 4 | P4: 9 | Q4: 25 | R4: 7 | S4: 2 | T4: 2 | U4: 185 | V4: 0.98918919 | W4: 0.17297297 | X4: 0.010810811 | Z4: 2026 | AA4: 2 | AB4: 7 | AC4: 0.010810811 | AD4: 0.021621622 | AE4: 0.032432432 | AF4: 0.043243243 | AG4: 0.47567568 | AH4: 0.021621622 | AI4: 0 | AJ4: 0.0054054054 | AK4: 0 | AL4: 0.032432432 | AM4: 0.027027027 | AN4: 0.021621622 | AO4: 0.048648649 | AP4: 0.13513514 | AQ4: 0.037837838 | AR4: 0.010810811 | AS4: 0.010810811 | AT4: 0.92432432 | AU4: 0.010810811 | AV4: 0.10810811
A5: SYCTOM | B5: 46068 | C5: 2 | D5: 23 | E5: 2 | F5: 1 | G5: 5 | H5: 0 | I5: 1 | J5: 3 | K5: 1 | L5: 2 | M5: 8 | N5: 4 | O5: 6 | P5: 9 | Q5: 0 | R5: 2 | S5: 2 | T5: 5 | U5: 76 | V5: 0.93421053 | W5: 0.43421053 | X5: 0.065789474 | Z5: 2026 | AA5: 2 | AB5: 7 | AC5: 0.026315789 | AD5: 0.30263158 | AE5: 0.026315789 | AF5: 0.065789474 | AG5: 0 | AH5: 0.013157895 | AI5: 0.039473684 | AJ5: 0.013157895 | AK5: 0.026315789 | AL5: 0.10526316 | AM5: 0.052631579 | AN5: 0.078947368 | AO5: 0.11842105 | AP5: 0 | AQ5: 0.026315789 | AR5: 0.026315789 | AS5: 0.065789474 | AT5: 0.92105263 | AU5: 0.065789474 | AV5: 0.42105263
A6: SYCTOM | B6: 46068 | C6: 0.2 | D6: 0.3 | E6: 0.01 | F6: 0.001 | G6: 0.2 | H6: 0.3 | I6: 0.6 | J6: 0.2 | K6: 0.1 | L6: 0.1 | M6: 0.1 | N6: 0.1 | O6: 0.1 | P6: 0.1 | Q6: 25 | R6: 0.2 | S6: 0.1 | T6: 10 | U6: 37.711 | V6: 0.73482538 | W6: 0.018853915 | X6: 0.26517462 | Z6: 2026 | AA6: 2 | AB6: 7 | AC6: 0.0053034923 | AD6: 0.0079552385 | AE6: 0.00026517462 | AF6: 0.0053034923 | AG6: 0.0079552385 | AH6: 0.015910477 | AI6: 0.0053034923 | AJ6: 0.0026517462 | AK6: 0.0026517462 | AL6: 0.0026517462 | AM6: 0.0026517462 | AN6: 0.0026517462 | AO6: 0.0026517462 | AP6: 0.66293654 | AQ6: 0.0053034923 | AR6: 0.0026517462 | AS6: 0.26517462 | AT6: 0.73479887 | AU6: 0.26517462 | AV6: 0.018827398

Sheet TCD
G1: MOIS CHIFFRE | H1: MOIS | I1: TAUX DE VALORISABLE | J1: TAUX REFUS
G2: 1 | H2: JANVIER | I2: =IFERROR(VLOOKUP(G2,A:C,2,0),"") | J2: =IFERROR(VLOOKUP(G2,A:C,3,0),"")
A3: Étiquettes de lignes | B3: Moyenne de Taux de valorisable | C3: Moyenne de Taux de refus | G3: 2 | H3: FÉVRIER | I3: =IFERROR(VLOOKUP(G3,A:C,2,0),"") | J3: =IFERROR(VLOOKUP(G3,A:C,3,0),"")
A4: 1 | B4: #DIV/0! | C4: #DIV/0! | G4: 3 | H4: MARS | I4: =IFERROR(VLOOKUP(G4,A:C,2,0),"") | J4: =IFERROR(VLOOKUP(G4,A:C,3,0),"")
A5: 2 | B5: 0.88607503 | C5: 0.11392497 | G5: 4 | H5: AVRIL | I5: =IFERROR(VLOOKUP(G5,A:C,2,0),"") | J5: =IFERROR(VLOOKUP(G5,A:C,3,0),"")
A6: (vide) | G6: 5 | H6: MAI | I6: =IFERROR(VLOOKUP(G6,A:C,2,0),"") | J6: =IFERROR(VLOOKUP(G6,A:C,3,0),"")
A7: Total général | B7: #DIV/0! | C7: #DIV/0! | G7: 6 | H7: JUIN | I7: =IFERROR(VLOOKUP(G7,A:C,2,0),"") | J7: =IFERROR(VLOOKUP(G7,A:C,3,0),"")
G8: 7 | H8: JUILLET | I8: =IFERROR(VLOOKUP(G8,A:C,2,0),"") | J8: =IFERROR(VLOOKUP(G8,A:C,3,0),"")
G9: 8 | H9: AOÛT | I9: =IFERROR(VLOOKUP(G9,A:C,2,0),"") | J9: =IFERROR(VLOOKUP(G9,A:C,3,0),"")
G10: 9 | H10: SEPTEMBRE | I10: =IFERROR(VLOOKUP(G10,A:C,2,0),"") | J10: =IFERROR(VLOOKUP(G10,A:C,3,0),"")
G11: 10 | H11: OCTOBRE | I11: =IFERROR(VLOOKUP(G11,A:C,2,0),"") | J11: =IFERROR(VLOOKUP(G11,A:C,3,0),"")
G12: 11 | H12: NOVEMBRE | I12: =IFERROR(VLOOKUP(G12,A:C,2,0),"") | J12: =IFERROR(VLOOKUP(G12,A:C,3,0),"")
G13: 12 | H13: DÉCEMBRE | I13: =IFERROR(VLOOKUP(G13,A:C,2,0),"") | J13: =IFERROR(VLOOKUP(G13,A:C,3,0),"")

Sheet Taux-Moyenne
A1: Caract avec le SMDO
C3: Flux caractérisé | D3: Date | E3: Taux de valorisable | F3: Taux de fibreux | G3: Taux de refus
C4: =SAISIE!$B2 | D4: =SAISIE!$C2 | E4: =SAISIE!BV2 | F4: =SAISIE!BX2 | G4: =SAISIE!BW2
C5: =SAISIE!$B3 | D5: =SAISIE!$C3 | E5: =SAISIE!BV3 | F5: =SAISIE!BX3 | G5: =SAISIE!BW3 | I5: Moyenne Valo | J5: Moyenne Fibreux | K5: Moyenne Refus
C6: =SAISIE!B4 | D6: =SAISIE!$C4 | E6: =SAISIE!BV4 | F6: =SAISIE!BX4 | G6: =SAISIE!BW4 | I6: =AVERAGE(E4:E9) | J6: =AVERAGE(E4:E9) | K6: =AVERAGE(E4:E9)
C7: =SAISIE!B5 | D7: =SAISIE!$C5 | E7: =SAISIE!BV5 | F7: =SAISIE!BX5 | G7: =SAISIE!BW5
C8: =SAISIE!$B6 | D8: =SAISIE!$C6 | E8: =SAISIE!BV6 | F8: =SAISIE!BX6 | G8: =SAISIE!BW6
C9: =SAISIE!$B7 | D9: =SAISIE!$C7 | E9: =SAISIE!BV7 | F9: =SAISIE!BX7 | G9: =SAISIE!BW7
C10: =SAISIE!B8 | D10: =SAISIE!$C8 | E10: =SAISIE!BV8 | F10: =SAISIE!BX8 | G10: =SAISIE!BW8
C11: =SAISIE!B9 | D11: =SAISIE!$C9 | E11: =SAISIE!BV9 | F11: =SAISIE!BX9 | G11: =SAISIE!BW9
C12: =SAISIE!$B10 | D12: =SAISIE!$C10 | E12: =SAISIE!BV10 | F12: =SAISIE!BX10 | G12: =SAISIE!BW10
C13: =SAISIE!$B11 | D13: =SAISIE!$C11 | E13: =SAISIE!BV11 | F13: =SAISIE!BX11 | G13: =SAISIE!BW11
C14: =SAISIE!B12 | D14: =SAISIE!$C12 | E14: =SAISIE!BV12 | F14: =SAISIE!BX12 | G14: =SAISIE!BW12
C15: =SAISIE!B13 | D15: =SAISIE!$C13 | E15: =SAISIE!BV13 | F15: =SAISIE!BX13 | G15: =SAISIE!BW13
C16: =SAISIE!$B14 | D16: =SAISIE!$C14 | E16: =SAISIE!BV14 | F16: =SAISIE!BX14 | G16: =SAISIE!BW14
C17: =SAISIE!$B15 | D17: =SAISIE!$C15 | E17: =SAISIE!BV15 | F17: =SAISIE!BX15 | G17: =SAISIE!BW15
C18: =SAISIE!B16 | D18: =SAISIE!$C16 | E18: =SAISIE!BV16 | F18: =SAISIE!BX16 | G18: =SAISIE!BW16
C19: =SAISIE!B17 | D19: =SAISIE!$C17 | E19: =SAISIE!BV17 | F19: =SAISIE!BX17 | G19: =SAISIE!BW17
C20: =SAISIE!$B18 | D20: =SAISIE!$C18 | E20: =SAISIE!BV18 | F20: =SAISIE!BX18 | G20: =SAISIE!BW18
C21: =SAISIE!$B19 | D21: =SAISIE!$C19 | E21: =SAISIE!BV19 | F21: =SAISIE!BX19 | G21: =SAISIE!BW19
C22: =SAISIE!B20 | D22: =SAISIE!$C20 | E22: =SAISIE!BV20 | F22: =SAISIE!BX20 | G22: =SAISIE!BW20
C23: =SAISIE!B21 | D23: =SAISIE!$C21 | E23: =SAISIE!BV21 | F23: =SAISIE!BX21 | G23: =SAISIE!BW21
C24: =SAISIE!$B22 | D24: =SAISIE!$C22 | E24: =SAISIE!BV22 | F24: =SAISIE!BX22 | G24: =SAISIE!BW22
C25: =SAISIE!$B23 | D25: =SAISIE!$C23 | E25: =SAISIE!BV23 | F25: =SAISIE!BX23 | G25: =SAISIE!BW23
C26: =SAISIE!B24 | D26: =SAISIE!$C24 | E26: =SAISIE!BV24 | F26: =SAISIE!BX24 | G26: =SAISIE!BW24
C27: =SAISIE!B25 | D27: =SAISIE!$C25 | E27: =SAISIE!BV25 | F27: =SAISIE!BX25 | G27: =SAISIE!BW25
C28: =SAISIE!$B26 | D28: =SAISIE!$C26 | E28: =SAISIE!BV26 | F28: =SAISIE!BX26 | G28: =SAISIE!BW26
C29: =SAISIE!$B27 | D29: =SAISIE!$C27 | E29: =SAISIE!BV27 | F29: =SAISIE!BX27 | G29: =SAISIE!BW27
C30: =SAISIE!B28 | D30: =SAISIE!$C28 | E30: =SAISIE!BV28 | F30: =SAISIE!BX28 | G30: =SAISIE!BW28
C31: =SAISIE!B29 | D31: =SAISIE!$C29 | E31: =SAISIE!BV29 | F31: =SAISIE!BX29 | G31: =SAISIE!BW29
C32: =SAISIE!$B30 | D32: =SAISIE!$C30 | E32: =SAISIE!BV30 | F32: =SAISIE!BX30 | G32: =SAISIE!BW30
C33: =SAISIE!$B31 | D33: =SAISIE!$C31 | E33: =SAISIE!BV31 | F33: =SAISIE!BX31 | G33: =SAISIE!BW31
C34: =SAISIE!B32 | D34: =SAISIE!$C32 | E34: =SAISIE!BV32 | F34: =SAISIE!BX32 | G34: =SAISIE!BW32
C35: =SAISIE!B33 | D35: =SAISIE!$C33 | E35: =SAISIE!BV33 | F35: =SAISIE!BX33 | G35: =SAISIE!BW33
C36: =SAISIE!$B34 | D36: =SAISIE!$C34 | E36: =SAISIE!BV34 | F36: =SAISIE!BX34 | G36: =SAISIE!BW34
C37: =SAISIE!$B35 | D37: =SAISIE!$C35 | E37: =SAISIE!BV35 | F37: =SAISIE!BX35 | G37: =SAISIE!BW35
C38: =SAISIE!B36 | D38: =SAISIE!$C36 | E38: =SAISIE!BV36 | F38: =SAISIE!BX36 | G38: =SAISIE!BW36
C39: =SAISIE!B37 | D39: =SAISIE!$C37 | E39: =SAISIE!BV37 | F39: =SAISIE!BX37 | G39: =SAISIE!BW37
C40: =SAISIE!$B38 | D40: =SAISIE!$C38 | E40: =SAISIE!BV38 | F40: =SAISIE!BX38 | G40: =SAISIE!BW38
C41: =SAISIE!$B39 | D41: =SAISIE!$C39 | E41: =SAISIE!BV39 | F41: =SAISIE!BX39 | G41: =SAISIE!BW39
...
